Workbook

Sheet 1. How it works
A1: Attempt Verification System: how it decides
A2: Check | B2: Question it answers | C2: Data | D2: Already exists? | E2: Can the rider game it? | F2: Source
A3: 1. Masked call | B3: Does the customer pick up when the system calls them (customer dialled first, 'Meesho Delivery' caller ID)? | C3: Call log: answered, ring time, duration, recording | D3: Partly: Valmo records rider–customer calls | E3: No: rider isn't on the customer leg | F3: Valmo privacy policy; Exotel
A4: 2. WhatsApp reply | B4: What does the customer say: Talk to rider / Reschedule / Nobody came? | C4: Customer's tap | D4: New message template | E4: No | F4: Meta WhatsApp pricing
A5: 3. Confidence-based geofence | B5: Is the rider inside a zone sized by how sure GeoIndia is of the address? | C5: Rider GPS, GeoIndia cell, delivery history, anti-spoofing | D5: Partly: GeoIndia powers geofencing | E5: Hard with anti-spoofing | F5: GeoIndia paper (EMNLP 2024)
A6: 4. Peer comparison | B6: Is this rider's failed-attempt / RTO rate far above other riders in the same locality? | C6: Rider and locality RTO history | D6: Data exists; comparison is new | E6: Not on one order | F6: No published benchmark
A7: Decision rules (rules first; a model later, trained on pilot data)
A8: Customer | B8: Rider location | C8: Call log | D8: Peer comparison | E8: Verdict | F8: Action
A9: Picks up / taps Talk or Reschedule | B9: Any | C9: Answered | D9: Any | E9: Genuine: rescued | F9: Deliver now or reschedule
A10: 'Nobody came' | B10: Outside zone | C10: Any | D10: Any | E10: Fake | F10: Same-day re-attempt; counts in rider score
A11: 'Nobody came' | B11: Inside zone | C11: Rider leg connected | D11: Any | E11: Disputed | F11: Hub reviews recording; re-attempt
A12: Silent | B12: Inside zone | C12: Phone rang | D12: Normal | E12: Likely genuine | F12: Normal re-attempt
A13: Silent | B13: Inside zone | C13: Phone rang | D13: Rider is an outlier | E13: Watch | F13: Re-attempt; rider review queue
A14: Silent | B14: Outside zone | C14: Rider rejected leg / no call | D14: Any | E14: Suspect | F14: Hold status; hub review; re-attempt
A15: Unreachable | B15: Any | C15: Call failed | D15: Any | E15: Genuine: unreachable | F15: SMS/WhatsApp; flag number

Sheet 2. Financials
A1: Attempt Verification System: incremental cash flow (existing team, no new hires)
A2: Item | B2: Value | C2: Unit | D2: Source / note
A3: A. Volume
A4: Total Valmo hubs | B4: 2700 | C4: hubs | D4: Team's primary research
A5: Share of hubs that are small | B5: 0.65 | C5: % | D5: Team's primary research
A6: Orders per small hub per day, low | B6: 400 | C6: orders/day | D6: Team's primary research
A7: Orders per small hub per day, high | B7: 700 | C7: orders/day | D7: Team's primary research
A8: Small-hub orders per day | B8: =ROUND(B4*B5,0)*AVERAGE(B6,B7) -> 965250 | C8: orders/day | D8: Small hubs × midpoint orders per hub
A9: Fake-attempt rate in small hubs | B9: 0.0114 | C9: % of orders | D9: Team's primary research
A10: Fake attempts per day, small hubs | B10: =ROUND(B8*B9,0) -> 11004 | C10: per day | D10: Small-hub orders × fake rate
A11: Share of hubs that are large | B11: =1-B5 -> 0.35 | C11: % | D11: Remaining hubs
A12: Orders per large hub per day, low | B12: 1500 | C12: orders/day | D12: Team's primary research
A13: Orders per large hub per day, high | B13: 2000 | C13: orders/day | D13: Team's primary research
A14: Large-hub orders per day | B14: =ROUND(B4*B11,0)*AVERAGE(B12,B13) -> 1653750 | C14: orders/day | D14: Large hubs × midpoint orders per hub
A15: Fake-attempt rate in large hubs | B15: 0.025 | C15: % of orders | D15: Team's primary research
A16: Fake attempts per day, large hubs | B16: =ROUND(B14*B15,0) -> 41344 | C16: per day | D16: Large-hub orders × fake rate
A17: Total orders per day | B17: =B8+B14 -> 2619000 | C17: orders/day | D17: Small + large
A18: Total fake attempts per day | B18: =B10+B16 -> 52348 | C18: per day | D18: Small + large
A19: 'Customer unavailable' rate (failed, not cancelled) | B19: =(2006-1821-90)/2006 -> 0.047357926 | C19: % of orders | D19: Your hub data, 5–10 Sep: (2,006 sent − 1,821 delivered − 90 cancelled) ÷ 2,006. One hub; applied to large hubs too (ASSUMPTION).
A20: 'Unavailable' taps per day (each triggers the system) | B20: =ROUND(B17*B19,0) -> 124030 | C20: taps/day | D20: Total orders × unavailable rate
A21: …of which genuine 'customer not available' | B21: =MAX(0,B20-B18) -> 71682 | C21: per day | D21: Taps − fake attempts
A23: B. Value of one rescued order
A24: Return shipping avoided | B24: 120 | C24: ₹/order | D24: Reverse logistics cost per RTO (case pack, illustrative)
A25: Net cash per rescued order | B25: =B24 -> 120 | C25: ₹/order | D25: Return avoided − rider payout
A27: C. Cost inputs
A28: WhatsApp message | B28: 0.115 | C28: ₹/tap | D28: Meta utility rate ₹0.115 from 1 Oct 2026 + 18% GST (Whautomate)
A29: Masked call rate per leg | B29: 1.5 | C29: ₹/min per leg | D29: TeleCMI: masking in India 'typically starts around Rs.1.50 per minute'; both legs billed
A30: Minutes per answered call | B30: 2 | C30: minutes | D30: ASSUMPTION: enough to say 'coming down' or give directions
A31: Ring time billed on an unanswered call | B31: 0.5 | C31: minutes | D31: ASSUMPTION: ~30 s timeout, customer leg only (Exotel can bill from ringing)
A32: Truecaller verified caller ID | B32: 0.3 | C32: ₹/call | D32: ASSUMPTION: enterprise-negotiated, price not public. Midpoint of ₹0.10–0.50 range (see section G)
A33: Scoring engine running cost | B33: 0 | C33: ₹/day | D33: Built by the existing team on existing data; running cost not public (0 = blank)
A35: D. Where the 52,348 fake attempts go (per day)
A36: Step | B36: Rate | C36: Orders per day | D36: Source / note
A37: Fake attempts | C37: =B18 -> 52348 | D37: From section A (small + large hubs)
A38: Customer replies to call / WhatsApp → fake exposed | B38: 0.55 | C38: =C37*B38 -> 28791.4 | D38: WEAKEST INPUT. Low end of HillTeck vendor range (calls 55–70%, WhatsApp 60–75%) for D2C order confirmation, not doorstep calls. Validate in pilot week 1; see section F.
A39: Customer silent | C39: =C37-C38 -> 23556.6 | D39: Fake attempts − customer replies
A40: …of these, caught by the confidence-based geofence | B40: 0.07 | C40: =C39*B40 -> 1648.962 | D40: Location check alone: Flipkart cut fake attempts 7% with better geocodes (peer-reviewed). Not Blowhorn's >25%, which includes customer calls and would double-count.
A41: …of the rest, caught by peer comparison | B41: 0 | C41: =(C39-C40)*B41 -> 0 | D41: No published figure: 0 until the pilot measures it
A42: Total fake attempts caught | C42: =C38+C40+C41 -> 30440.362 | D42: Sum of the three
A43: Rider sent back → parcel delivered | B43: 0.85 | C43: =C42*B43 -> 25874.308 | D43: ~85% delivered near the hub (case pack: RTO 15% at ~2 km)
...

Sheet 3. Monthly projection
A1: Monthly projection: all Valmo orders, fake attempts falling as the system deters riders
A2: Input | B2: Value | C2: Unit
A3: Valmo orders per day today | B3: 4200000 | C3: orders/day
A4: Valmo share of Meesho shipped orders today | B4: 0.6452 | C4: %
A5: Increase in Valmo share per month | B5: 0.01 | C5: points/month
A6: Maximum Valmo share | B6: 0.85 | C6: %
A7: Growth in Meesho's total orders per month | B7: 0 | C7: %/month
A8: Share of orders through small hubs | B8: ='2. Financials'!$B$8/'2. Financials'!$B$17 -> 0.3685567 | C8: %
A9: Starting fake-attempt rate, small hubs | B9: 0.02 | C9: % of orders
A10: Starting fake-attempt rate, large hubs | B10: 0.04 | C10: % of orders
A11: Monthly fall in fake-attempt rate once riders know they are checked | B11: 0.1 | C11: % per month
A12: Genuine 'customer not home' rate | B12: =(2006-1821-90)/2006-1.14% -> 0.035957926 | C12: % of orders
A13: Days per month | B13: 30 | C13: days
A14: Month-by-month
A15: Month | B15: Valmo share | C15: Valmo orders / day | D15: Fake rate small | E15: Fake rate large | F15: Fakes / day with system | G15: Fakes / day without system | H15: Fakes prevented / day | I15: Fakes caught / day | J15: RTOs avoided / day | K15: 'Unavailable' taps / day | L15: Saved ₹ Cr | M15: Cost ₹ Cr | N15: Net ₹ Cr | O15: Cumulative net ₹ Cr
A16: 1 | B16: =MIN($B$6,$B$4+$B$5*(A16-1)) -> 0.6452 | C16: =$B$3*(B16/$B$4)*(1+$B$7)^(A16-1) -> 4200000 | D16: =$B$9*(1-$B$11)^(A16-1) -> 0.02 | E16: =$B$10*(1-$B$11)^(A16-1) -> 0.04 | F16: =C16*($B$8*D16+(1-$B$8)*E16) -> 137041.24 | G16: =C16*($B$8*$B$9+(1-$B$8)*$B$10) -> 137041.24 | H16: =G16-F16 -> 0 | I16: =F16*('2. Financials'!$B$38+(1-'2. Financials'!$B$38)*'2. Financials'!$B$40+(1-'2. Financials'!$B$38)*(1-'2. Financials'!$B$40)*'2. Financials'!$B$41) -> 79689.479 | J16: =(H16+I16)*'2. Financials'!$B$43*'2. Financials'!$B$44 -> 51402.54 | K16: =C16*($B$12+$B$8*D16+(1-$B$8)*E16) -> 288064.53 | L16: =J16*'2. Financials'!$B$25*$B$13/10^7 -> 18.504914 | M16: =(K16*('2. Financials'!$B$28+'2. Financials'!$B$32)+K16*'2. Financials'!$B$38*'2. Financials'!$B$29*2*'2. Financials'!$B$30+K16*(1-'2. Financials'!$B$38)*'2. Financials'!$B$29*'2. Financials'!$B$31+'2. Financials'!$B$33)*$B$13/10^7 -> 3.5021445 | N16: =L16-M16 -> 15.00277 | O16: =SUM($N$16:N16) -> 15.00277
A17: 2 | B17: =MIN($B$6,$B$4+$B$5*(A17-1)) -> 0.6552 | C17: =$B$3*(B17/$B$4)*(1+$B$7)^(A17-1) -> 4265096.1 | D17: =$B$9*(1-$B$11)^(A17-1) -> 0.018 | E17: =$B$10*(1-$B$11)^(A17-1) -> 0.036 | F17: =C17*($B$8*D17+(1-$B$8)*E17) -> 125248.72 | G17: =C17*($B$8*$B$9+(1-$B$8)*$B$10) -> 139165.25 | H17: =G17-F17 -> 13916.525 | I17: =F17*('2. Financials'!$B$38+(1-'2. Financials'!$B$38)*'2. Financials'!$B$40+(1-'2. Financials'!$B$38)*(1-'2. Financials'!$B$40)*'2. Financials'!$B$41) -> 72832.133 | J17: =(H17+I17)*'2. Financials'!$B$43*'2. Financials'!$B$44 -> 55955.961 | K17: =C17*($B$12+$B$8*D17+(1-$B$8)*E17) -> 278612.73 | L17: =J17*'2. Financials'!$B$25*$B$13/10^7 -> 20.144146 | M17: =(K17*('2. Financials'!$B$28+'2. Financials'!$B$32)+K17*'2. Financials'!$B$38*'2. Financials'!$B$29*2*'2. Financials'!$B$30+K17*(1-'2. Financials'!$B$38)*'2. Financials'!$B$29*'2. Financials'!$B$31+'2. Financials'!$B$33)*$B$13/10^7 -> 3.3872343 | N17: =L17-M17 -> 16.756911 | O17: =SUM($N$16:N17) -> 31.759681
A18: 3 | B18: =MIN($B$6,$B$4+$B$5*(A18-1)) -> 0.6652 | C18: =$B$3*(B18/$B$4)*(1+$B$7)^(A18-1) -> 4330192.2 | D18: =$B$9*(1-$B$11)^(A18-1) -> 0.0162 | E18: =$B$10*(1-$B$11)^(A18-1) -> 0.0324 | F18: =C18*($B$8*D18+(1-$B$8)*E18) -> 114444.3 | G18: =C18*($B$8*$B$9+(1-$B$8)*$B$10) -> 141289.26 | H18: =G18-F18 -> 26844.96 | I18: =F18*('2. Financials'!$B$38+(1-'2. Financials'!$B$38)*'2. Financials'!$B$40+(1-'2. Financials'!$B$38)*(1-'2. Financials'!$B$40)*'2. Financials'!$B$41) -> 66549.361 | J18: =(H18+I18)*'2. Financials'!$B$43*'2. Financials'!$B$44 -> 60242.649 | K18: =C18*($B$12+$B$8*D18+(1-$B$8)*E18) -> 270149.03 | L18: =J18*'2. Financials'!$B$25*$B$13/10^7 -> 21.687354 | M18: =(K18*('2. Financials'!$B$28+'2. Financials'!$B$32)+K18*'2. Financials'!$B$38*'2. Financials'!$B$29*2*'2. Financials'!$B$30+K18*(1-'2. Financials'!$B$38)*'2. Financials'!$B$29*'2. Financials'!$B$31+'2. Financials'!$B$33)*$B$13/10^7 -> 3.2843369 | N18: =L18-M18 -> 18.403017 | O18: =SUM($N$16:N18) -> 50.162698
A19: 4 | B19: =MIN($B$6,$B$4+$B$5*(A19-1)) -> 0.6752 | C19: =$B$3*(B19/$B$4)*(1+$B$7)^(A19-1) -> 4395288.3 | D19: =$B$9*(1-$B$11)^(A19-1) -> 0.01458 | E19: =$B$10*(1-$B$11)^(A19-1) -> 0.02916 | F19: =C19*($B$8*D19+(1-$B$8)*E19) -> 104548.28 | G19: =C19*($B$8*$B$9+(1-$B$8)*$B$10) -> 143413.27 | H19: =G19-F19 -> 38864.997 | I19: =F19*('2. Financials'!$B$38+(1-'2. Financials'!$B$38)*'2. Financials'!$B$40+(1-'2. Financials'!$B$38)*(1-'2. Financials'!$B$40)*'2. Financials'!$B$41) -> 60794.822 | J19: =(H19+I19)*'2. Financials'!$B$43*'2. Financials'!$B$44 -> 64284.117 | K19: =C19*($B$12+$B$8*D19+(1-$B$8)*E19) -> 262593.73 | L19: =J19*'2. Financials'!$B$25*$B$13/10^7 -> 23.142282 | M19: =(K19*('2. Financials'!$B$28+'2. Financials'!$B$32)+K19*'2. Financials'!$B$38*'2. Financials'!$B$29*2*'2. Financials'!$B$30+K19*(1-'2. Financials'!$B$38)*'2. Financials'!$B$29*'2. Financials'!$B$31+'2. Financials'!$B$33)*$B$13/10^7 -> 3.1924832 | N19: =L19-M19 -> 19.949799 | O19: =SUM($N$16:N19) -> 70.112497
A20: 5 | B20: =MIN($B$6,$B$4+$B$5*(A20-1)) -> 0.6852 | C20: =$B$3*(B20/$B$4)*(1+$B$7)^(A20-1) -> 4460384.4 | D20: =$B$9*(1-$B$11)^(A20-1) -> 0.013122 | E20: =$B$10*(1-$B$11)^(A20-1) -> 0.026244 | F20: =C20*($B$8*D20+(1-$B$8)*E20) -> 95487.012 | G20: =C20*($B$8*$B$9+(1-$B$8)*$B$10) -> 145537.28 | H20: =G20-F20 -> 50050.272 | I20: =F20*('2. Financials'!$B$38+(1-'2. Financials'!$B$38)*'2. Financials'!$B$40+(1-'2. Financials'!$B$38)*(1-'2. Financials'!$B$40)*'2. Financials'!$B$41) -> 55525.698 | J20: =(H20+I20)*'2. Financials'!$B$43*'2. Financials'!$B$44 -> 68100.244 | K20: =C20*($B$12+$B$8*D20+(1-$B$8)*E20) -> 255873.18 | L20: =J20*'2. Financials'!$B$25*$B$13/10^7 -> 24.516088 | M20: =(K20*('2. Financials'!$B$28+'2. Financials'!$B$32)+K20*'2. Financials'!$B$38*'2. Financials'!$B$29*2*'2. Financials'!$B$30+K20*(1-'2. Financials'!$B$38)*'2. Financials'!$B$29*'2. Financials'!$B$31+'2. Financials'!$B$33)*$B$13/10^7 -> 3.1107782 | N20: =L20-M20 -> 21.40531 | O20: =SUM($N$16:N20) -> 91.517807
A21: 6 | B21: =MIN($B$6,$B$4+$B$5*(A21-1)) -> 0.6952 | C21: =$B$3*(B21/$B$4)*(1+$B$7)^(A21-1) -> 4525480.5 | D21: =$B$9*(1-$B$11)^(A21-1) -> 0.0118098 | E21: =$B$10*(1-$B$11)^(A21-1) -> 0.0236196 | F21: =C21*($B$8*D21+(1-$B$8)*E21) -> 87192.519 | G21: =C21*($B$8*$B$9+(1-$B$8)*$B$10) -> 147661.3 | H21: =G21-F21 -> 60468.777 | I21: =F21*('2. Financials'!$B$38+(1-'2. Financials'!$B$38)*'2. Financials'!$B$40+(1-'2. Financials'!$B$38)*(1-'2. Financials'!$B$40)*'2. Financials'!$B$41) -> 50702.45 | J21: =(H21+I21)*'2. Financials'!$B$43*'2. Financials'!$B$44 -> 71709.384 | K21: =C21*($B$12+$B$8*D21+(1-$B$8)*E21) -> 249919.41 | L21: =J21*'2. Financials'!$B$25*$B$13/10^7 -> 25.815378 | M21: =(K21*('2. Financials'!$B$28+'2. Financials'!$B$32)+K21*'2. Financials'!$B$38*'2. Financials'!$B$29*2*'2. Financials'!$B$30+K21*(1-'2. Financials'!$B$38)*'2. Financials'!$B$29*'2. Financials'!$B$31+'2. Financials'!$B$33)*$B$13/10^7 -> 3.0383952 | N21: =L21-M21 -> 22.776983 | O21: =SUM($N$16:N21) -> 114.29479
A22: 7 | B22: =MIN($B$6,$B$4+$B$5*(A22-1)) -> 0.7052 | C22: =$B$3*(B22/$B$4)*(1+$B$7)^(A22-1) -> 4590576.6 | D22: =$B$9*(1-$B$11)^(A22-1) -> 0.01062882 | E22: =$B$10*(1-$B$11)^(A22-1) -> 0.02125764 | F22: =C22*($B$8*D22+(1-$B$8)*E22) -> 79602.054 | G22: =C22*($B$8*$B$9+(1-$B$8)*$B$10) -> 149785.31 | H22: =G22-F22 -> 70183.254 | I22: =F22*('2. Financials'!$B$38+(1-'2. Financials'!$B$38)*'2. Financials'!$B$40+(1-'2. Financials'!$B$38)*(1-'2. Financials'!$B$40)*'2. Financials'!$B$41) -> 46288.594 | J22: =(H22+I22)*'2. Financials'!$B$43*'2. Financials'!$B$44 -> 75128.472 | K22: =C22*($B$12+$B$8*D22+(1-$B$8)*E22) -> 244669.67 | L22: =J22*'2. Financials'!$B$25*$B$13/10^7 -> 27.04625 | M22: =(K22*('2. Financials'!$B$28+'2. Financials'!$B$32)+K22*'2. Financials'!$B$38*'2. Financials'!$B$29*2*'2. Financials'!$B$30+K22*(1-'2. Financials'!$B$38)*'2. Financials'!$B$29*'2. Financials'!$B$31+'2. Financials'!$B$33)*$B$13/10^7 -> 2.9745715 | N22: =L22-M22 -> 24.071679 | O22: =SUM($N$16:N22) -> 138.36647
A23: 8 | B23: =MIN($B$6,$B$4+$B$5*(A23-1)) -> 0.7152 | C23: =$B$3*(B23/$B$4)*(1+$B$7)^(A23-1) -> 4655672.7 | D23: =$B$9*(1-$B$11)^(A23-1) -> 0.009565938 | E23: =$B$10*(1-$B$11)^(A23-1) -> 0.019131876 | F23: =C23*($B$8*D23+(1-$B$8)*E23) -> 72657.756 | G23: =C23*($B$8*$B$9+(1-$B$8)*$B$10) -> 151909.32 | H23: =G23-F23 -> 79251.563 | I23: =F23*('2. Financials'!$B$38+(1-'2. Financials'!$B$38)*'2. Financials'!$B$40+(1-'2. Financials'!$B$38)*(1-'2. Financials'!$B$40)*'2. Financials'!$B$41) -> 42250.485 | J23: =(H23+I23)*'2. Financials'!$B$43*'2. Financials'!$B$44 -> 78373.13 | K23: =C23*($B$12+$B$8*D23+(1-$B$8)*E23) -> 240066.09 | L23: =J23*'2. Financials'!$B$25*$B$13/10^7 -> 28.214327 | M23: =(K23*('2. Financials'!$B$28+'2. Financials'!$B$32)+K23*'2. Financials'!$B$38*'2. Financials'!$B$29*2*'2. Financials'!$B$30+K23*(1-'2. Financials'!$B$38)*'2. Financials'!$B$29*'2. Financials'!$B$31+'2. Financials'!$B$33)*$B$13/10^7 -> 2.9186035 | N23: =L23-M23 -> 25.295723 | O23: =SUM($N$16:N23) -> 163.66219
A24: 9 | B24: =MIN($B$6,$B$4+$B$5*(A24-1)) -> 0.7252 | C24: =$B$3*(B24/$B$4)*(1+$B$7)^(A24-1) -> 4720768.8 | D24: =$B$9*(1-$B$11)^(A24-1) -> 0.0086093442 | E24: =$B$10*(1-$B$11)^(A24-1) -> 0.017218688 | F24: =C24*($B$8*D24+(1-$B$8)*E24) -> 66306.298 | G24: =C24*($B$8*$B$9+(1-$B$8)*$B$10) -> 154033.33 | H24: =G24-F24 -> 87727.033 | I24: =F24*('2. Financials'!$B$38+(1-'2. Financials'!$B$38)*'2. Financials'!$B$40+(1-'2. Financials'!$B$38)*(1-'2. Financials'!$B$40)*'2. Financials'!$B$41) -> 38557.112 | J24: =(H24+I24)*'2. Financials'!$B$43*'2. Financials'!$B$44 -> 81457.752 | K24: =C24*($B$12+$B$8*D24+(1-$B$8)*E24) -> 236055.35 | L24: =J24*'2. Financials'!$B$25*$B$13/10^7 -> 29.324791 | M24: =(K24*('2. Financials'!$B$28+'2. Financials'!$B$32)+K24*'2. Financials'!$B$38*'2. Financials'!$B$29*2*'2. Financials'!$B$30+K24*(1-'2. Financials'!$B$38)*'2. Financials'!$B$29*'2. Financials'!$B$31+'2. Financials'!$B$33)*$B$13/10^7 -> 2.869843 | N24: =L24-M24 -> 26.454948 | O24: =SUM($N$16:N24) -> 190.11714
A25: 10 | B25: =MIN($B$6,$B$4+$B$5*(A25-1)) -> 0.7352 | C25: =$B$3*(B25/$B$4)*(1+$B$7)^(A25-1) -> 4785864.8 | D25: =$B$9*(1-$B$11)^(A25-1) -> 0.0077484098 | E25: =$B$10*(1-$B$11)^(A25-1) -> 0.01549682 | F25: =C25*($B$8*D25+(1-$B$8)*E25) -> 60498.554 | G25: =C25*($B$8*$B$9+(1-$B$8)*$B$10) -> 156157.34 | H25: =G25-F25 -> 95658.789 | I25: =F25*('2. Financials'!$B$38+(1-'2. Financials'!$B$38)*'2. Financials'!$B$40+(1-'2. Financials'!$B$38)*(1-'2. Financials'!$B$40)*'2. Financials'!$B$41) -> 35179.909 | J25: =(H25+I25)*'2. Financials'!$B$43*'2. Financials'!$B$44 -> 84395.6 | K25: =C25*($B$12+$B$8*D25+(1-$B$8)*E25) -> 232588.33 | L25: =J25*'2. Financials'!$B$25*$B$13/10^7 -> 30.382416 | M25: =(K25*('2. Financials'!$B$28+'2. Financials'!$B$32)+K25*'2. Financials'!$B$38*'2. Financials'!$B$29*2*'2. Financials'!$B$30+K25*(1-'2. Financials'!$B$38)*'2. Financials'!$B$29*'2. Financials'!$B$31+'2. Financials'!$B$33)*$B$13/10^7 -> 2.8276926 | N25: =L25-M25 -> 27.554723 | O25: =SUM($N$16:N25) -> 217.67186
A26: 11 | B26: =MIN($B$6,$B$4+$B$5*(A26-1)) -> 0.7452 | C26: =$B$3*(B26/$B$4)*(1+$B$7)^(A26-1) -> 4850960.9 | D26: =$B$9*(1-$B$11)^(A26-1) -> 0.0069735688 | E26: =$B$10*(1-$B$11)^(A26-1) -> 0.013947138 | F26: =C26*($B$8*D26+(1-$B$8)*E26) -> 55189.296 | G26: =C26*($B$8*$B$9+(1-$B$8)*$B$10) -> 158281.35 | H26: =G26-F26 -> 103092.06 | I26: =F26*('2. Financials'!$B$38+(1-'2. Financials'!$B$38)*'2. Financials'!$B$40+(1-'2. Financials'!$B$38)*(1-'2. Financials'!$B$40)*'2. Financials'!$B$41) -> 32092.575 | J26: =(H26+I26)*'2. Financials'!$B$43*'2. Financials'!$B$44 -> 87198.883 | K26: =C26*($B$12+$B$8*D26+(1-$B$8)*E26) -> 229619.79 | L26: =J26*'2. Financials'!$B$25*$B$13/10^7 -> 31.391598 | M26: =(K26*('2. Financials'!$B$28+'2. Financials'!$B$32)+K26*'2. Financials'!$B$38*'2. Financials'!$B$29*2*'2. Financials'!$B$30+K26*(1-'2. Financials'!$B$38)*'2. Financials'!$B$29*'2. Financials'!$B$31+'2. Financials'!$B$33)*$B$13/10^7 -> 2.7916026 | N26: =L26-M26 -> 28.599995 | O26: =SUM($N$16:N26) -> 246.27186
A27: 12 | B27: =MIN($B$6,$B$4+$B$5*(A27-1)) -> 0.7552 | C27: =$B$3*(B27/$B$4)*(1+$B$7)^(A27-1) -> 4916057 | D27: =$B$9*(1-$B$11)^(A27-1) -> 0.0062762119 | E27: =$B$10*(1-$B$11)^(A27-1) -> 0.012552424 | F27: =C27*($B$8*D27+(1-$B$8)*E27) -> 50336.904 | G27: =C27*($B$8*$B$9+(1-$B$8)*$B$10) -> 160405.37 | H27: =G27-F27 -> 110068.46 | I27: =F27*('2. Financials'!$B$38+(1-'2. Financials'!$B$38)*'2. Financials'!$B$40+(1-'2. Financials'!$B$38)*(1-'2. Financials'!$B$40)*'2. Financials'!$B$41) -> 29270.909 | J27: =(H27+I27)*'2. Financials'!$B$43*'2. Financials'!$B$44 -> 89878.836 | K27: =C27*($B$12+$B$8*D27+(1-$B$8)*E27) -> 227108.12 | L27: =J27*'2. Financials'!$B$25*$B$13/10^7 -> 32.356381 | M27: =(K27*('2. Financials'!$B$28+'2. Financials'!$B$32)+K27*'2. Financials'!$B$38*'2. Financials'!$B$29*2*'2. Financials'!$B$30+K27*(1-'2. Financials'!$B$38)*'2. Financials'!$B$29*'2. Financials'!$B$31+'2. Financials'!$B$33)*$B$13/10^7 -> 2.761067 | N27: =L27-M27 -> 29.595314 | O27: =SUM($N$16:N27) -> 275.86717
A28: Year | I28: Avg / total → | J28: =AVERAGE(J16:J27) -> 72343.964 | L28: =SUM(L16:L27) -> 312.52592 | M28: =SUM(M16:M27) -> 36.658753 | N28: =SUM(N16:N27) -> 275.86717

Sheet RMS
A1: Risk | B1: Impact | C1: Probability | D1: Guardrail
A2: Poor/uncertain GPS & address accuracy in Tier 3/4 | B2: High | C2: High | D2: Use GeoIndia confidence-based adaptive geofencing + road accessibility + historical delivery locations; never use a fixed radius
A3: Customer doesn't answer IVR/WhatsApp | B3: High | C3: High | D3: No response = inconclusive; rely on Geo + call + rider history; use IVR/SMS fallback
A4: Customer gives incorrect response / colludes with rider | B4: High | C4: Medium | D4: Customer response is only one signal; require convergence across independent signals
A5: GPS spoofing / deliberate rider gaming | B5: High | C5: Medium | D5: Combine GPS with trajectory, dwell, call behaviour and locality-level rider anomaly; no single signal triggers punishment
A6: High RTO in genuinely difficult locality | B6: High | C6: Medium | D6: Compare rider against matched local peers and adjust for COD, distance, address quality and delivery time
A7: AI false positives | B7: High | C7: Medium | D7: Use Genuine / Uncertain / Suspicious classification; high-impact action requires high-confidence evidence + human review
A8: IVR bridging cost too high | B8: Medium | C8: Medium | D8: Use risk-based escalation; bridge only ambiguous/high-risk attempts rather than every NDR
A9: Verification creates customer/rider friction | B9: Medium | C9: Medium | D9: One-tap WhatsApp + short IVR; passive telemetry; limit verification to failed attempts
A10: Poor network prevents telemetry / customer response | B10: Medium | C10: High | D10: Offline-first rider telemetry + SMS/IVR fallback; missing data reduces confidence rather than increasing fraud probability
A11: New rider has insufficient history | B11: Medium | C11: Medium | D11: Use locality peer benchmark until sufficient rider-level data is available
A14: Risk | B14: Impact | C14: Probability | D14: Guardrail
... A19: False-positive rider punishment | B19: High | C19: Medium | D19: 3-way output: Genuine / Uncertain / Suspicious; investigation before action

Sheet KPI
A1: KPI | B1: Formula | C1: What it tells
A2: RTO Rate | B2: Total RTO Orders ÷ Total Orders × 100 | C2: Overall scale of the RTO problem
A3: Fake-Attempt RTO Rate | B3: Fake-Attempt RTOs ÷ Total RTOs × 100 | C3: How much of RTO is attributable to suspected/genuine fake attempts
A4: Prevented RTOs | B4: Orders that would have reached RTO but were successfully delivered after intervention | C4: Direct number of RTOs prevented by the solution
A5: Detection Precision | B5: Confirmed Fake Attempts ÷ Attempts Flagged as Suspicious × 100 | C5: How accurately the AI identifies fake attempts without wrongly flagging genuine attempts
A6: False Positive Rate | B6: Genuine Attempts Incorrectly Flagged ÷ Total Genuine Attempts × 100 | C6: How often genuine riders are incorrectly flagged
A7: Customer Response Rate | B7: Customers Responding to IVR/WhatsApp ÷ Customers Contacted × 100 | C7: How effectively the customer-verification layer obtains usable evidence
A8: Cost per Prevented RTO | B8: Total Solution Cost ÷ Prevented RTOs | C8: Cost required to prevent each RTO
A9: Net Savings | B9: Avoided RTO Cost − (Telephony + WhatsApp + AI/Infrastructure + Incremental Reattempt Costs) | C9: Actual financial benefit generated by the solution
A14: KPI
A15: Fake-Attempt RTO Rate ↓ | E15: Target / Direction
A16: Fake-Attempt RTO Reduction ↑ | E16: ↓
A17: Detection Precision ↑ | E17: ↓
A18: False Positive Rate ↓ | E18: ↑
A19: Customer Verification Response Rate ↑ | E19: ↑
A20: Cost per RTO Prevented ↓ | E20: ↑
E21: ↑
E22: ↑
E23: ↑
E24: ↓
E25: ↓
E26: ↓
E27: ↑
E28: ↑
E29: ↑
E30: ↑
E31: Monitor
E32: ↓
... E55: ↓
