Workbook
Name Running_M: 'India Rollout'!$B$14
Name Rent_Method: Profitability!$B$19
Name Rent_Sold: Profitability!$B$20
Name ST_Target: Inputs!$B$45
Name COD_Share: Inputs!$B$5
Name Maint_P: Profitability!$B$57
Name Net_Sold_High: 'Unit Economics'!$D$23
Name OneTime_Hubs: 'India Rollout'!$B$12
Name Gateway: Inputs!$B$27
Name Y_ST: 'India Rollout'!$B$18:$E$18
Name Eligible: Inputs!$B$10
Name RTO_Prepaid: Inputs!$B$7
Name Prof2: Profitability!$C$34
Name Hubs: Inputs!$B$8
Name RTO_Rate: 'India Rollout'!$B$3
Name Y_NetBase: 'India Rollout'!$B$21:$E$21
Name Remote_Uplift: 'Unit Economics'!$B$41
Name TierB_Transfer: 'Unit Economics'!$C$39
Name Save_Unsold: 'Unit Economics'!$E$24
Name C_Training: Inputs!$B$53
Name Route_Sourced: 'Unit Economics'!$B$32
Name ST_M1: Profitability!$B$22
Name Rent_Parcel: Profitability!$B$18
Name AOV: Inputs!$B$39
Name Route_High: Inputs!$B$26
Name N_FMCart: Inputs!$B$15
Name Routed_D_P: Profitability!$B$55
Name LM_Remote: Inputs!$B$31
Name YP_Base: Profitability!$B$104:$E$104
Name Y_Share: 'India Rollout'!$B$20:$E$20
Name Y_Saved: 'India Rollout'!$B$19:$E$19
Name Days_Sold: Inputs!$B$35
Name Prof1: Profitability!$B$34
Name RTO_Cost_Year: 'India Rollout'!$B$24
Name N_FMSC: Inputs!$B$16
Name Orders: Inputs!$B$4
Name RTO_Day: 'India Rollout'!$B$4
Name Routed_Hub: Profitability!$B$17
Name OneTime_P: Profitability!$B$58
Name Shelf: Inputs!$B$9
Name Leg_Other: 'Unit Economics'!$B$7
Name C_Scanner: Inputs!$B$51
Name Save_Sold_High: 'Unit Economics'!$D$24
Name Payback_High: 'India Rollout'!$C$23
Name Rent_Hub: Profitability!$B$16
Name N_LMSC: Inputs!$B$18
Name OneTime_Central: 'India Rollout'!$B$11
Name Other_Avoid: Inputs!$B$22
Name Rev_Sale: Profitability!$B$12
Name N_LMDC: Inputs!$B$20
Name C_Maint: Inputs!$B$54
Name N_FMHub: Inputs!$B$14
Name Leg_Attempt: 'Unit Economics'!$B$5
Name Cap_Day: 'India Rollout'!$B$6
Name Rent_Unsold: Profitability!$B$21
Name Net_Today: 'Unit Economics'!$B$23
Name RTO_Avoid_Sale: Profitability!$B$125
Name ST_Start: Inputs!$B$44
Name C_Support: Inputs!$B$55
Name C_HubMonthly: Inputs!$B$56

Sheet Summary
A1: Hypersale — financial summary
A2: Per parcel | D2: India-wide (all 2,700 hubs)
B3: ₹35 base | C3: ₹45 high | E3: ₹35 base | F3: ₹45 high
A4: Today: cost of one RTO | B4: =-Net_Today -> 120 | C4: =-Net_Today -> 120 | D4: Year 1 net profit (after setup) | E4: {=INDEX(Y_NetBase,1)} -> 410.94251 | F4: {=INDEX(Y_NetHigh,1)} -> 376.66999
A5: Saving when a parcel sells | B5: =Save_Sold_Base -> 127.72058 | C5: =Save_Sold_High -> 117.72058 | D5: Year 2 net profit | E5: {=INDEX(Y_NetBase,2)} -> 669.90238 | F5: {=INDEX(Y_NetHigh,2)} -> 615.78787
A6: Saving when it doesn't sell | B6: =Save_Unsold -> -2.2764228 | C6: =Save_Unsold -> -2.2764228 | D6: 3-year net profit | E6: {=INDEX(Y_NetBase,4)} -> 1750.7473 | F6: {=INDEX(Y_NetHigh,4)} -> 1608.2457
A7: Saving per parcel routed (steady state) | B7: =ST_Target*Save_Sold_Base+(1-ST_Target)*Save_Unsold -> 46.472452 | C7: =ST_Target*Save_Sold_High+(1-ST_Target)*Save_Unsold -> 42.722452 | D7: Payback month | E7: =Payback_Base -> 1 | F7: =Payback_High -> 1
A8: Furthest profitable radius | B8: =IF('Unit Economics'!D40>0,"Another city",IF('Unit Economics'!D39>0,"Nearby hub","Same hub only")) -> Another city | C8: =IF('Unit Economics'!E40>0,"Another city",IF(ROUND('Unit Economics'!E39,2)>0,"Nearby hub","Same hub only")) -> Another city | D8: One-time setup cost | E8: =OneTime/10^7 -> 1.02 | F8: =OneTime/10^7 -> 1.02
A10: RTO impact
B11: Year 1 | C11: Year 2
A12: RTO parcels saved from the reverse trip | B12: {=INDEX(Y_Saved,1)} -> 342.72522 | C12: {=INDEX(Y_Saved,2)} -> 541.14509
A13: Share of all RTO parcels saved | B13: {=INDEX(Y_Share,1)} -> 0.13150885 | C13: {=INDEX(Y_Share,2)} -> 0.20764556
A14: Parcels routed into Hypersale per day | B14: =Routed_Day -> 395357.14 | C14: =IF(Elig_Day>Cap_Day,"limited by shelf space","limited by eligible parcels") -> limited by shelf space
A15: Today's total Valmo RTO cost per year | B15: =RTO_Cost_Year -> 3127.32
A17: Key assumptions
A18: Assumption | B18: Value | D18: Type
A19: Sell-through: month 1 → steady state | B19: =TEXT(ST_Start,"0%")&" → "&TEXT(ST_Target,"0.0%")&" over "&Ramp&" months" -> 10% → 37.5% over 12 months | D19: Assumption; 37.5% = Zomato proxy (ceiling)
A20: Routing + repack + delivery per sale | B20: ="₹"&Route_Base&" base / ₹"&Route_High&" high" -> ₹35 base / ₹45 high | D20: Assumption anchored to ₹31.7 sourced
A21: Fees per sale (express + seller) | B21: ="₹"&TEXT(AOV*Fee_Express,"0")&" + ₹"&TEXT(AOV*Fee_Seller,"0") -> ₹15 + ₹30 | D21: Assumption
A22: Eligible share of RTO parcels | B22: =Eligible -> 0.9 | D22: Assumption
A23: RTO parcels routed limited by | B23: ="Shelf: "&TEXT(Shelf,"0")&" per hub per week" -> Shelf: 1025 per hub per week | D23: Design decision
A24: App build + cloud setup | B24: =OneTime_Central/10^7 -> 1.02 | D24: Published source (top of range)

Sheet Inputs
A1: Input Costs
A2: Assumption | B2: Value | C2: Unit | D2: Source / note
A3: A. Network & volume
A4: Valmo orders per day | B4: 4200000 | C4: orders | D4: Team field research: ~42 lakh Valmo orders/day
A5: COD share of orders | B5: 0.8 | C5: % | D5: Case data pack
A6: RTO rate — COD orders | B6: 0.2 | C6: % | D6: Case data pack
A7: RTO rate — prepaid orders | B7: 0.05 | C7: % | D7: Case data pack
A8: Valmo last-mile hubs | B8: 2700 | C8: hubs | D8: Team field research
A9: Hold-shelf capacity per hub | B9: =0.65*500+0.35*2000 -> 1025 | C9: parcels/week | D9: Shelf holds one week of RTO pieces (~500/hub)
A10: Share of RTO parcels eligible for Hypersale | B10: 0.9 | C10: % | D10: Rest excluded: opened/damaged, large, perishable (cf. Ozon's exclusions)
A12: B. Today's cost of one RTO (₹ per order)
A13: Total cost of one RTO | B13: 120 | C13: ₹/order | D13: Case data pack: ₹120 per RTO shipment (total)
A14: Node cost — First-mile hub | B14: 4 | C14: ₹/order | D14: Case data pack node split
A15: Node cost — First-mile carting | B15: 2 | C15: ₹/order | D15: Case data pack node split
A16: Node cost — Source sort centre (FMSC) | B16: 5 | C16: ₹/order | D16: Case data pack node split
A17: Node cost — National line haul | B17: 8 | C17: ₹/order | D17: Case data pack node split
A18: Node cost — Destination sort centre (LMSC) | B18: 5 | C18: ₹/order | D18: Case data pack node split
A19: Node cost — Regional line haul | B19: 5 | C19: ₹/order | D19: Case data pack node split
A20: Node cost — Last-mile delivery (LMDC) | B20: 14 | C20: ₹/order | D20: Rest ₹7 Accounted later
A21: Reverse trip back to the seller | B21: 29 | C21: ₹/order | D21: Retraces the forward path to the last-mile hub (₹29); not given separately in the pack
A22: Share of 'other RTO costs' avoided when the item is resold | B22: 0.3 | C22: % | D22: atleast ₹24 is saved
A24: C. Hypersale cost per sale
A25: Routing + repack + delivery — BASE case | B25: 35 | C25: ₹/sale | D25: Anchored to the sourced breakup on 'Unit Economics' (₹31.7) + ~4 min hub labour
A26: Routing + repack + delivery — HIGH case | B26: 45 | C26: ₹/sale | D26: ₹31.7 sourced + ~17 min hub labour, re-sort and support
A27: Payment gateway fee (Hypersale is prepaid only) | B27: 0.0236 | C27: % of payment | D27: Razorpay standard: 2% + 18% GST
A28: New tamper-proof courier bag | B28: 1.5 | C28: ₹/sale | D28: IndiaMART: LDPE security envelope, ₹3/piece
A29: New shipping label | B29: 1 | C29: ₹/sale | D29: IndiaMART label listings: ₹0.25–1/piece (top used)
A30: Hub staff wage | B30: 15000 | C30: ₹/month | D30: 500 x 7 x (30/7) with ₹7 commission to hub manager
A31: Last-mile cost when the buyer is at another hub | B31: 25 | C31: ₹/sale | D31: Team assumption for extended-radius deliveries (vs ₹21 local)
A32: Share of sales delivered from another hub (Tier B) | B32: 0.25 | C32: % | D32: Needs hub data; see 'Scenarios' for 10–65%
A33: Listing / QC cost per held item (paid even if unsold) | B33: 0 | C33: ₹/item | D33: Set to 0 if already inside the ₹35/₹45
A34: Holding cost per item per day | B34: =((10000/30)/(Shelf/7)) -> 2.2764228 | C34: ₹/item/day | D34: Rent ₹10,000/month ÷ 30 days ÷ parcels sitting on the shelf at one time (≈ one week's intake = Shelf). Rent counted here only.
A35: Average days held before a sale | B35: 3 | C35: days | D35: Needs pilot data
A36: Maximum hold window | B36: 7 | C36: days | D36: Unsold items go back to the seller after 7 days
A38: D. Hypersale revenue
A39: Average order value | B39: 270 | C39: ₹/order | D39: Team field research
A40: Customer express fee | B40: 0.055555556 | C40: % of AOV | D40: Equals ₹15; team's own ₹10–15 for 1-day delivery. Ref: Amazon ₹5, Flipkart ₹3 platform fees
A41: Seller protection fee | B41: 0.1111 | C41: % of AOV | D41: Equals ₹20; no benchmark — sellers' alternative is a ₹35–45 reship (Shiprocket)
A43: E. Demand (sell-through)
A44: Sell-through in month 1 | B44: 0.1 | C44: % | D44: Team assumption
...

Sheet Profitability
A1: Hypersale profitability — the channel pays for itself on fees alone
A2: A. What this view counts, and what it leaves out
A3: Counted as revenue | B3: Customer express fee + seller protection fee, on every Hypersale sale
A4: Counted as cost | B4: Routing + repack + delivery to the new buyer, and shelf rent
A5: NOT counted (upside) | B5: The ₹29 reverse trip the sale avoids, and any share of the ₹62 other RTO cost — shown as a memo line only
A6: NOT counted (removed) | B6: The ₹6.5 average remote-hub transfer cost
A7: B. Inputs for this view
A8: Input | B8: Value | C8: Unit
A9: Average order value | B9: =AOV -> 270 | C9: ₹/order
A10: Customer express fee | B10: =Fee_Express -> 0.055555556 | C10: % of AOV
A11: Seller protection fee | B11: =Fee_Seller -> 0.1111 | C11: % of AOV
A12: Revenue per Hypersale sale | B12: =AOV_P*FeeE_P+AOV_P*FeeS_P -> 44.997 | C12: ₹/sale
A13: Routing + repack + delivery — case 1 | B13: =Route_Base -> 35 | C13: ₹/sale
A14: Routing + repack + delivery — case 2 | B14: 40 | C14: ₹/sale
A15: Routing + repack + delivery — case 3 | B15: =Route_High -> 45 | C15: ₹/sale
A16: Shelf rent per hub | B16: 10000 | C16: ₹/month
A17: Parcels routed per hub | B17: =Shelf*30/7 -> 4392.8571 | C17: parcels/month
A18: Shelf rent per parcel routed | B18: =Rent_Hub/Routed_Hub -> 2.2764228 | C18: ₹/parcel
A19: Rent method: 1 = once per parcel routed, 2 = per day on the shelf | B19: 1 | C19: 1 or 2
A20: Rent charged to a parcel that sells | B20: =IF(Rent_Method=1,Rent_Parcel,Rent_Parcel*Days_Sold) -> 2.2764228 | C20: ₹/sale
A21: Rent charged to a parcel that does not sell | B21: =IF(Rent_Method=1,Rent_Parcel,Rent_Parcel*Hold_Max) -> 2.2764228 | C21: ₹/parcel
A22: Sell-through, month 1 | B22: 0.05 | C22: %
A23: Sell-through, end of year 1 (month 12) | B23: 0.2 | C23: %
A24: Sell-through, end of year 3 (month 36) | B24: 0.375 | C24: %
A26: C. Profit on one Hypersale sale
A27: ₹ per sale | B27: ₹35 case | C27: ₹40 case | D27: ₹45 case
A28: Customer express fee | B28: =AOV_P*FeeE_P -> 15 | C28: =AOV_P*FeeE_P -> 15 | D28: =AOV_P*FeeE_P -> 15
A29: Seller protection fee | B29: =AOV_P*FeeS_P -> 29.997 | C29: =AOV_P*FeeS_P -> 29.997 | D29: =AOV_P*FeeS_P -> 29.997
A30: Revenue per sale | B30: =SUM(B28:B29) -> 44.997 | C30: =SUM(C28:C29) -> 44.997 | D30: =SUM(D28:D29) -> 44.997
A31: Routing + repack + delivery to the new buyer | B31: -35 | C31: -45 | D31: -55
A32: Shelf rent | B32: =-Rent_Sold -> -2.2764228 | C32: =-Rent_Sold -> -2.2764228 | D32: =-Rent_Sold -> -2.2764228
A33: Cost per sale | B33: =SUM(B31:B32) -> -37.276423 | C33: =SUM(C31:C32) -> -47.276423 | D33: =SUM(D31:D32) -> -57.276423
A34: PROFIT per sale | B34: =B30+B33 -> 7.7205772 | C34: =C30+C33 -> -2.2794228 | D34: =D30+D33 -> -12.279423
A35: Margin on the sale | B35: =B34/B30 -> 0.17157982 | C35: =C34/C30 -> -0.050657216 | D35: =D34/D30 -> -0.27289425
A37: D. Profit on one parcel put on the shelf (sold and unsold together)
A38: Sell-through | B38: ₹35 case | C38: ₹40 case | D38: ₹45 case
A39: 0.05 | B39: =$A39*Prof1-(1-$A39)*Rent_Unsold -> -1.7765728 | C39: =$A39*Prof2-(1-$A39)*Rent_Unsold -> -2.2765728 | D39: =$A39*Prof3-(1-$A39)*Rent_Unsold -> -2.7765728
A40: 0.1 | B40: =$A40*Prof1-(1-$A40)*Rent_Unsold -> -1.2767228 | C40: =$A40*Prof2-(1-$A40)*Rent_Unsold -> -2.2767228 | D40: =$A40*Prof3-(1-$A40)*Rent_Unsold -> -3.2767228
A41: 0.2 | B41: =$A41*Prof1-(1-$A41)*Rent_Unsold -> -0.27702276 | C41: =$A41*Prof2-(1-$A41)*Rent_Unsold -> -2.2770228 | D41: =$A41*Prof3-(1-$A41)*Rent_Unsold -> -4.2770228
A42: 0.25 | B42: =$A42*Prof1-(1-$A42)*Rent_Unsold -> 0.22282724 | C42: =$A42*Prof2-(1-$A42)*Rent_Unsold -> -2.2771728 | D42: =$A42*Prof3-(1-$A42)*Rent_Unsold -> -4.7771728
...

Sheet Unit Economics
A1: Unit economics — one RTO parcel
A2: A. What one RTO costs today
A3: Cost leg | B3: ₹ per RTO | F3: How it's calculated
A4: Forward trip to the last-mile hub | B4: =N_FMHub+N_FMCart+N_FMSC+N_NLH+N_LMSC+N_RLH -> 29 | F4: Sum of the six case-pack node costs before last mile
A5: Failed last-mile attempt | B5: 0 | F5: LMDC node cost
A6: Reverse trip back to the seller | B6: =Reverse -> 29 | F6: Team assumption: retraces the forward path
A7: Other RTO costs (not broken down in the pack) | B7: =62+29 -> 91 | F7: Residual: ₹120 minus the three legs above
A8: Total cost of one RTO today | B8: =SUM(B4:B7) -> 149
A10: B. One RTO parcel: today vs Hypersale
A11: Line item (₹ per parcel) | B11: Today: return to seller | C11: Hypersale: sold (₹35 base) | D11: Hypersale: sold (₹45 high) | E11: Hypersale: not sold in 7 days | F11: Note
A12: Forward trip (already spent) | F12: Same in every case
A13: Failed attempt (already spent) | B13: 0 | C13: 0 | D13: 0 | E13: 0 | F13: Same in every case
A14: Reverse trip to seller | B14: =-Leg_Reverse -> -29 | C14: 0 | D14: 0 | E14: =-Leg_Reverse -> -29 | F14: Avoided only when the item sells
A15: Other RTO costs | B15: =-Leg_Other -> -91 | C15: 0 | D15: 0 | E15: =-Leg_Other -> -91 | F15: Share avoided is a missing input (0%)
A16: Routing + repack + delivery to new buyer | B16: 0 | C16: =-Route_Base -> -35 | D16: =-Route_High -> -45 | E16: 0 | F16: ₹35 / ₹45 (breakup in section 3)
A17: Extra cost for buyers at another hub (avg) | B17: 0 | E17: 0 | F17: Tier B share × extra cost (section 4)
A18: Listing / QC handling | B18: 0 | C18: =-Handling -> 0 | D18: =-Handling -> 0 | E18: =-Handling -> 0 | F18: Missing input (0)
A19: Holding on the shelf | B19: 0 | C19: =-Hold_Day -> -2.2764228 | D19: =-Hold_Day -> -2.2764228 | E19: =-Hold_Day -> -2.2764228 | F19: Missing input (0)
A20: Total cost | B20: =SUM(B12:B19) -> -120 | C20: =SUM(C12:C19) -> -37.276423 | D20: =SUM(D12:D19) -> -47.276423 | E20: =SUM(E12:E19) -> -122.27642
A21: Customer express fee | B21: 0 | C21: =AOV*Fee_Express -> 15 | D21: =AOV*Fee_Express -> 15 | E21: 0 | F21: Paid only on a Hypersale sale
A22: Seller protection fee | B22: 0 | C22: =AOV*Fee_Seller -> 29.997 | D22: =AOV*Fee_Seller -> 29.997 | E22: 0 | F22: Paid only on a Hypersale sale
A23: NET cost per parcel | B23: =B20+B21+B22 -> -120 | C23: =C20+C21+C22 -> 7.7205772 | D23: =D20+D21+D22 -> -2.2794228 | E23: =E20+E21+E22 -> -122.27642
A24: Saving vs today | B24: =B23-$B$23 -> 0 | C24: =C23-$B$23 -> 127.72058 | D24: =D23-$B$23 -> 117.72058 | E24: =E23-$B$23 -> -2.2764228
A26: C. What's inside the ₹35 / ₹45 routing cost
A27: Component | B27: ₹ per sale | F27: Source
A28: Last-mile delivery to the new buyer | B28: =N_LMDC -> 14 | F28: Case data pack LMDC node
A29: Payment gateway (on price + express fee) | B29: =Gateway*(AOV+AOV*Fee_Express) -> 6.726 | F29: Razorpay 2.36%
A30: New courier bag | B30: =Bag -> 1.5 | F30: IndiaMART
A31: New label | B31: =Label -> 1 | F31: IndiaMART
A32: Sourced components | B32: =SUM(B28:B31) -> 23.226
A33: Left for hub labour, re-sort, support — base / high | B33: =Route_Base-Route_Sourced -> 11.774 | C33: =Route_High-Route_Sourced -> 21.774 | F33: Base in column C, high in column D
A34: …which buys this many minutes of hub staff time — base / high | B34: =(Route_Base-Route_Sourced)/(Wage/(26*8*60)) -> 9.795968 | C34: =(Route_High-Route_Sourced)/(Wage/(26*8*60)) -> 18.115968 | F34: Wage ÷ (26 days × 8 h × 60 min). A hub time-check settles which case is closer.
A36: D. Remote hubs — how far can the radius extend?
A37: Where the buyer is | B37: Extra last mile | C37: Transfer cost | D37: Saving per sale — ₹35 | E37: Saving per sale — ₹45 | F37: Extend the radius here?
A38: A — same hub (local) | B38: =0 -> 0 | C38: =0 -> 0 | D38: =Save_Sold_Base+Remote_Uplift-B38-C38 -> 134.22058 | E38: =Save_Sold_High+Remote_Uplift-B38-C38 -> 124.22058 | F38: =IF(ROUND(E38,2)>0,"Yes",IF(D38>0,"Base case only (break-even at ₹45)","No — return to seller")) -> Yes
A39: B — another hub, same sort centre | B39: =LM_Remote-N_LMDC -> 11 | C39: =N_RLH+N_LMSC+N_RLH -> 15 | D39: =Save_Sold_Base+Remote_Uplift-B39-C39 -> 108.22058 | E39: =Save_Sold_High+Remote_Uplift-B39-C39 -> 98.220577 | F39: =IF(ROUND(E39,2)>0,"Yes",IF(D39>0,"Base case only (break-even at ₹45)","No — return to seller")) -> Yes
A40: C — a hub in another city | B40: =LM_Remote-N_LMDC -> 11 | C40: =N_RLH+N_LMSC+N_NLH+N_LMSC+N_RLH -> 28 | D40: =Save_Sold_Base+Remote_Uplift-B40-C40 -> 95.220577 | E40: =Save_Sold_High+Remote_Uplift-B40-C40 -> 85.220577 | F40: =IF(ROUND(E40,2)>0,"Yes",IF(D40>0,"Base case only (break-even at ₹45)","No — return to seller")) -> Yes
A41: Average extra cost per sale (Tier B share × Tier B extra cost) | B41: =TierB_Share*(TierB_Extra+TierB_Transfer) -> 6.5 | F41: Tier B share is a missing input (0%) — see Scenarios

Sheet India Rollout
A1: India rollout — volume, costs and 3-year results
A2: A. How many parcels go into Hypersale
A3: Blended RTO rate | B3: =COD_Share*RTO_COD+(1-COD_Share)*RTO_Prepaid -> 0.17 | C3: 80% × 20% + 20% × 5%
A4: RTO parcels per day | B4: =Orders*RTO_Rate -> 714000 | C4: Orders × RTO rate
A5: RTO parcels per day of which eligible for Hypersale | B5: =RTO_Day*Eligible -> 642600 | C5: × 90% eligible
A6: Shelf capacity across all hubs, per day | B6: =Hubs*Shelf/7 -> 395357.14 | C6: 2,700 hubs × 500 per week ÷ 7
A7: Parcels routed into Hypersale per day | B7: =MIN(Elig_Day,Cap_Day) -> 395357.14 | C7: The lower of the two
A8: What limits volume? | B8: =IF(Elig_Day>Cap_Day,"Shelf space","Eligible parcels") -> Shelf space | C8: More shelf/kirana hold space raises volume if shelf-limited
A10: B. Setup and running costs
A11: One-time: app/site build + cloud setup | B11: =C_Build+C_Cloud -> 10200000
A12: One-time: hub equipment (scanner + racks + training) × hubs | B12: =Hubs*(C_Scanner+C_Racks+C_Training+Printer_Note) -> 0
A13: TOTAL one-time cost (charged in month 1) | B13: =OneTime_Central+OneTime_Hubs -> 10200000
A14: Monthly running: maintenance + support + per-hub costs × hubs | B14: =C_Maint+C_Support+C_HubMonthly*Hubs -> 600000
A16: C. Results by year
B17: Year 1 | C17: Year 2 | D17: Year 3 | E17: 3-year total
A18: Average sell-through | B18: =AVERAGE(B29:B40) -> 0.2375 | C18: =AVERAGE(B41:B52) -> 0.375 | D18: =AVERAGE(B53:B64) -> 0.375
A19: RTO parcels saved from the reverse trip | B19: =SUM(D29:D40)/10^5 -> 342.72522 | C19: =SUM(D41:D52)/10^5 -> 541.14509 | D19: =SUM(D53:D64)/10^5 -> 541.14509 | E19: =SUM(D29:D64)/10^5 -> 1425.0154
A20: Share of all RTO parcels saved | B20: =SUM(D29:D40)/(RTO_Day*365) -> 0.13150885 | C20: =SUM(D41:D52)/(RTO_Day*365) -> 0.20764556 | D20: =SUM(D53:D64)/(RTO_Day*365) -> 0.20764556 | E20: =SUM(D29:D64)/(RTO_Day*365*3) -> 0.18226666
A21: Net profit — ₹35 base | B21: =SUM(I29:I40) -> 410.94251 | C21: =SUM(I41:I52) -> 669.90238 | D21: =SUM(I53:I64) -> 669.90238 | E21: =SUM(I29:I64) -> 1750.7473
A22: Net profit — ₹45 high | B22: =SUM(K29:K40) -> 376.66999 | C22: =SUM(K41:K52) -> 615.78787 | D22: =SUM(K53:K64) -> 615.78787 | E22: =SUM(K29:K64) -> 1608.2457
A23: Payback month — ₹35 base / ₹45 high | B23: =IF(J64<0,"Beyond 36",COUNTIF(J29:J64,"<0")+1) -> 1 | C23: =IF(L64<0,"Beyond 36",COUNTIF(L29:L64,"<0")+1) -> 1
A24: Today's total Valmo RTO cost per year (for scale) | B24: =RTO_Day*365*RTO_Total/10^7 -> 3127.32
A27: D. Month-by-month detail
A28: Month | B28: Sell-through | C28: Parcels routed | D28: Sold = RTO saved | E28: Saving — ₹35 | F28: Saving — ₹45 | G28: Running cost | H28: One-time cost | I28: Net — ₹35 | J28: Cumulative — ₹35 | K28: Net — ₹45 | L28: Cumulative — ₹45
A29: 1 | B29: =IF(A29>=Ramp,ST_Target,ST_Start+(ST_Target-ST_Start)*(A29-1)/MAX(1,Ramp-1)) -> 0.1 | C29: =Routed_Day*365/12 -> 12025446 | D29: =C29*B29 -> 1202544.6 | E29: =C29*(B29*Save_Sold_Base+(1-B29)*Save_Unsold)/10^7 -> 12.89522 | F29: =C29*(B29*Save_Sold_High+(1-B29)*Save_Unsold)/10^7 -> 11.692675 | G29: =-Running_M/10^7 -> -0.06 | H29: =IF(A29=1,-OneTime/10^7,0) -> -1.02 | I29: =E29+G29+H29 -> 11.81522 | J29: =I29 -> 11.81522 | K29: =F29+G29+H29 -> 10.612675 | L29: =K29 -> 10.612675
A30: 2 | B30: =IF(A30>=Ramp,ST_Target,ST_Start+(ST_Target-ST_Start)*(A30-1)/MAX(1,Ramp-1)) -> 0.125 | C30: =Routed_Day*365/12 -> 12025446 | D30: =C30*B30 -> 1503180.8 | E30: =C30*(B30*Save_Sold_Base+(1-B30)*Save_Unsold)/10^7 -> 16.803399 | F30: =C30*(B30*Save_Sold_High+(1-B30)*Save_Unsold)/10^7 -> 15.300219 | G30: =-Running_M/10^7 -> -0.06 | H30: =IF(A30=1,-OneTime/10^7,0) -> 0 | I30: =E30+G30+H30 -> 16.743399 | J30: =J29+I30 -> 28.558619 | K30: =F30+G30+H30 -> 15.240219 | L30: =L29+K30 -> 25.852894
A31: 3 | B31: =IF(A31>=Ramp,ST_Target,ST_Start+(ST_Target-ST_Start)*(A31-1)/MAX(1,Ramp-1)) -> 0.15 | C31: =Routed_Day*365/12 -> 12025446 | D31: =C31*B31 -> 1803817 | E31: =C31*(B31*Save_Sold_Base+(1-B31)*Save_Unsold)/10^7 -> 20.711579 | F31: =C31*(B31*Save_Sold_High+(1-B31)*Save_Unsold)/10^7 -> 18.907762 | G31: =-Running_M/10^7 -> -0.06 | H31: =IF(A31=1,-OneTime/10^7,0) -> 0 | I31: =E31+G31+H31 -> 20.651579 | J31: =J30+I31 -> 49.210198 | K31: =F31+G31+H31 -> 18.847762 | L31: =L30+K31 -> 44.700656
A32: 4 | B32: =IF(A32>=Ramp,ST_Target,ST_Start+(ST_Target-ST_Start)*(A32-1)/MAX(1,Ramp-1)) -> 0.175 | C32: =Routed_Day*365/12 -> 12025446 | D32: =C32*B32 -> 2104453.1 | E32: =C32*(B32*Save_Sold_Base+(1-B32)*Save_Unsold)/10^7 -> 24.619759 | F32: =C32*(B32*Save_Sold_High+(1-B32)*Save_Unsold)/10^7 -> 22.515306 | G32: =-Running_M/10^7 -> -0.06 | H32: =IF(A32=1,-OneTime/10^7,0) -> 0 | I32: =E32+G32+H32 -> 24.559759 | J32: =J31+I32 -> 73.769958 | K32: =F32+G32+H32 -> 22.455306 | L32: =L31+K32 -> 67.155962
A33: 5 | B33: =IF(A33>=Ramp,ST_Target,ST_Start+(ST_Target-ST_Start)*(A33-1)/MAX(1,Ramp-1)) -> 0.2 | C33: =Routed_Day*365/12 -> 12025446 | D33: =C33*B33 -> 2405089.3 | E33: =C33*(B33*Save_Sold_Base+(1-B33)*Save_Unsold)/10^7 -> 28.527939 | F33: =C33*(B33*Save_Sold_High+(1-B33)*Save_Unsold)/10^7 -> 26.12285 | G33: =-Running_M/10^7 -> -0.06 | H33: =IF(A33=1,-OneTime/10^7,0) -> 0 | I33: =E33+G33+H33 -> 28.467939 | J33: =J32+I33 -> 102.2379 | K33: =F33+G33+H33 -> 26.06285 | L33: =L32+K33 -> 93.218812
A34: 6 | B34: =IF(A34>=Ramp,ST_Target,ST_Start+(ST_Target-ST_Start)*(A34-1)/MAX(1,Ramp-1)) -> 0.225 | C34: =Routed_Day*365/12 -> 12025446 | D34: =C34*B34 -> 2705725.4 | E34: =C34*(B34*Save_Sold_Base+(1-B34)*Save_Unsold)/10^7 -> 32.436119 | F34: =C34*(B34*Save_Sold_High+(1-B34)*Save_Unsold)/10^7 -> 29.730394 | G34: =-Running_M/10^7 -> -0.06 | H34: =IF(A34=1,-OneTime/10^7,0) -> 0 | I34: =E34+G34+H34 -> 32.376119 | J34: =J33+I34 -> 134.61402 | K34: =F34+G34+H34 -> 29.670394 | L34: =L33+K34 -> 122.88921
A35: 7 | B35: =IF(A35>=Ramp,ST_Target,ST_Start+(ST_Target-ST_Start)*(A35-1)/MAX(1,Ramp-1)) -> 0.25 | C35: =Routed_Day*365/12 -> 12025446 | D35: =C35*B35 -> 3006361.6 | E35: =C35*(B35*Save_Sold_Base+(1-B35)*Save_Unsold)/10^7 -> 36.344299 | F35: =C35*(B35*Save_Sold_High+(1-B35)*Save_Unsold)/10^7 -> 33.337937 | G35: =-Running_M/10^7 -> -0.06 | H35: =IF(A35=1,-OneTime/10^7,0) -> 0 | I35: =E35+G35+H35 -> 36.284299 | J35: =J34+I35 -> 170.89831 | K35: =F35+G35+H35 -> 33.277937 | L35: =L34+K35 -> 156.16714
A36: 8 | B36: =IF(A36>=Ramp,ST_Target,ST_Start+(ST_Target-ST_Start)*(A36-1)/MAX(1,Ramp-1)) -> 0.275 | C36: =Routed_Day*365/12 -> 12025446 | D36: =C36*B36 -> 3306997.8 | E36: =C36*(B36*Save_Sold_Base+(1-B36)*Save_Unsold)/10^7 -> 40.252479 | F36: =C36*(B36*Save_Sold_High+(1-B36)*Save_Unsold)/10^7 -> 36.945481 | G36: =-Running_M/10^7 -> -0.06 | H36: =IF(A36=1,-OneTime/10^7,0) -> 0 | I36: =E36+G36+H36 -> 40.192479 | J36: =J35+I36 -> 211.09079 | K36: =F36+G36+H36 -> 36.885481 | L36: =L35+K36 -> 193.05262
A37: 9 | B37: =IF(A37>=Ramp,ST_Target,ST_Start+(ST_Target-ST_Start)*(A37-1)/MAX(1,Ramp-1)) -> 0.3 | C37: =Routed_Day*365/12 -> 12025446 | D37: =C37*B37 -> 3607633.9 | E37: =C37*(B37*Save_Sold_Base+(1-B37)*Save_Unsold)/10^7 -> 44.160659 | F37: =C37*(B37*Save_Sold_High+(1-B37)*Save_Unsold)/10^7 -> 40.553025 | G37: =-Running_M/10^7 -> -0.06 | H37: =IF(A37=1,-OneTime/10^7,0) -> 0 | I37: =E37+G37+H37 -> 44.100659 | J37: =J36+I37 -> 255.19145 | K37: =F37+G37+H37 -> 40.493025 | L37: =L36+K37 -> 233.54565
A38: 10 | B38: =IF(A38>=Ramp,ST_Target,ST_Start+(ST_Target-ST_Start)*(A38-1)/MAX(1,Ramp-1)) -> 0.325 | C38: =Routed_Day*365/12 -> 12025446 | D38: =C38*B38 -> 3908270.1 | E38: =C38*(B38*Save_Sold_Base+(1-B38)*Save_Unsold)/10^7 -> 48.068839 | F38: =C38*(B38*Save_Sold_High+(1-B38)*Save_Unsold)/10^7 -> 44.160569 | G38: =-Running_M/10^7 -> -0.06 | H38: =IF(A38=1,-OneTime/10^7,0) -> 0 | I38: =E38+G38+H38 -> 48.008839 | J38: =J37+I38 -> 303.20029 | K38: =F38+G38+H38 -> 44.100569 | L38: =L37+K38 -> 277.64622
A39: 11 | B39: =IF(A39>=Ramp,ST_Target,ST_Start+(ST_Target-ST_Start)*(A39-1)/MAX(1,Ramp-1)) -> 0.35 | C39: =Routed_Day*365/12 -> 12025446 | D39: =C39*B39 -> 4208906.2 | E39: =C39*(B39*Save_Sold_Base+(1-B39)*Save_Unsold)/10^7 -> 51.977019 | F39: =C39*(B39*Save_Sold_High+(1-B39)*Save_Unsold)/10^7 -> 47.768112 | G39: =-Running_M/10^7 -> -0.06 | H39: =IF(A39=1,-OneTime/10^7,0) -> 0 | I39: =E39+G39+H39 -> 51.917019 | J39: =J38+I39 -> 355.11731 | K39: =F39+G39+H39 -> 47.708112 | L39: =L38+K39 -> 325.35433
A40: 12 | B40: =IF(A40>=Ramp,ST_Target,ST_Start+(ST_Target-ST_Start)*(A40-1)/MAX(1,Ramp-1)) -> 0.375 | C40: =Routed_Day*365/12 -> 12025446 | D40: =C40*B40 -> 4509542.4 | E40: =C40*(B40*Save_Sold_Base+(1-B40)*Save_Unsold)/10^7 -> 55.885198 | F40: =C40*(B40*Save_Sold_High+(1-B40)*Save_Unsold)/10^7 -> 51.375656 | G40: =-Running_M/10^7 -> -0.06 | H40: =IF(A40=1,-OneTime/10^7,0) -> 0 | I40: =E40+G40+H40 -> 55.825198 | J40: =J39+I40 -> 410.94251 | K40: =F40+G40+H40 -> 51.315656 | L40: =L39+K40 -> 376.66999
A41: 13 | B41: =IF(A41>=Ramp,ST_Target,ST_Start+(ST_Target-ST_Start)*(A41-1)/MAX(1,Ramp-1)) -> 0.375 | C41: =Routed_Day*365/12 -> 12025446 | D41: =C41*B41 -> 4509542.4 | E41: =C41*(B41*Save_Sold_Base+(1-B41)*Save_Unsold)/10^7 -> 55.885198 | F41: =C41*(B41*Save_Sold_High+(1-B41)*Save_Unsold)/10^7 -> 51.375656 | G41: =-Running_M/10^7 -> -0.06 | H41: =IF(A41=1,-OneTime/10^7,0) -> 0 | I41: =E41+G41+H41 -> 55.825198 | J41: =J40+I41 -> 466.76771 | K41: =F41+G41+H41 -> 51.315656 | L41: =L40+K41 -> 427.98564
... A64: 36 | B64: =IF(A64>=Ramp,ST_Target,ST_Start+(ST_Target-ST_Start)*(A64-1)/MAX(1,Ramp-1)) -> 0.375 | C64: =Routed_Day*365/12 -> 12025446 | D64: =C64*B64 -> 4509542.4 | E64: =C64*(B64*Save_Sold_Base+(1-B64)*Save_Unsold)/10^7 -> 55.885198 | F64: =C64*(B64*Save_Sold_High+(1-B64)*Save_Unsold)/10^7 -> 51.375656 | G64: =-Running_M/10^7 -> -0.06 | H64: =IF(A64=1,-OneTime/10^7,0) -> 0 | I64: =E64+G64+H64 -> 55.825198 | J64: =J63+I64 -> 1750.7473 | K64: =F64+G64+H64 -> 51.315656 | L64: =L63+K64 -> 1608.2457

Sheet Scenarios
A1: Scenarios - what if the assumptions are wrong?
A2: A. Saving per parcel routed into Hypersale (sold and unsold averaged)
A3: Sell-through | B3: ₹35 base | C3: ₹45 high
A4: 0 | B4: =A4*Save_Sold_Base+(1-A4)*Save_Unsold -> -2.2764228 | C4: =A4*Save_Sold_High+(1-A4)*Save_Unsold -> -2.2764228
A5: 0.1 | B5: =A5*Save_Sold_Base+(1-A5)*Save_Unsold -> 10.723277 | C5: =A5*Save_Sold_High+(1-A5)*Save_Unsold -> 9.7232772
A6: 0.2 | B6: =A6*Save_Sold_Base+(1-A6)*Save_Unsold -> 23.722977 | C6: =A6*Save_Sold_High+(1-A6)*Save_Unsold -> 21.722977
A7: 0.3 | B7: =A7*Save_Sold_Base+(1-A7)*Save_Unsold -> 36.722677 | C7: =A7*Save_Sold_High+(1-A7)*Save_Unsold -> 33.722677
A8: 0.375 | B8: =A8*Save_Sold_Base+(1-A8)*Save_Unsold -> 46.472452 | C8: =A8*Save_Sold_High+(1-A8)*Save_Unsold -> 42.722452
A9: 0.5 | B9: =A9*Save_Sold_Base+(1-A9)*Save_Unsold -> 62.722077 | C9: =A9*Save_Sold_High+(1-A9)*Save_Unsold -> 57.722077
A10: 0.75 | B10: =A10*Save_Sold_Base+(1-A10)*Save_Unsold -> 95.221327 | C10: =A10*Save_Sold_High+(1-A10)*Save_Unsold -> 87.721327
A11: 1 | B11: =A11*Save_Sold_Base+(1-A11)*Save_Unsold -> 127.72058 | C11: =A11*Save_Sold_High+(1-A11)*Save_Unsold -> 117.72058
A13: B. Annual net profit, India-wide (steady state)
A14: Sell-through | B14: ₹35 base | C14: ₹45 high | D14: RTO parcels saved / year | E14: Share of RTO saved
A15: 0.1 | B15: =(Routed_Day*365*(A15*Save_Sold_Base+(1-A15)*Save_Unsold)-12*Running_M)/10^7 -> 154.02264 | C15: =(Routed_Day*365*(A15*Save_Sold_High+(1-A15)*Save_Unsold)-12*Running_M)/10^7 -> 139.5921 | D15: =Routed_Day*365*A15/10^5 -> 144.30536 | E15: =Routed_Day*A15/RTO_Day -> 0.055372149
A16: 0.25 | B16: =(Routed_Day*365*(A16*Save_Sold_Base+(1-A16)*Save_Unsold)-12*Running_M)/10^7 -> 435.41159 | C16: =(Routed_Day*365*(A16*Save_Sold_High+(1-A16)*Save_Unsold)-12*Running_M)/10^7 -> 399.33525 | D16: =Routed_Day*365*A16/10^5 -> 360.76339 | E16: =Routed_Day*A16/RTO_Day -> 0.13843037
A17: 0.375 | B17: =(Routed_Day*365*(A17*Save_Sold_Base+(1-A17)*Save_Unsold)-12*Running_M)/10^7 -> 669.90238 | C17: =(Routed_Day*365*(A17*Save_Sold_High+(1-A17)*Save_Unsold)-12*Running_M)/10^7 -> 615.78787 | D17: =Routed_Day*365*A17/10^5 -> 541.14509 | E17: =Routed_Day*A17/RTO_Day -> 0.20764556
A18: 0.5 | B18: =(Routed_Day*365*(A18*Save_Sold_Base+(1-A18)*Save_Unsold)-12*Running_M)/10^7 -> 904.39318 | C18: =(Routed_Day*365*(A18*Save_Sold_High+(1-A18)*Save_Unsold)-12*Running_M)/10^7 -> 832.2405 | D18: =Routed_Day*365*A18/10^5 -> 721.52679 | E18: =Routed_Day*A18/RTO_Day -> 0.27686074
A19: 0.75 | B19: =(Routed_Day*365*(A19*Save_Sold_Base+(1-A19)*Save_Unsold)-12*Running_M)/10^7 -> 1373.3748 | C19: =(Routed_Day*365*(A19*Save_Sold_High+(1-A19)*Save_Unsold)-12*Running_M)/10^7 -> 1265.1457 | D19: =Routed_Day*365*A19/10^5 -> 1082.2902 | E19: =Routed_Day*A19/RTO_Day -> 0.41529112
A21: C. Annual net profit if some buyers are at another hub (Tier B)
A22: Share of sales via Tier B | B22: ₹35 base | C22: ₹45 high | D22: Extra cost per sale (avg)
A23: 0 | B23: =(Routed_Day*365*(ST_Target*(Save_Sold_Base-(A23-TierB_Share)*(TierB_Extra+TierB_Transfer))+(1-ST_Target)*Save_Unsold)-12*Running_M)/10^7 -> 705.07681 | C23: =(Routed_Day*365*(ST_Target*(Save_Sold_High-(A23-TierB_Share)*(TierB_Extra+TierB_Transfer))+(1-ST_Target)*Save_Unsold)-12*Running_M)/10^7 -> 650.9623 | D23: =A23*(TierB_Extra+TierB_Transfer) -> 0
A24: 0.1 | B24: =(Routed_Day*365*(ST_Target*(Save_Sold_Base-(A24-TierB_Share)*(TierB_Extra+TierB_Transfer))+(1-ST_Target)*Save_Unsold)-12*Running_M)/10^7 -> 691.00704 | C24: =(Routed_Day*365*(ST_Target*(Save_Sold_High-(A24-TierB_Share)*(TierB_Extra+TierB_Transfer))+(1-ST_Target)*Save_Unsold)-12*Running_M)/10^7 -> 636.89253 | D24: =A24*(TierB_Extra+TierB_Transfer) -> 2.6
A25: 0.25 | B25: =(Routed_Day*365*(ST_Target*(Save_Sold_Base-(A25-TierB_Share)*(TierB_Extra+TierB_Transfer))+(1-ST_Target)*Save_Unsold)-12*Running_M)/10^7 -> 669.90238 | C25: =(Routed_Day*365*(ST_Target*(Save_Sold_High-(A25-TierB_Share)*(TierB_Extra+TierB_Transfer))+(1-ST_Target)*Save_Unsold)-12*Running_M)/10^7 -> 615.78787 | D25: =A25*(TierB_Extra+TierB_Transfer) -> 6.5
A26: 0.5 | B26: =(Routed_Day*365*(ST_Target*(Save_Sold_Base-(A26-TierB_Share)*(TierB_Extra+TierB_Transfer))+(1-ST_Target)*Save_Unsold)-12*Running_M)/10^7 -> 634.72795 | C26: =(Routed_Day*365*(ST_Target*(Save_Sold_High-(A26-TierB_Share)*(TierB_Extra+TierB_Transfer))+(1-ST_Target)*Save_Unsold)-12*Running_M)/10^7 -> 580.61344 | D26: =A26*(TierB_Extra+TierB_Transfer) -> 13
A27: 0.65 | B27: =(Routed_Day*365*(ST_Target*(Save_Sold_Base-(A27-TierB_Share)*(TierB_Extra+TierB_Transfer))+(1-ST_Target)*Save_Unsold)-12*Running_M)/10^7 -> 613.62329 | C27: =(Routed_Day*365*(ST_Target*(Save_Sold_High-(A27-TierB_Share)*(TierB_Extra+TierB_Transfer))+(1-ST_Target)*Save_Unsold)-12*Running_M)/10^7 -> 559.50878 | D27: =A27*(TierB_Extra+TierB_Transfer) -> 16.9

Sheet Benchmarks
A1: Benchmarks — who else resells failed deliveries locally
A2: Company | B2: What they do | C2: Key number | D2: Lesson for Hypersale | E2: Source
A3: Ozon (Russia) — closest match | B3: Since 10 Sep 2026, refused or uncollected orders stay at the pickup point and are re-listed, if the point has shelf space. Large items, perishables and jewellery excluded. Automatic for sellers. | C3: Pickup-point owners paid 0.20 RUB per litre per day for held stock | D3: Gate eligibility on shelf space; exclude categories; pay the hub for storage | E3: selsup.ru/blog/ozon-prodazha-tovarov-iz-pvz
A4: Zomato Food Rescue (India) | B4: A cancelled order in transit is offered to users within 3 km at a lower price. Prepaid only; the original customer can't rebuy it; 2 cancellations per user per month. | C4: ~4 lakh cancelled orders/month; 75% of eligible orders claimed (Mar 2025) | D4: Anti-gaming rules; prepaid only; let sellers opt out (mandatory rollout drew pushback) | E4: storyboard18.com; greenqueen.com.hk
A5: Wildberries (Russia) | B5: Customers pay a fee for refusing or not collecting an order. | C5: 100 RUB refusal / 200 RUB not collected (Mar 2025); ≤1% of orders | D5: Pairs with Hypersale: the refuser pays part of the wasted trip | E5: oborot.ru
A6: Amazon Grade & Resell (UK/US/EU) | B6: Returned items graded into 4 conditions and re-listed as used at the seller's chosen price. | C6: Live UK 2021, US end-2021, EU 2022 | D6: Add a condition check; full price only for sealed parcels | E6: aboutamazon.co.uk
A7: Amazon FBA Liquidations | B7: Returned or excess stock sold in bulk to resale partners instead of shipping back. | C7: No figures published | D7: Day-8 fallback for unsold items instead of the full reverse trip | E7: aboutamazon.co.uk
A8: Returnless refunds (Amazon, Walmart) | B8: When a return costs more than the item is worth, the item is never collected. | C8: Return processing ~$12–33 (vendor estimate) | D8: At ₹270 AOV a ₹120 RTO is 44% of value — set a price floor for Hypersale | E8: claimlane.com
A9: Jumia (Africa) | B9: Failed deliveries checked in the local warehouse; passing items re-listed, failing items disposed of locally. | C9: No figures published | D9: Local QC gate; local disposal for items that fail it | E9: vendor.jumia.com
A10: Too Good To Go (Europe/US) | B10: Nearby surplus shown on a map, reserved and paid in-app, collected at a set time. | C10: Food at half price or less | D10: UX model for a local, prepaid, time-boxed listing | E10: toogoodtogo.com
A11: Flipkart 2GUD (India) | B11: Marketplace for certified returned and refurbished goods with warranties. | C11: Priced at 50–80% of original | D11: Opened goods needed a discount — keep original price for sealed parcels only | E11: entrackr.com
