Workbook

Sheet Assumptions
A1: Assumptions
A2: Parameter | B2: Value | C2: Unit | D2: Link
A3: 1. Volume and base economics
A4: Valmo orders per day | B4: 4200000 | C4: orders/day | D4: Open source ↗
A5: Annual growth in Valmo orders (years 2-10) | B5: 0 | C5: % | D5: Open source ↗
A6: Average order value (AOV) | B6: 270 | C6: ₹/order | D6: Open source ↗
A7: COD share of orders | B7: 0.8 | C7: % | D7: Open source ↗
A8: RTO rate on COD orders (door delivery) | B8: 0.2 | C8: % | D8: Open source ↗
A9: RTO rate on prepaid orders (door delivery) | B9: 0.05 | C9: %
A10: Blended RTO rate at the door | B10: =Assumptions!$B$7*Assumptions!$B$8+(1-Assumptions!$B$7)*Assumptions!$B$9 -> 0.17 | C10: %
A11: Last-mile cost per door delivery | B11: 21 | C11: ₹/parcel | D11: Open source ↗
A12: Reverse logistics cost per RTO | B12: 120 | C12: ₹/RTO
A13: Days per year | B13: 365 | C13: days
A14: 2. Kirana pickup plan (team inputs, used as given)
A15: Valmo hub cost per parcel (part of the ₹21) | B15: 6 | C15: ₹/parcel
A16: Rider pay per parcel dropped at a kirana | B16: 6 | C16: ₹/parcel
A17: Kirana pay per parcel handed over | B17: 7 | C17: ₹/parcel | D17: Open source ↗
A18: Last-mile saving per collected parcel | B18: =Assumptions!$B$11-Assumptions!$B$15-Assumptions!$B$16-Assumptions!$B$17 -> 2 | C18: ₹/parcel
A19: Discount on a customer's 1st pickup order | B19: 0.05 | C19: % of AOV
A20: Give a discount on the 2nd pickup order too? | B20: Yes | C20: Yes / No
A21: Discount on a customer's 2nd pickup order | B21: 0.05 | C21: % of AOV
A22: Years the pickup discounts run | B22: 3 | C22: years (1-10)
A23: Festive surge to kirana (Oct and Nov) | B23: 0 | C23: ₹/parcel
A24: Hold period at the kirana before RTO | B24: 5 | C24: days | D24: Open source ↗
A25: Kirana refundable deposit (memo, not a cost) | B25: 5000 | C25: ₹/kirana
A26: Wrong-address share of all RTOs | B26: 0.15 | C26: %
A27: Share of wrong-address RTOs solved - month 1 | B27: 0.2 | C27: %
A28: Share of wrong-address RTOs solved - month 60 | B28: 0.5 | C28: %
A29: Months over which the share rises | B29: 60 | C29: months
A30: Share solved in years 6-10 | B30: =Assumptions!$B$28 -> 0.5 | C30: %
A31: 3. Re-basing benchmarks to Meesho's customers (Tier 3/4, COD-heavy, low AOV)
A32: Tier-3-and-below share of orders, general e-commerce | B32: 0.38 | C32: % | D32: Open source ↗
A33: Tier-3-and-below share of Meesho orders | B33: 0.65 | C33: % | D33: Open source ↗
A34: Small-town vs city messaging reach ratio | B34: 0.815 | C34: x | D34: Open source ↗
A35: Messaging re-basing factor for Meesho | B35: =((1-Assumptions!$B$33)+Assumptions!$B$33*Assumptions!$B$34)/((1-Assumptions!$B$32)+Assumptions!$B$32*Assumptions!$B$34) -> 0.94627299 | C35: x
A36: Indian shoppers who prefer delivery to a pickup point or locker | B36: 0.08 | C36: % | D36: Open source ↗
A37: Pickup adoption among Meesho orders offered pickup | B37: =Assumptions!$B$36 -> 0.08 | C37: % | D37: Open source ↗
A38: Share of pickup parcels collected (India benchmark) | B38: 0.8 | C38: % | D38: Open source ↗
A39: Share of pickup parcels collected (Meesho) | B39: =Assumptions!$B$38*Assumptions!$B$35 -> 0.75701839 | C39: %
A40: Orders per Meesho customer per year | B40: 10.3 | C40: orders/yr | D40: Open source ↗
...

Sheet Money Saved
A1: Total Money Saved
A2: Avenues | B2: Year-1 | C2: Year-2 | D2: Year-3 | E2: Year-4 | F2: Year-5 | G2: Year-6 | H2: Year-7 | I2: Year-8 | J2: Year-9 | K2: Year-10 | L2: 10-Year Total
A3: Door last-mile cost not paid (₹21 per collected parcel) | B3: ='Year 1 Monthly'!O16 -> 1.2753996e+08 | C3: =C10*Assumptions!$B$11 -> 6.8237941e+08 | D3: =D10*Assumptions!$B$11 -> 9.7482773e+08 | E3: =E10*Assumptions!$B$11 -> 1169793270 | F3: =F10*Assumptions!$B$11 -> 1267276043 | G3: =G10*Assumptions!$B$11 -> 1267276043 | H3: =H10*Assumptions!$B$11 -> 1267276043 | I3: =I10*Assumptions!$B$11 -> 1267276043 | J3: =J10*Assumptions!$B$11 -> 1267276043 | K3: =K10*Assumptions!$B$11 -> 1267276043 | L3: =SUM(B3:K3) -> 10558196619
A4: Wrong-address RTO cost avoided (₹120 each) | B4: ='Year 1 Monthly'!O18 -> 6001804.1 | C4: =C12*Assumptions!$B$12 -> 37289316 | D4: =D12*Assumptions!$B$12 -> 64719622 | E4: =E12*Assumptions!$B$12 -> 91402553 | F4: =F12*Assumptions!$B$12 -> 1.1390336e+08 | G4: =G12*Assumptions!$B$12 -> 121965480 | H4: =H12*Assumptions!$B$12 -> 121965480 | I4: =I12*Assumptions!$B$12 -> 121965480 | J4: =J12*Assumptions!$B$12 -> 121965480 | K4: =K12*Assumptions!$B$12 -> 121965480 | L4: =SUM(B4:K4) -> 9.2314405e+08
A5: Total Money Saved | B5: ='Year 1 Monthly'!O19 -> 1.3354176e+08 | C5: =C3+C4 -> 7.1966872e+08 | D5: =D3+D4 -> 1039547347 | E5: =E3+E4 -> 1261195823 | F5: =F3+F4 -> 1381179398 | G5: =G3+G4 -> 1389241523 | H5: =H3+H4 -> 1389241523 | I5: =I3+I4 -> 1389241523 | J5: =J3+J4 -> 1389241523 | K5: =K3+K4 -> 1389241523 | L5: =SUM(B5:K5) -> 11481340669
A7: Drivers
A8: Year | B8: Year-1 | C8: Year-2 | D8: Year-3 | E8: Year-4 | F8: Year-5 | G8: Year-6 | H8: Year-7 | I8: Year-8 | J8: Year-9 | K8: Year-10 | L8: 10-Year Total
A9: Coverage: share of Valmo orders with a kirana nearby (year end) | B9: ='Year 1 Monthly'!N4 -> 0.2 | C9: =Assumptions!$B$47 -> 0.35 | D9: =Assumptions!$B$48 -> 0.5 | E9: =Assumptions!$B$49 -> 0.6 | F9: =Assumptions!$B$50 -> 0.65 | G9: =Assumptions!$B$50 -> 0.65 | H9: =Assumptions!$B$50 -> 0.65 | I9: =Assumptions!$B$50 -> 0.65 | J9: =Assumptions!$B$50 -> 0.65 | K9: =Assumptions!$B$50 -> 0.65
A10: Parcels collected at kiranas in the year | B10: ='Year 1 Monthly'!O15 -> 6073331.5 | C10: =C13*Assumptions!$B$39*Assumptions!$B$13 -> 32494258 | D10: =D13*Assumptions!$B$39*Assumptions!$B$13 -> 46420368 | E10: =E13*Assumptions!$B$39*Assumptions!$B$13 -> 55704441 | F10: =F13*Assumptions!$B$39*Assumptions!$B$13 -> 60346478 | G10: =G13*Assumptions!$B$39*Assumptions!$B$13 -> 60346478 | H10: =H13*Assumptions!$B$39*Assumptions!$B$13 -> 60346478 | I10: =I13*Assumptions!$B$39*Assumptions!$B$13 -> 60346478 | J10: =J13*Assumptions!$B$39*Assumptions!$B$13 -> 60346478 | K10: =K13*Assumptions!$B$39*Assumptions!$B$13 -> 60346478 | L10: =SUM(B10:K10) -> 5.0277127e+08
A11: Share of wrong-address RTOs solved (year average) | B11: ='Year 1 Monthly'!O9 -> 0.2279661 | C11: =IF(2>5,Assumptions!$B$30,Assumptions!$B$27+(Assumptions!$B$28-Assumptions!$B$27)*MIN(1,(12*2-6.5-1)/(Assumptions!$B$29-1))) -> 0.28389831 | D11: =IF(3>5,Assumptions!$B$30,Assumptions!$B$27+(Assumptions!$B$28-Assumptions!$B$27)*MIN(1,(12*3-6.5-1)/(Assumptions!$B$29-1))) -> 0.34491525 | E11: =IF(4>5,Assumptions!$B$30,Assumptions!$B$27+(Assumptions!$B$28-Assumptions!$B$27)*MIN(1,(12*4-6.5-1)/(Assumptions!$B$29-1))) -> 0.4059322 | F11: =IF(5>5,Assumptions!$B$30,Assumptions!$B$27+(Assumptions!$B$28-Assumptions!$B$27)*MIN(1,(12*5-6.5-1)/(Assumptions!$B$29-1))) -> 0.46694915 | G11: =IF(6>5,Assumptions!$B$30,Assumptions!$B$27+(Assumptions!$B$28-Assumptions!$B$27)*MIN(1,(12*6-6.5-1)/(Assumptions!$B$29-1))) -> 0.5 | H11: =IF(7>5,Assumptions!$B$30,Assumptions!$B$27+(Assumptions!$B$28-Assumptions!$B$27)*MIN(1,(12*7-6.5-1)/(Assumptions!$B$29-1))) -> 0.5 | I11: =IF(8>5,Assumptions!$B$30,Assumptions!$B$27+(Assumptions!$B$28-Assumptions!$B$27)*MIN(1,(12*8-6.5-1)/(Assumptions!$B$29-1))) -> 0.5 | J11: =IF(9>5,Assumptions!$B$30,Assumptions!$B$27+(Assumptions!$B$28-Assumptions!$B$27)*MIN(1,(12*9-6.5-1)/(Assumptions!$B$29-1))) -> 0.5 | K11: =IF(10>5,Assumptions!$B$30,Assumptions!$B$27+(Assumptions!$B$28-Assumptions!$B$27)*MIN(1,(12*10-6.5-1)/(Assumptions!$B$29-1))) -> 0.5
A12: Wrong-address RTOs avoided (orders) | B12: ='Year 1 Monthly'!O17 -> 50015.034 | C12: =C13*Assumptions!$B$13*Assumptions!$B$71*C11 -> 310744.3 | D12: =D13*Assumptions!$B$13*Assumptions!$B$71*D11 -> 539330.19 | E12: =E13*Assumptions!$B$13*Assumptions!$B$71*E11 -> 761687.94 | F12: =F13*Assumptions!$B$13*Assumptions!$B$71*F11 -> 949194.63 | G12: =G13*Assumptions!$B$13*Assumptions!$B$71*G11 -> 1016379 | H12: =H13*Assumptions!$B$13*Assumptions!$B$71*H11 -> 1016379 | I12: =I13*Assumptions!$B$13*Assumptions!$B$71*I11 -> 1016379 | J12: =J13*Assumptions!$B$13*Assumptions!$B$71*J11 -> 1016379 | K12: =K13*Assumptions!$B$13*Assumptions!$B$71*K11 -> 1016379 | L12: =SUM(B12:K12) -> 7692867.1
A13: Parcels dropped at kiranas per day (year average) | B13: ='Year 1 Monthly'!O5 -> 21980 | C13: =Assumptions!$B$4*(1+Assumptions!$B$5)^(2-1)*C9*Assumptions!$B$37 -> 117600 | D13: =Assumptions!$B$4*(1+Assumptions!$B$5)^(3-1)*D9*Assumptions!$B$37 -> 168000 | E13: =Assumptions!$B$4*(1+Assumptions!$B$5)^(4-1)*E9*Assumptions!$B$37 -> 201600 | F13: =Assumptions!$B$4*(1+Assumptions!$B$5)^(5-1)*F9*Assumptions!$B$37 -> 218400 | G13: =Assumptions!$B$4*(1+Assumptions!$B$5)^(6-1)*G9*Assumptions!$B$37 -> 218400 | H13: =Assumptions!$B$4*(1+Assumptions!$B$5)^(7-1)*H9*Assumptions!$B$37 -> 218400 | I13: =Assumptions!$B$4*(1+Assumptions!$B$5)^(8-1)*I9*Assumptions!$B$37 -> 218400 | J13: =Assumptions!$B$4*(1+Assumptions!$B$5)^(9-1)*J9*Assumptions!$B$37 -> 218400 | K13: =Assumptions!$B$4*(1+Assumptions!$B$5)^(10-1)*K9*Assumptions!$B$37 -> 218400

Sheet Costs
A1: Total Costs
A2: Components | B2: Year-1 | C2: Year-2 | D2: Year-3 | E2: Year-4 | F2: Year-5 | G2: Year-6 | H2: Year-7 | I2: Year-8 | J2: Year-9 | K2: Year-10 | L2: 10-Year Total
A3: Valmo hub: ₹7 per collected parcel | B3: ='Year 1 Monthly'!O23 -> 36439989 | C3: ='Money Saved'!C10*Assumptions!$B$15 -> 194965545 | D3: ='Money Saved'!D10*Assumptions!$B$15 -> 2.7852221e+08 | E3: ='Money Saved'!E10*Assumptions!$B$15 -> 3.3422665e+08 | F3: ='Money Saved'!F10*Assumptions!$B$15 -> 3.6207887e+08 | G3: ='Money Saved'!G10*Assumptions!$B$15 -> 3.6207887e+08 | H3: ='Money Saved'!H10*Assumptions!$B$15 -> 3.6207887e+08 | I3: ='Money Saved'!I10*Assumptions!$B$15 -> 3.6207887e+08 | J3: ='Money Saved'!J10*Assumptions!$B$15 -> 3.6207887e+08 | K3: ='Money Saved'!K10*Assumptions!$B$15 -> 3.6207887e+08 | L3: =SUM(B3:K3) -> 3016627605
A4: Rider pay: ₹6 per parcel dropped | B4: ='Year 1 Monthly'!O22 -> 48136200 | C4: ='Money Saved'!C13*Assumptions!$B$13*Assumptions!$B$16 -> 257544000 | D4: ='Money Saved'!D13*Assumptions!$B$13*Assumptions!$B$16 -> 367920000 | E4: ='Money Saved'!E13*Assumptions!$B$13*Assumptions!$B$16 -> 441504000 | F4: ='Money Saved'!F13*Assumptions!$B$13*Assumptions!$B$16 -> 478296000 | G4: ='Money Saved'!G13*Assumptions!$B$13*Assumptions!$B$16 -> 478296000 | H4: ='Money Saved'!H13*Assumptions!$B$13*Assumptions!$B$16 -> 478296000 | I4: ='Money Saved'!I13*Assumptions!$B$13*Assumptions!$B$16 -> 478296000 | J4: ='Money Saved'!J13*Assumptions!$B$13*Assumptions!$B$16 -> 478296000 | K4: ='Money Saved'!K13*Assumptions!$B$13*Assumptions!$B$16 -> 478296000 | L4: =SUM(B4:K4) -> 3984880200
A5: Kirana pay: ₹7 per parcel handed over | B5: ='Year 1 Monthly'!O24 -> 42513320 | C5: ='Money Saved'!C10*Assumptions!$B$17 -> 2.274598e+08 | D5: ='Money Saved'!D10*Assumptions!$B$17 -> 324942575 | E5: ='Money Saved'!E10*Assumptions!$B$17 -> 389931090 | F5: ='Money Saved'!F10*Assumptions!$B$17 -> 4.2242535e+08 | G5: ='Money Saved'!G10*Assumptions!$B$17 -> 4.2242535e+08 | H5: ='Money Saved'!H10*Assumptions!$B$17 -> 4.2242535e+08 | I5: ='Money Saved'!I10*Assumptions!$B$17 -> 4.2242535e+08 | J5: ='Money Saved'!J10*Assumptions!$B$17 -> 4.2242535e+08 | K5: ='Money Saved'!K10*Assumptions!$B$17 -> 4.2242535e+08 | L5: =SUM(B5:K5) -> 3519398873
A6: Discount on 1st pickup order | B6: ='Year 1 Monthly'!O25 -> 27303577 | C6: =IF(2<=Assumptions!$B$22,C22*Assumptions!$B$39*Assumptions!$B$19*Assumptions!$B$6,0) -> 27987426 | D6: =IF(3<=Assumptions!$B$22,D22*Assumptions!$B$39*Assumptions!$B$19*Assumptions!$B$6,0) -> 35288493 | E6: =IF(4<=Assumptions!$B$22,E22*Assumptions!$B$39*Assumptions!$B$19*Assumptions!$B$6,0) -> 0 | F6: =IF(5<=Assumptions!$B$22,F22*Assumptions!$B$39*Assumptions!$B$19*Assumptions!$B$6,0) -> 0 | G6: =IF(6<=Assumptions!$B$22,G22*Assumptions!$B$39*Assumptions!$B$19*Assumptions!$B$6,0) -> 0 | H6: =IF(7<=Assumptions!$B$22,H22*Assumptions!$B$39*Assumptions!$B$19*Assumptions!$B$6,0) -> 0 | I6: =IF(8<=Assumptions!$B$22,I22*Assumptions!$B$39*Assumptions!$B$19*Assumptions!$B$6,0) -> 0 | J6: =IF(9<=Assumptions!$B$22,J22*Assumptions!$B$39*Assumptions!$B$19*Assumptions!$B$6,0) -> 0 | K6: =IF(10<=Assumptions!$B$22,K22*Assumptions!$B$39*Assumptions!$B$19*Assumptions!$B$6,0) -> 0 | L6: =SUM(B6:K6) -> 90579496
A7: Discount on 2nd pickup order | B7: ='Year 1 Monthly'!O26 -> 21654852 | C7: =IF(2<=Assumptions!$B$22,C23*Assumptions!$B$39*Assumptions!$B$21*Assumptions!$B$6,0) -> 26821037 | D7: =IF(3<=Assumptions!$B$22,D23*Assumptions!$B$39*Assumptions!$B$21*Assumptions!$B$6,0) -> 33817829 | E7: =IF(4<=Assumptions!$B$22,E23*Assumptions!$B$39*Assumptions!$B$21*Assumptions!$B$6,0) -> 0 | F7: =IF(5<=Assumptions!$B$22,F23*Assumptions!$B$39*Assumptions!$B$21*Assumptions!$B$6,0) -> 0 | G7: =IF(6<=Assumptions!$B$22,G23*Assumptions!$B$39*Assumptions!$B$21*Assumptions!$B$6,0) -> 0 | H7: =IF(7<=Assumptions!$B$22,H23*Assumptions!$B$39*Assumptions!$B$21*Assumptions!$B$6,0) -> 0 | I7: =IF(8<=Assumptions!$B$22,I23*Assumptions!$B$39*Assumptions!$B$21*Assumptions!$B$6,0) -> 0 | J7: =IF(9<=Assumptions!$B$22,J23*Assumptions!$B$39*Assumptions!$B$21*Assumptions!$B$6,0) -> 0 | K7: =IF(10<=Assumptions!$B$22,K23*Assumptions!$B$39*Assumptions!$B$21*Assumptions!$B$6,0) -> 0 | L7: =SUM(B7:K7) -> 82293717
A8: Festive surge to kiranas (Oct-Nov) | B8: ='Year 1 Monthly'!O27 -> 0 | C8: ='Money Saved'!C10*2/12*Assumptions!$B$23 -> 0 | D8: ='Money Saved'!D10*2/12*Assumptions!$B$23 -> 0 | E8: ='Money Saved'!E10*2/12*Assumptions!$B$23 -> 0 | F8: ='Money Saved'!F10*2/12*Assumptions!$B$23 -> 0 | G8: ='Money Saved'!G10*2/12*Assumptions!$B$23 -> 0 | H8: ='Money Saved'!H10*2/12*Assumptions!$B$23 -> 0 | I8: ='Money Saved'!I10*2/12*Assumptions!$B$23 -> 0 | J8: ='Money Saved'!J10*2/12*Assumptions!$B$23 -> 0 | K8: ='Money Saved'!K10*2/12*Assumptions!$B$23 -> 0 | L8: =SUM(B8:K8) -> 0
A9: Messaging (WhatsApp + OTP SMS) | B9: ='Year 1 Monthly'!O28+'Year 1 Monthly'!O29 -> 3122942.8 | C9: ='Money Saved'!C13*Assumptions!$B$13*Assumptions!$B$70+'Money Saved'!C10*Assumptions!$B$55 -> 16708738 | D9: ='Money Saved'!D13*Assumptions!$B$13*Assumptions!$B$70+'Money Saved'!D10*Assumptions!$B$55 -> 23869626 | E9: ='Money Saved'!E13*Assumptions!$B$13*Assumptions!$B$70+'Money Saved'!E10*Assumptions!$B$55 -> 28643551 | F9: ='Money Saved'!F13*Assumptions!$B$13*Assumptions!$B$70+'Money Saved'!F10*Assumptions!$B$55 -> 31030514 | G9: ='Money Saved'!G13*Assumptions!$B$13*Assumptions!$B$70+'Money Saved'!G10*Assumptions!$B$55 -> 31030514 | H9: ='Money Saved'!H13*Assumptions!$B$13*Assumptions!$B$70+'Money Saved'!H10*Assumptions!$B$55 -> 31030514 | I9: ='Money Saved'!I13*Assumptions!$B$13*Assumptions!$B$70+'Money Saved'!I10*Assumptions!$B$55 -> 31030514 | J9: ='Money Saved'!J13*Assumptions!$B$13*Assumptions!$B$70+'Money Saved'!J10*Assumptions!$B$55 -> 31030514 | K9: ='Money Saved'!K13*Assumptions!$B$13*Assumptions!$B$70+'Money Saved'!K10*Assumptions!$B$55 -> 31030514 | L9: =SUM(B9:K9) -> 2.5852794e+08
A10: Customer support + UPI cost + photo storage | B10: ='Year 1 Monthly'!O30+'Year 1 Monthly'!O31+'Year 1 Monthly'!O32 -> 3625310.1 | C10: ='Money Saved'!C13*Assumptions!$B$13*Assumptions!$B$57*Assumptions!$B$58+'Money Saved'!C10*Assumptions!$B$56*Assumptions!$B$6+'Money Saved'!C10/Assumptions!$B$13*Assumptions!$B$60*Assumptions!$B$59/1000000*Assumptions!$B$61*12 -> 19396564 | D10: ='Money Saved'!D13*Assumptions!$B$13*Assumptions!$B$57*Assumptions!$B$58+'Money Saved'!D10*Assumptions!$B$56*Assumptions!$B$6+'Money Saved'!D10/Assumptions!$B$13*Assumptions!$B$60*Assumptions!$B$59/1000000*Assumptions!$B$61*12 -> 27709377 | E10: ='Money Saved'!E13*Assumptions!$B$13*Assumptions!$B$57*Assumptions!$B$58+'Money Saved'!E10*Assumptions!$B$56*Assumptions!$B$6+'Money Saved'!E10/Assumptions!$B$13*Assumptions!$B$60*Assumptions!$B$59/1000000*Assumptions!$B$61*12 -> 33251252 | F10: ='Money Saved'!F13*Assumptions!$B$13*Assumptions!$B$57*Assumptions!$B$58+'Money Saved'!F10*Assumptions!$B$56*Assumptions!$B$6+'Money Saved'!F10/Assumptions!$B$13*Assumptions!$B$60*Assumptions!$B$59/1000000*Assumptions!$B$61*12 -> 36022190 | G10: ='Money Saved'!G13*Assumptions!$B$13*Assumptions!$B$57*Assumptions!$B$58+'Money Saved'!G10*Assumptions!$B$56*Assumptions!$B$6+'Money Saved'!G10/Assumptions!$B$13*Assumptions!$B$60*Assumptions!$B$59/1000000*Assumptions!$B$61*12 -> 36022190 | H10: ='Money Saved'!H13*Assumptions!$B$13*Assumptions!$B$57*Assumptions!$B$58+'Money Saved'!H10*Assumptions!$B$56*Assumptions!$B$6+'Money Saved'!H10/Assumptions!$B$13*Assumptions!$B$60*Assumptions!$B$59/1000000*Assumptions!$B$61*12 -> 36022190 | I10: ='Money Saved'!I13*Assumptions!$B$13*Assumptions!$B$57*Assumptions!$B$58+'Money Saved'!I10*Assumptions!$B$56*Assumptions!$B$6+'Money Saved'!I10/Assumptions!$B$13*Assumptions!$B$60*Assumptions!$B$59/1000000*Assumptions!$B$61*12 -> 36022190 | J10: ='Money Saved'!J13*Assumptions!$B$13*Assumptions!$B$57*Assumptions!$B$58+'Money Saved'!J10*Assumptions!$B$56*Assumptions!$B$6+'Money Saved'!J10/Assumptions!$B$13*Assumptions!$B$60*Assumptions!$B$59/1000000*Assumptions!$B$61*12 -> 36022190 | K10: ='Money Saved'!K13*Assumptions!$B$13*Assumptions!$B$57*Assumptions!$B$58+'Money Saved'!K10*Assumptions!$B$56*Assumptions!$B$6+'Money Saved'!K10/Assumptions!$B$13*Assumptions!$B$60*Assumptions!$B$59/1000000*Assumptions!$B$61*12 -> 36022190 | L10: =SUM(B10:K10) -> 3.0011564e+08
A11: Kirana onboarding | B11: ='Year 1 Monthly'!O33 -> 4480000 | C11: =C19*Assumptions!$B$68 -> 3360000 | D11: =D19*Assumptions!$B$68 -> 3360000 | E11: =E19*Assumptions!$B$68 -> 2240000 | F11: =F19*Assumptions!$B$68 -> 1120000 | G11: =G19*Assumptions!$B$68 -> 0 | H11: =H19*Assumptions!$B$68 -> 0 | I11: =I19*Assumptions!$B$68 -> 0 | J11: =J19*Assumptions!$B$68 -> 0 | K11: =K19*Assumptions!$B$68 -> 0 | L11: =SUM(B11:K11) -> 14560000
A12: Contingency (10% of discount to onboarding) | B12: ='Year 1 Monthly'!O34 -> 6018668.2 | C12: =SUM(C6:C11)*Assumptions!$B$62 -> 9427376.4 | D12: =SUM(D6:D11)*Assumptions!$B$62 -> 12404532 | E12: =SUM(E6:E11)*Assumptions!$B$62 -> 6413480.4 | F12: =SUM(F6:F11)*Assumptions!$B$62 -> 6817270.4 | G12: =SUM(G6:G11)*Assumptions!$B$62 -> 6705270.4 | H12: =SUM(H6:H11)*Assumptions!$B$62 -> 6705270.4 | I12: =SUM(I6:I11)*Assumptions!$B$62 -> 6705270.4 | J12: =SUM(J6:J11)*Assumptions!$B$62 -> 6705270.4 | K12: =SUM(K6:K11)*Assumptions!$B$62 -> 6705270.4 | L12: =SUM(B12:K12) -> 74607680
A13: One-time investment (tech, training, legal at M0) | B13: ='Year 1 Monthly'!O35+'Year 1 Monthly'!O36+'Year 1 Monthly'!O37 -> 1750000 | C13: =0 -> 0 | D13: =0 -> 0 | E13: =0 -> 0 | F13: =0 -> 0 | G13: =0 -> 0 | H13: =0 -> 0 | I13: =0 -> 0 | J13: =0 -> 0 | K13: =0 -> 0 | L13: =SUM(B13:K13) -> 1750000
A14: Total Costs | B14: =SUM(B3:B13) -> 1.9504486e+08 | C14: =SUM(C3:C13) -> 7.8367049e+08 | D14: =SUM(D3:D13) -> 1107834640 | E14: =SUM(E3:E13) -> 1236210023 | F14: =SUM(F3:F13) -> 1337790191 | G14: =SUM(G3:G13) -> 1336558191 | H14: =SUM(H3:H13) -> 1336558191 | I14: =SUM(I3:I13) -> 1336558191 | ... K14: =SUM(K3:K13) -> 1336558191 | L14: =SUM(B14:K14) -> 11343341157
A16: Kiranas and customers (drivers of the cost lines)
A17: Year | B17: Year-1 | C17: Year-2 | D17: Year-3 | E17: Year-4 | F17: Year-5 | G17: Year-6 | H17: Year-7 | I17: Year-8 | J17: Year-9 | K17: Year-10 | L17: 10-Year Total
A18: Kiranas live (year end) | B18: ='Year 1 Monthly'!N7 -> 2240 | C18: =ROUNDUP('Money Saved'!C13/Assumptions!$B$42,0) -> 3920 | D18: =ROUNDUP('Money Saved'!D13/Assumptions!$B$42,0) -> 5600 | E18: =ROUNDUP('Money Saved'!E13/Assumptions!$B$42,0) -> 6720 | F18: =ROUNDUP('Money Saved'!F13/Assumptions!$B$42,0) -> 7280 | G18: =ROUNDUP('Money Saved'!G13/Assumptions!$B$42,0) -> 7280 | H18: =ROUNDUP('Money Saved'!H13/Assumptions!$B$42,0) -> 7280 | I18: =ROUNDUP('Money Saved'!I13/Assumptions!$B$42,0) -> 7280 | J18: =ROUNDUP('Money Saved'!J13/Assumptions!$B$42,0) -> 7280 | K18: =ROUNDUP('Money Saved'!K13/Assumptions!$B$42,0) -> 7280 | L18: =K18 -> 7280
A19: Kiranas added in the year | B19: ='Year 1 Monthly'!O8 -> 2240 | C19: =MAX(0,C18-B18) -> 1680 | D19: =MAX(0,D18-C18) -> 1680 | E19: =MAX(0,E18-D18) -> 1120 | F19: =MAX(0,F18-E18) -> 560 | G19: =MAX(0,G18-F18) -> 0 | H19: =MAX(0,H18-G18) -> 0 | I19: =MAX(0,I18-H18) -> 0 | J19: =MAX(0,J18-I18) -> 0 | K19: =MAX(0,K18-J18) -> 0 | L19: =SUM(B19:K19) -> 7280
A20: Deposits held (memo, refundable, not a cost) | B20: ='Year 1 Monthly'!N7*Assumptions!$B$25 -> 11200000 | C20: =C18*Assumptions!$B$25 -> 19600000 | D20: =D18*Assumptions!$B$25 -> 28000000 | E20: =E18*Assumptions!$B$25 -> 33600000 | F20: =F18*Assumptions!$B$25 -> 36400000 | G20: =G18*Assumptions!$B$25 -> 36400000 | H20: =H18*Assumptions!$B$25 -> 36400000 | I20: =I18*Assumptions!$B$25 -> 36400000 | J20: =J18*Assumptions!$B$25 -> 36400000 | K20: =K18*Assumptions!$B$25 -> 36400000 | L20: =K20 -> 36400000
A21: Active pickup customers (year end) | B21: ='Year 1 Monthly'!O10 -> 2381359.2 | C21: ='Money Saved'!C13*Assumptions!$B$13/Assumptions!$B$40 -> 4167378.6 | D21: ='Money Saved'!D13*Assumptions!$B$13/Assumptions!$B$40 -> 5953398.1 | E21: ='Money Saved'!E13*Assumptions!$B$13/Assumptions!$B$40 -> 7144077.7 | F21: ='Money Saved'!F13*Assumptions!$B$13/Assumptions!$B$40 -> 7739417.5 | G21: ='Money Saved'!G13*Assumptions!$B$13/Assumptions!$B$40 -> 7739417.5 | H21: ='Money Saved'!H13*Assumptions!$B$13/Assumptions!$B$40 -> 7739417.5 | I21: ='Money Saved'!I13*Assumptions!$B$13/Assumptions!$B$40 -> 7739417.5 | J21: ='Money Saved'!J13*Assumptions!$B$13/Assumptions!$B$40 -> 7739417.5 | K21: ='Money Saved'!K13*Assumptions!$B$13/Assumptions!$B$40 -> 7739417.5 | L21: =K21 -> 7739417.5
A22: New pickup customers (get the 1st-order discount while discounts run) | B22: ='Year 1 Monthly'!O11 -> 2671648.7 | C22: =MAX(0,C21-B21*(1-Assumptions!$B$41)) -> 2738563.1 | D22: =MAX(0,D21-C21*(1-Assumptions!$B$41)) -> 3452970.9 | E22: =MAX(0,E21-D21*(1-Assumptions!$B$41)) -> 3572038.8 | F22: =MAX(0,F21-E21*(1-Assumptions!$B$41)) -> 3452970.9 | G22: =MAX(0,G21-F21*(1-Assumptions!$B$41)) -> 3095767 | H22: =MAX(0,H21-G21*(1-Assumptions!$B$41)) -> 3095767 | I22: =MAX(0,I21-H21*(1-Assumptions!$B$41)) -> 3095767 | J22: =MAX(0,J21-I21*(1-Assumptions!$B$41)) -> 3095767 | K22: =MAX(0,K21-J21*(1-Assumptions!$B$41)) -> 3095767 | L22: =SUM(B22:K22) -> 31367027
A23: Customers getting the 2nd-order discount | B23: ='Year 1 Monthly'!O12 -> 2118922.2 | C23: =IF(Assumptions!$B$20="Yes",C22*(1-Assumptions!$B$73),0) -> 2624432.2 | D23: =IF(Assumptions!$B$20="Yes",D22*(1-Assumptions!$B$73),0) -> 3309066.7 | E23: =IF(Assumptions!$B$20="Yes",E22*(1-Assumptions!$B$73),0) -> 3423172.4 | F23: =IF(Assumptions!$B$20="Yes",F22*(1-Assumptions!$B$73),0) -> 3309066.7 | G23: =IF(Assumptions!$B$20="Yes",G22*(1-Assumptions!$B$73),0) -> 2966749.4 | H23: =IF(Assumptions!$B$20="Yes",H22*(1-Assumptions!$B$73),0) -> 2966749.4 | I23: =IF(Assumptions!$B$20="Yes",I22*(1-Assumptions!$B$73),0) -> 2966749.4 | J23: =IF(Assumptions!$B$20="Yes",J22*(1-Assumptions!$B$73),0) -> 2966749.4 | K23: =IF(Assumptions!$B$20="Yes",K22*(1-Assumptions!$B$73),0) -> 2966749.4 | L23: =SUM(B23:K23) -> 29618407

Sheet Payback
A1: ="Payback - "&TEXT(Assumptions!$B$19,"0%")&" off the 1st pickup order"&IF(Assumptions!$B$20="Yes",", "&TEXT(Assumptions!$B$21,"0%")&" off the 2nd","")&IF(Assumptions!$B$22<10,", discounts for "&Assumptions!$B$22&" year(s)","") -> Payback - 5% off the 1st pickup order, 5% off the 2nd, discounts for 3 year(s)
A2: Year | B2: Year-1 | C2: Year-2 | D2: Year-3 | E2: Year-4 | F2: Year-5 | G2: Year-6 | H2: Year-7 | I2: Year-8 | J2: Year-9 | K2: Year-10 | L2: 10-Year Total
A3: Total Money Saved | B3: ='Money Saved'!B5 -> 1.3354176e+08 | C3: ='Money Saved'!C5 -> 7.1966872e+08 | D3: ='Money Saved'!D5 -> 1039547347 | E3: ='Money Saved'!E5 -> 1261195823 | F3: ='Money Saved'!F5 -> 1381179398 | G3: ='Money Saved'!G5 -> 1389241523 | H3: ='Money Saved'!H5 -> 1389241523 | I3: ='Money Saved'!I5 -> 1389241523 | ... K3: ='Money Saved'!K5 -> 1389241523 | L3: =SUM(B3:K3) -> 11481340669
A4: Total Costs | B4: =Costs!B14 -> 1.9504486e+08 | C4: =Costs!C14 -> 7.8367049e+08 | D4: =Costs!D14 -> 1107834640 | E4: =Costs!E14 -> 1236210023 | F4: =Costs!F14 -> 1337790191 | G4: =Costs!G14 -> 1336558191 | H4: =Costs!H14 -> 1336558191 | I4: =Costs!I14 -> 1336558191 | ... K4: =Costs!K14 -> 1336558191 | L4: =SUM(B4:K4) -> 11343341157
A5: Net Money Saved | B5: =B3-B4 -> -61503094 | C5: =C3-C4 -> -64001765 | D5: =D3-D4 -> -68287292 | E5: =E3-E4 -> 24985800 | F5: =F3-F4 -> 43389206 | G5: =G3-G4 -> 52683331 | H5: =H3-H4 -> 52683331 | I5: =I3-I4 -> 52683331 | ... K5: =K3-K4 -> 52683331 | L5: =SUM(B5:K5) -> 1.3799951e+08
A6: Cumulative net money saved | B6: =B5 -> -61503094 | C6: =B6+C5 -> -1.2550486e+08 | D6: =C6+D5 -> -1.9379215e+08 | E6: =D6+E5 -> -1.6880635e+08 | F6: =E6+F5 -> -1.2541715e+08 | G6: =F6+G5 -> -72733814 | H6: =G6+H5 -> -20050482 | I6: =H6+I5 -> 32632849 | J6: =I6+J5 -> 85316180 | K6: =J6+K5 -> 1.3799951e+08 | L6: =K6 -> 1.3799951e+08
A7: Investment paid back? | B7: =IF(B6>=0,"Yes","No") -> No | C7: =IF(C6>=0,"Yes","No") -> No | D7: =IF(D6>=0,"Yes","No") -> No | E7: =IF(E6>=0,"Yes","No") -> No | F7: =IF(F6>=0,"Yes","No") -> No | G7: =IF(G6>=0,"Yes","No") -> No | H7: =IF(H6>=0,"Yes","No") -> No | I7: =IF(I6>=0,"Yes","No") -> Yes | ... K7: =IF(K6>=0,"Yes","No") -> Yes
A8: Money saved per ₹1 spent | B8: =B3/B4 -> 0.68467206 | C8: =C3/C4 -> 0.91833077 | D8: =D3/D4 -> 0.93835967 | E8: =E3/E4 -> 1.0202116 | F8: =F3/F4 -> 1.0324335 | G8: =G3/G4 -> 1.0394172 | H8: =H3/H4 -> 1.0394172 | I8: =I3/I4 -> 1.0394172 | ... K8: =K3/K4 -> 1.0394172
A9: Payback point (years from launch) | B9: =IF(COUNT('Year 1 Monthly'!B44:N44)>0,MIN('Year 1 Monthly'!B44:N44)/12,"") | C9: =IF(AND(B6<0,C6>=0),1+(-B6)/C5,"") | D9: =IF(AND(C6<0,D6>=0),2+(-C6)/D5,"") | E9: =IF(AND(D6<0,E6>=0),3+(-D6)/E5,"") | F9: =IF(AND(E6<0,F6>=0),4+(-E6)/F5,"") | G9: =IF(AND(F6<0,G6>=0),5+(-F6)/G5,"") | H9: =IF(AND(G6<0,H6>=0),6+(-G6)/H5,"") | I9: =IF(AND(H6<0,I6>=0),7+(-H6)/I5,"") -> 7.3805849 | J9: =IF(AND(I6<0,J6>=0),8+(-I6)/J5,"") | K9: =IF(AND(J6<0,K6>=0),9+(-J6)/K5,"")
A11: Payback Summary
A12: 2nd-order discount on? | B12: =Assumptions!$B$20 -> Yes
A13: Years the discounts run | B13: =Assumptions!$B$22 -> 3
A14: Upfront investment (M0) | B14: =Costs!B13 -> 1750000
A15: Payback period (years) | B15: =IF(COUNT(B9:K9)=0,"Not within 10 years",MIN(B9:K9)) -> 7.3805849
A16: Payback month | B16: =IF(ISNUMBER(B15),"M"&ROUNDUP(B15*12,0)&" ("&TEXT(EDATE(DATE(2026,12,1),ROUNDUP(B15*12,0)),"mmm yyyy")&")","-") -> M89 (May 2034)
A17: Peak cash outlay before payback | B17: =-MIN(0,MIN(B6:K6)) -> 1.9379215e+08
A18: Total discount paid in Year-1 | B18: =SUM(Costs!B6:B7) -> 48958429
A19: Total discount paid over 10 years | B19: =SUM(Costs!L6:L7) -> 172873213
A20: Year-1 net money saved | B20: =B5 -> -61503094
A21: 10-year net money saved | B21: =L5 -> 1.3799951e+08
A22: Money saved per ₹1 spent (10 years) | B22: =L3/L4 -> 1.0121657
A25: Discount Payback (orders to earn back the discount, Year-10 steady state)
A26: Saving per pickup order before discounts | B26: =(K5+(Costs!K6+Costs!K7)*(1+Assumptions!$B$62))/('Money Saved'!K13*Assumptions!$B$13) -> 0.66088779
A27: Discount given per customer (incl. contingency) | B27: =(Assumptions!$B$19+IF(Assumptions!$B$20="Yes",Assumptions!$B$21,0))*Assumptions!$B$6*(1+Assumptions!$B$62) -> 29.7
A28: Discount Payback (orders) | B28: =IF(B26<=0,"Never: saving per order is not positive",B27/B26) -> 44.93955
A29: Discount Payback (months for a typical customer) | B29: =IF(ISNUMBER(B28),B28/Assumptions!$B$40*12,"Never") -> 52.356757

Sheet Year 1 Monthly
A1: Year 1 Month by Month (M0 build, pilot from M1)
A2: Rollout
A3: Month | B3: M0 Setup | C3: M1 Jan 2027 | D3: M2 Feb 2027 | E3: M3 Mar 2027 | F3: M4 Apr 2027 | G3: M5 May 2027 | H3: M6 Jun 2027 | I3: M7 Jul 2027 | J3: M8 Aug 2027 | K3: M9 Sep 2027 | L3: M10 Oct 2027 | M3: M11 Nov 2027 | N3: M12 Dec 2027 | O3: Year-1 Total
A4: Coverage: share of Valmo orders with a kirana nearby | B4: =0 -> 0 | C4: =IF(1<=Assumptions!$B$44,Assumptions!$B$45,Assumptions!$B$45+(Assumptions!$B$46-Assumptions!$B$45)*(1-Assumptions!$B$44)/(12-Assumptions!$B$44)) -> 0.01 | D4: =IF(2<=Assumptions!$B$44,Assumptions!$B$45,Assumptions!$B$45+(Assumptions!$B$46-Assumptions!$B$45)*(2-Assumptions!$B$44)/(12-Assumptions!$B$44)) -> 0.01 | E4: =IF(3<=Assumptions!$B$44,Assumptions!$B$45,Assumptions!$B$45+(Assumptions!$B$46-Assumptions!$B$45)*(3-Assumptions!$B$44)/(12-Assumptions!$B$44)) -> 0.01 | F4: =IF(4<=Assumptions!$B$44,Assumptions!$B$45,Assumptions!$B$45+(Assumptions!$B$46-Assumptions!$B$45)*(4-Assumptions!$B$44)/(12-Assumptions!$B$44)) -> 0.01 | G4: =IF(5<=Assumptions!$B$44,Assumptions!$B$45,Assumptions!$B$45+(Assumptions!$B$46-Assumptions!$B$45)*(5-Assumptions!$B$44)/(12-Assumptions!$B$44)) -> 0.01 | H4: =IF(6<=Assumptions!$B$44,Assumptions!$B$45,Assumptions!$B$45+(Assumptions!$B$46-Assumptions!$B$45)*(6-Assumptions!$B$44)/(12-Assumptions!$B$44)) -> 0.01 | I4: =IF(7<=Assumptions!$B$44,Assumptions!$B$45,Assumptions!$B$45+(Assumptions!$B$46-Assumptions!$B$45)*(7-Assumptions!$B$44)/(12-Assumptions!$B$44)) -> 0.041666667 | J4: =IF(8<=Assumptions!$B$44,Assumptions!$B$45,Assumptions!$B$45+(Assumptions!$B$46-Assumptions!$B$45)*(8-Assumptions!$B$44)/(12-Assumptions!$B$44)) -> 0.073333333 | K4: =IF(9<=Assumptions!$B$44,Assumptions!$B$45,Assumptions!$B$45+(Assumptions!$B$46-Assumptions!$B$45)*(9-Assumptions!$B$44)/(12-Assumptions!$B$44)) -> 0.105 | L4: =IF(10<=Assumptions!$B$44,Assumptions!$B$45,Assumptions!$B$45+(Assumptions!$B$46-Assumptions!$B$45)*(10-Assumptions!$B$44)/(12-Assumptions!$B$44)) -> 0.13666667 | M4: =IF(11<=Assumptions!$B$44,Assumptions!$B$45,Assumptions!$B$45+(Assumptions!$B$46-Assumptions!$B$45)*(11-Assumptions!$B$44)/(12-Assumptions!$B$44)) -> 0.16833333 | N4: =IF(12<=Assumptions!$B$44,Assumptions!$B$45,Assumptions!$B$45+(Assumptions!$B$46-Assumptions!$B$45)*(12-Assumptions!$B$44)/(12-Assumptions!$B$44)) -> 0.2 | O4: =AVERAGE(C4:N4) -> 0.065416667
A5: Parcels dropped at kiranas per day | B5: =Assumptions!$B$4*B4*Assumptions!$B$37 -> 0 | C5: =Assumptions!$B$4*C4*Assumptions!$B$37 -> 3360 | D5: =Assumptions!$B$4*D4*Assumptions!$B$37 -> 3360 | E5: =Assumptions!$B$4*E4*Assumptions!$B$37 -> 3360 | F5: =Assumptions!$B$4*F4*Assumptions!$B$37 -> 3360 | G5: =Assumptions!$B$4*G4*Assumptions!$B$37 -> 3360 | H5: =Assumptions!$B$4*H4*Assumptions!$B$37 -> 3360 | I5: =Assumptions!$B$4*I4*Assumptions!$B$37 -> 14000 | ... N5: =Assumptions!$B$4*N4*Assumptions!$B$37 -> 67200 | O5: =AVERAGE(C5:N5) -> 21980
A6: Parcels collected per day | B6: =B5*Assumptions!$B$39 -> 0 | C6: =C5*Assumptions!$B$39 -> 2543.5818 | D6: =D5*Assumptions!$B$39 -> 2543.5818 | E6: =E5*Assumptions!$B$39 -> 2543.5818 | F6: =F5*Assumptions!$B$39 -> 2543.5818 | G6: =G5*Assumptions!$B$39 -> 2543.5818 | H6: =H5*Assumptions!$B$39 -> 2543.5818 | I6: =I5*Assumptions!$B$39 -> 10598.257 | ... N6: =N5*Assumptions!$B$39 -> 50871.636 | O6: =AVERAGE(C6:N6) -> 16639.264
A7: Kiranas live | B7: =ROUNDUP(B5/Assumptions!$B$42,0) -> 0 | C7: =ROUNDUP(C5/Assumptions!$B$42,0) -> 112 | D7: =ROUNDUP(D5/Assumptions!$B$42,0) -> 112 | E7: =ROUNDUP(E5/Assumptions!$B$42,0) -> 112 | F7: =ROUNDUP(F5/Assumptions!$B$42,0) -> 112 | G7: =ROUNDUP(G5/Assumptions!$B$42,0) -> 112 | H7: =ROUNDUP(H5/Assumptions!$B$42,0) -> 112 | I7: =ROUNDUP(I5/Assumptions!$B$42,0) -> 467 | ... N7: =ROUNDUP(N5/Assumptions!$B$42,0) -> 2240 | O7: =N7 -> 2240
A8: Kiranas added this month | B8: =B7 -> 0 | C8: =MAX(0,C7-B7) -> 112 | D8: =MAX(0,D7-C7) -> 0 | E8: =MAX(0,E7-D7) -> 0 | F8: =MAX(0,F7-E7) -> 0 | G8: =MAX(0,G7-F7) -> 0 | H8: =MAX(0,H7-G7) -> 0 | I8: =MAX(0,I7-H7) -> 355 | J8: =MAX(0,J7-I7) -> 355 | ... N8: =MAX(0,N7-M7) -> 354 | O8: =SUM(B8:N8) -> 2240
A9: Share of wrong-address RTOs solved | B9: =0 -> 0 | C9: =Assumptions!$B$27+(Assumptions!$B$28-Assumptions!$B$27)*MIN(1,(1-1)/(Assumptions!$B$29-1)) -> 0.2 | D9: =Assumptions!$B$27+(Assumptions!$B$28-Assumptions!$B$27)*MIN(1,(2-1)/(Assumptions!$B$29-1)) -> 0.20508475 | E9: =Assumptions!$B$27+(Assumptions!$B$28-Assumptions!$B$27)*MIN(1,(3-1)/(Assumptions!$B$29-1)) -> 0.21016949 | F9: =Assumptions!$B$27+(Assumptions!$B$28-Assumptions!$B$27)*MIN(1,(4-1)/(Assumptions!$B$29-1)) -> 0.21525424 | G9: =Assumptions!$B$27+(Assumptions!$B$28-Assumptions!$B$27)*MIN(1,(5-1)/(Assumptions!$B$29-1)) -> 0.22033898 | H9: =Assumptions!$B$27+(Assumptions!$B$28-Assumptions!$B$27)*MIN(1,(6-1)/(Assumptions!$B$29-1)) -> 0.22542373 | I9: =Assumptions!$B$27+(Assumptions!$B$28-Assumptions!$B$27)*MIN(1,(7-1)/(Assumptions!$B$29-1)) -> 0.23050847 | J9: =Assumptions!$B$27+(Assumptions!$B$28-Assumptions!$B$27)*MIN(1,(8-1)/(Assumptions!$B$29-1)) -> 0.23559322 | K9: =Assumptions!$B$27+(Assumptions!$B$28-Assumptions!$B$27)*MIN(1,(9-1)/(Assumptions!$B$29-1)) -> 0.24067797 | L9: =Assumptions!$B$27+(Assumptions!$B$28-Assumptions!$B$27)*MIN(1,(10-1)/(Assumptions!$B$29-1)) -> 0.24576271 | M9: =Assumptions!$B$27+(Assumptions!$B$28-Assumptions!$B$27)*MIN(1,(11-1)/(Assumptions!$B$29-1)) -> 0.25084746 | N9: =Assumptions!$B$27+(Assumptions!$B$28-Assumptions!$B$27)*MIN(1,(12-1)/(Assumptions!$B$29-1)) -> 0.2559322 | O9: =AVERAGE(C9:N9) -> 0.2279661
A10: Pickup customers (active) | B10: =B5*(Assumptions!$B$13/12)/Assumptions!$B$72 -> 0 | C10: =C5*(Assumptions!$B$13/12)/Assumptions!$B$72 -> 119067.96 | D10: =D5*(Assumptions!$B$13/12)/Assumptions!$B$72 -> 119067.96 | E10: =E5*(Assumptions!$B$13/12)/Assumptions!$B$72 -> 119067.96 | F10: =F5*(Assumptions!$B$13/12)/Assumptions!$B$72 -> 119067.96 | G10: =G5*(Assumptions!$B$13/12)/Assumptions!$B$72 -> 119067.96 | H10: =H5*(Assumptions!$B$13/12)/Assumptions!$B$72 -> 119067.96 | I10: =I5*(Assumptions!$B$13/12)/Assumptions!$B$72 -> 496116.5 | ... N10: =N5*(Assumptions!$B$13/12)/Assumptions!$B$72 -> 2381359.2 | O10: =N10 -> 2381359.2
A11: New pickup customers (1st discounted order) | B11: =B10 -> 0 | C11: =MAX(0,C10-B10*(1-Assumptions!$B$73)) -> 119067.96 | D11: =MAX(0,D10-C10*(1-Assumptions!$B$73)) -> 4962.2134 | E11: =MAX(0,E10-D10*(1-Assumptions!$B$73)) -> 4962.2134 | F11: =MAX(0,F10-E10*(1-Assumptions!$B$73)) -> 4962.2134 | G11: =MAX(0,G10-F10*(1-Assumptions!$B$73)) -> 4962.2134 | H11: =MAX(0,H10-G10*(1-Assumptions!$B$73)) -> 4962.2134 | I11: =MAX(0,I10-H10*(1-Assumptions!$B$73)) -> 382010.76 | J11: =MAX(0,J10-I10*(1-Assumptions!$B$73)) -> 397724.43 | ... N11: =MAX(0,N10-M10*(1-Assumptions!$B$73)) -> 460579.14 | O11: =SUM(B11:N11) -> 2671648.7
A12: Customers on their 2nd discounted order (last month's new customers still active) | B12: =0 -> 0 | C12: =IF(Assumptions!$B$20="Yes",B11*(1-Assumptions!$B$73),0) -> 0 | D12: =IF(Assumptions!$B$20="Yes",C11*(1-Assumptions!$B$73),0) -> 114105.75 | E12: =IF(Assumptions!$B$20="Yes",D11*(1-Assumptions!$B$73),0) -> 4755.4108 | F12: =IF(Assumptions!$B$20="Yes",E11*(1-Assumptions!$B$73),0) -> 4755.4108 | G12: =IF(Assumptions!$B$20="Yes",F11*(1-Assumptions!$B$73),0) -> 4755.4108 | H12: =IF(Assumptions!$B$20="Yes",G11*(1-Assumptions!$B$73),0) -> 4755.4108 | I12: =IF(Assumptions!$B$20="Yes",H11*(1-Assumptions!$B$73),0) -> 4755.4108 | J12: =IF(Assumptions!$B$20="Yes",I11*(1-Assumptions!$B$73),0) -> 366090.28 | ... N12: =IF(Assumptions!$B$20="Yes",M11*(1-Assumptions!$B$73),0) -> 426325.48 | O12: =SUM(B12:N12) -> 2118922.2
A13: Money Saved
A14: Month | B14: M0 Setup | C14: M1 Jan 2027 | D14: M2 Feb 2027 | E14: M3 Mar 2027 | F14: M4 Apr 2027 | G14: M5 May 2027 | H14: M6 Jun 2027 | I14: M7 Jul 2027 | J14: M8 Aug 2027 | K14: M9 Sep 2027 | L14: M10 Oct 2027 | M14: M11 Nov 2027 | N14: M12 Dec 2027 | O14: Year-1 Total
A15: Parcels collected in the month | B15: =B6*(Assumptions!$B$13/12) -> 0 | C15: =C6*(Assumptions!$B$13/12) -> 77367.28 | D15: =D6*(Assumptions!$B$13/12) -> 77367.28 | E15: =E6*(Assumptions!$B$13/12) -> 77367.28 | F15: =F6*(Assumptions!$B$13/12) -> 77367.28 | G15: =G6*(Assumptions!$B$13/12) -> 77367.28 | H15: =H6*(Assumptions!$B$13/12) -> 77367.28 | I15: =I6*(Assumptions!$B$13/12) -> 322363.67 | ... N15: =N6*(Assumptions!$B$13/12) -> 1547345.6 | O15: =SUM(B15:N15) -> 6073331.5
A16: Door last-mile cost not paid (₹21 per collected parcel) | B16: =B15*Assumptions!$B$11 -> 0 | C16: =C15*Assumptions!$B$11 -> 1624712.9 | D16: =D15*Assumptions!$B$11 -> 1624712.9 | E16: =E15*Assumptions!$B$11 -> 1624712.9 | F16: =F15*Assumptions!$B$11 -> 1624712.9 | G16: =G15*Assumptions!$B$11 -> 1624712.9 | H16: =H15*Assumptions!$B$11 -> 1624712.9 | I16: =I15*Assumptions!$B$11 -> 6769637 | ... N16: =N15*Assumptions!$B$11 -> 32494258 | O16: =SUM(B16:N16) -> 1.2753996e+08
A17: Wrong-address RTOs avoided (orders) | B17: =B5*(Assumptions!$B$13/12)*Assumptions!$B$71*B9 -> 0 | C17: =C5*(Assumptions!$B$13/12)*Assumptions!$B$71*C9 -> 521.22 | D17: =D5*(Assumptions!$B$13/12)*Assumptions!$B$71*D9 -> 534.47136 | E17: =E5*(Assumptions!$B$13/12)*Assumptions!$B$71*E9 -> 547.72271 | F17: =F5*(Assumptions!$B$13/12)*Assumptions!$B$71*F9 -> 560.97407 | G17: =G5*(Assumptions!$B$13/12)*Assumptions!$B$71*G9 -> 574.22542 | H17: =H5*(Assumptions!$B$13/12)*Assumptions!$B$71*H9 -> 587.47678 | I17: =I5*(Assumptions!$B$13/12)*Assumptions!$B$71*I9 -> 2503.0339 | ... N17: =N5*(Assumptions!$B$13/12)*Assumptions!$B$71*N9 -> 13339.698 | O17: =SUM(B17:N17) -> 50015.034
A18: Wrong-address RTO cost avoided (₹120 each) | B18: =B17*Assumptions!$B$12 -> 0 | C18: =C17*Assumptions!$B$12 -> 62546.4 | D18: =D17*Assumptions!$B$12 -> 64136.563 | E18: =E17*Assumptions!$B$12 -> 65726.725 | F18: =F17*Assumptions!$B$12 -> 67316.888 | G18: =G17*Assumptions!$B$12 -> 68907.051 | H18: =H17*Assumptions!$B$12 -> 70497.214 | I18: =I17*Assumptions!$B$12 -> 300364.07 | ... N18: =N17*Assumptions!$B$12 -> 1600763.8 | O18: =SUM(B18:N18) -> 6001804.1
A19: Total Money Saved | B19: =B16+B18 -> 0 | C19: =C16+C18 -> 1687259.3 | D19: =D16+D18 -> 1688849.4 | E19: =E16+E18 -> 1690439.6 | F19: =F16+F18 -> 1692029.8 | G19: =G16+G18 -> 1693619.9 | H19: =H16+H18 -> 1695210.1 | I19: =I16+I18 -> 7070001 | ... N19: =N16+N18 -> 34095021 | O19: =SUM(B19:N19) -> 1.3354176e+08
A20: Costs
A21: Month | B21: M0 Setup | C21: M1 Jan 2027 | D21: M2 Feb 2027 | E21: M3 Mar 2027 | F21: M4 Apr 2027 | G21: M5 May 2027 | H21: M6 Jun 2027 | I21: M7 Jul 2027 | J21: M8 Aug 2027 | K21: M9 Sep 2027 | L21: M10 Oct 2027 | M21: M11 Nov 2027 | N21: M12 Dec 2027 | O21: Year-1 Total
A22: Rider pay: ₹6 per parcel dropped (incl. never collected) | B22: =B5*(Assumptions!$B$13/12)*Assumptions!$B$16 -> 0 | C22: =C5*(Assumptions!$B$13/12)*Assumptions!$B$16 -> 613200 | D22: =D5*(Assumptions!$B$13/12)*Assumptions!$B$16 -> 613200 | E22: =E5*(Assumptions!$B$13/12)*Assumptions!$B$16 -> 613200 | F22: =F5*(Assumptions!$B$13/12)*Assumptions!$B$16 -> 613200 | G22: =G5*(Assumptions!$B$13/12)*Assumptions!$B$16 -> 613200 | H22: =H5*(Assumptions!$B$13/12)*Assumptions!$B$16 -> 613200 | I22: =I5*(Assumptions!$B$13/12)*Assumptions!$B$16 -> 2555000 | ... N22: =N5*(Assumptions!$B$13/12)*Assumptions!$B$16 -> 12264000 | O22: =SUM(B22:N22) -> 48136200
A23: Valmo hub: ₹7 per collected parcel (the part of ₹21 still paid) | B23: =B15*Assumptions!$B$15 -> 0 | C23: =C15*Assumptions!$B$15 -> 464203.68 | D23: =D15*Assumptions!$B$15 -> 464203.68 | E23: =E15*Assumptions!$B$15 -> 464203.68 | F23: =F15*Assumptions!$B$15 -> 464203.68 | G23: =G15*Assumptions!$B$15 -> 464203.68 | H23: =H15*Assumptions!$B$15 -> 464203.68 | I23: =I15*Assumptions!$B$15 -> 1934182 | ... N23: =N15*Assumptions!$B$15 -> 9284073.6 | O23: =SUM(B23:N23) -> 36439989
A24: Kirana pay: ₹7 per parcel handed over | B24: =B15*Assumptions!$B$17 -> 0 | C24: =C15*Assumptions!$B$17 -> 541570.96 | D24: =D15*Assumptions!$B$17 -> 541570.96 | E24: =E15*Assumptions!$B$17 -> 541570.96 | F24: =F15*Assumptions!$B$17 -> 541570.96 | G24: =G15*Assumptions!$B$17 -> 541570.96 | H24: =H15*Assumptions!$B$17 -> 541570.96 | I24: =I15*Assumptions!$B$17 -> 2256545.7 | ... N24: =N15*Assumptions!$B$17 -> 10831419 | O24: =SUM(B24:N24) -> 42513320
A25: Discount on 1st pickup order (collected only) | B25: =IF(Assumptions!$B$22>=1,B11*Assumptions!$B$39*Assumptions!$B$19*Assumptions!$B$6,0) -> 0 | C25: =IF(Assumptions!$B$22>=1,C11*Assumptions!$B$39*Assumptions!$B$19*Assumptions!$B$6,0) -> 1216844.6 | D25: =IF(Assumptions!$B$22>=1,D11*Assumptions!$B$39*Assumptions!$B$19*Assumptions!$B$6,0) -> 50712.572 | E25: =IF(Assumptions!$B$22>=1,E11*Assumptions!$B$39*Assumptions!$B$19*Assumptions!$B$6,0) -> 50712.572 | F25: =IF(Assumptions!$B$22>=1,F11*Assumptions!$B$39*Assumptions!$B$19*Assumptions!$B$6,0) -> 50712.572 | G25: =IF(Assumptions!$B$22>=1,G11*Assumptions!$B$39*Assumptions!$B$19*Assumptions!$B$6,0) -> 50712.572 | H25: =IF(Assumptions!$B$22>=1,H11*Assumptions!$B$39*Assumptions!$B$19*Assumptions!$B$6,0) -> 50712.572 | I25: =IF(Assumptions!$B$22>=1,I11*Assumptions!$B$39*Assumptions!$B$19*Assumptions!$B$6,0) -> 3904053.8 | ... N25: =IF(Assumptions!$B$22>=1,N11*Assumptions!$B$39*Assumptions!$B$19*Assumptions!$B$6,0) -> 4707002.8 | O25: =SUM(B25:N25) -> 27303577
A26: Discount on 2nd pickup order (collected only) | B26: =IF(Assumptions!$B$22>=1,B12*Assumptions!$B$39*Assumptions!$B$21*Assumptions!$B$6,0) -> 0 | C26: =IF(Assumptions!$B$22>=1,C12*Assumptions!$B$39*Assumptions!$B$21*Assumptions!$B$6,0) -> 0 | D26: =IF(Assumptions!$B$22>=1,D12*Assumptions!$B$39*Assumptions!$B$21*Assumptions!$B$6,0) -> 1166132 | E26: =IF(Assumptions!$B$22>=1,E12*Assumptions!$B$39*Assumptions!$B$21*Assumptions!$B$6,0) -> 48599.102 | F26: =IF(Assumptions!$B$22>=1,F12*Assumptions!$B$39*Assumptions!$B$21*Assumptions!$B$6,0) -> 48599.102 | G26: =IF(Assumptions!$B$22>=1,G12*Assumptions!$B$39*Assumptions!$B$21*Assumptions!$B$6,0) -> 48599.102 | H26: =IF(Assumptions!$B$22>=1,H12*Assumptions!$B$39*Assumptions!$B$21*Assumptions!$B$6,0) -> 48599.102 | I26: =IF(Assumptions!$B$22>=1,I12*Assumptions!$B$39*Assumptions!$B$21*Assumptions!$B$6,0) -> 48599.102 | ... N26: =IF(Assumptions!$B$22>=1,N12*Assumptions!$B$39*Assumptions!$B$21*Assumptions!$B$6,0) -> 4356939.1 | O26: =SUM(B26:N26) -> 21654852
A27: Festive surge to kiranas (Oct-Nov) | B27: =IF(OR(0=10,0=11),B15*Assumptions!$B$23,0) -> 0 | C27: =IF(OR(1=10,1=11),C15*Assumptions!$B$23,0) -> 0 | D27: =IF(OR(2=10,2=11),D15*Assumptions!$B$23,0) -> 0 | E27: =IF(OR(3=10,3=11),E15*Assumptions!$B$23,0) -> 0 | F27: =IF(OR(4=10,4=11),F15*Assumptions!$B$23,0) -> 0 | G27: =IF(OR(5=10,5=11),G15*Assumptions!$B$23,0) -> 0 | H27: =IF(OR(6=10,6=11),H15*Assumptions!$B$23,0) -> 0 | I27: =IF(OR(7=10,7=11),I15*Assumptions!$B$23,0) -> 0 | J27: =IF(OR(8=10,8=11),J15*Assumptions!$B$23,0) -> 0 | K27: =IF(OR(9=10,9=11),K15*Assumptions!$B$23,0) -> 0 | L27: =IF(OR(10=10,10=11),L15*Assumptions!$B$23,0) -> 0 | M27: =IF(OR(11=10,11=11),M15*Assumptions!$B$23,0) -> 0 | N27: =IF(OR(12=10,12=11),N15*Assumptions!$B$23,0) -> 0 | O27: =SUM(B27:N27) -> 0
A28: WhatsApp messages + service-provider markup | B28: =B5*(Assumptions!$B$13/12)*Assumptions!$B$70 -> 0 | C28: =C5*(Assumptions!$B$13/12)*Assumptions!$B$70 -> 25856.6 | D28: =D5*(Assumptions!$B$13/12)*Assumptions!$B$70 -> 25856.6 | E28: =E5*(Assumptions!$B$13/12)*Assumptions!$B$70 -> 25856.6 | F28: =F5*(Assumptions!$B$13/12)*Assumptions!$B$70 -> 25856.6 | G28: =G5*(Assumptions!$B$13/12)*Assumptions!$B$70 -> 25856.6 | H28: =H5*(Assumptions!$B$13/12)*Assumptions!$B$70 -> 25856.6 | I28: =I5*(Assumptions!$B$13/12)*Assumptions!$B$70 -> 107735.83 | ... N28: =N5*(Assumptions!$B$13/12)*Assumptions!$B$70 -> 517132 | O28: =SUM(B28:N28) -> 2029743.1
A29: OTP SMS at handover | B29: =B15*Assumptions!$B$55 -> 0 | C29: =C15*Assumptions!$B$55 -> 13926.11 | D29: =D15*Assumptions!$B$55 -> 13926.11 | E29: =E15*Assumptions!$B$55 -> 13926.11 | F29: =F15*Assumptions!$B$55 -> 13926.11 | G29: =G15*Assumptions!$B$55 -> 13926.11 | H29: =H15*Assumptions!$B$55 -> 13926.11 | I29: =I15*Assumptions!$B$55 -> 58025.46 | ... N29: =N15*Assumptions!$B$55 -> 278522.21 | O29: =SUM(B29:N29) -> 1093199.7
A30: UPI payment cost at the counter | B30: =B15*Assumptions!$B$56*Assumptions!$B$6 -> 0 | C30: =C15*Assumptions!$B$56*Assumptions!$B$6 -> 0 | D30: =D15*Assumptions!$B$56*Assumptions!$B$6 -> 0 | E30: =E15*Assumptions!$B$56*Assumptions!$B$6 -> 0 | F30: =F15*Assumptions!$B$56*Assumptions!$B$6 -> 0 | G30: =G15*Assumptions!$B$56*Assumptions!$B$6 -> 0 | H30: =H15*Assumptions!$B$56*Assumptions!$B$6 -> 0 | I30: =I15*Assumptions!$B$56*Assumptions!$B$6 -> 0 | ... N30: =N15*Assumptions!$B$56*Assumptions!$B$6 -> 0 | O30: =SUM(B30:N30) -> 0
A31: Customer-support contacts | B31: =B5*(Assumptions!$B$13/12)*Assumptions!$B$57*Assumptions!$B$58 -> 0 | C31: =C5*(Assumptions!$B$13/12)*Assumptions!$B$57*Assumptions!$B$58 -> 45990 | D31: =D5*(Assumptions!$B$13/12)*Assumptions!$B$57*Assumptions!$B$58 -> 45990 | E31: =E5*(Assumptions!$B$13/12)*Assumptions!$B$57*Assumptions!$B$58 -> 45990 | F31: =F5*(Assumptions!$B$13/12)*Assumptions!$B$57*Assumptions!$B$58 -> 45990 | G31: =G5*(Assumptions!$B$13/12)*Assumptions!$B$57*Assumptions!$B$58 -> 45990 | H31: =H5*(Assumptions!$B$13/12)*Assumptions!$B$57*Assumptions!$B$58 -> 45990 | I31: =I5*(Assumptions!$B$13/12)*Assumptions!$B$57*Assumptions!$B$58 -> 191625 | ... N31: =N5*(Assumptions!$B$13/12)*Assumptions!$B$57*Assumptions!$B$58 -> 919800 | O31: =SUM(B31:N31) -> 3610215
A32: Handover photo storage | B32: =B6*Assumptions!$B$60*Assumptions!$B$59/1000000*Assumptions!$B$61 -> 0 | C32: =C6*Assumptions!$B$60*Assumptions!$B$59/1000000*Assumptions!$B$61 -> 192.29478 | D32: =D6*Assumptions!$B$60*Assumptions!$B$59/1000000*Assumptions!$B$61 -> 192.29478 | E32: =E6*Assumptions!$B$60*Assumptions!$B$59/1000000*Assumptions!$B$61 -> 192.29478 | F32: =F6*Assumptions!$B$60*Assumptions!$B$59/1000000*Assumptions!$B$61 -> 192.29478 | G32: =G6*Assumptions!$B$60*Assumptions!$B$59/1000000*Assumptions!$B$61 -> 192.29478 | H32: =H6*Assumptions!$B$60*Assumptions!$B$59/1000000*Assumptions!$B$61 -> 192.29478 | I32: =I6*Assumptions!$B$60*Assumptions!$B$59/1000000*Assumptions!$B$61 -> 801.22827 | ... N32: =N6*Assumptions!$B$60*Assumptions!$B$59/1000000*Assumptions!$B$61 -> 3845.8957 | O32: =SUM(B32:N32) -> 15095.141
A33: Kirana onboarding (₹2,000 per kirana added) | B33: =B8*Assumptions!$B$68 -> 0 | C33: =C8*Assumptions!$B$68 -> 224000 | D33: =D8*Assumptions!$B$68 -> 0 | E33: =E8*Assumptions!$B$68 -> 0 | F33: =F8*Assumptions!$B$68 -> 0 | G33: =G8*Assumptions!$B$68 -> 0 | H33: =H8*Assumptions!$B$68 -> 0 | I33: =I8*Assumptions!$B$68 -> 710000 | ... N33: =N8*Assumptions!$B$68 -> 708000 | O33: =SUM(B33:N33) -> 4480000
A34: Contingency (10% of discount to onboarding) | B34: =SUM(B25:B33)*Assumptions!$B$62 -> 0 | C34: =SUM(C25:C33)*Assumptions!$B$62 -> 152680.96 | D34: =SUM(D25:D33)*Assumptions!$B$62 -> 130280.96 | E34: =SUM(E25:E33)*Assumptions!$B$62 -> 18527.668 | F34: =SUM(F25:F33)*Assumptions!$B$62 -> 18527.668 | G34: =SUM(G25:G33)*Assumptions!$B$62 -> 18527.668 | H34: =SUM(H25:H33)*Assumptions!$B$62 -> 18527.668 | I34: =SUM(I25:I33)*Assumptions!$B$62 -> 502084.04 | ... N34: =SUM(N25:N33)*Assumptions!$B$62 -> 1149124.2 | O34: =SUM(B34:N34) -> 6018668.2
A35: One-time: tech build | B35: =Assumptions!$B$64 -> 1500000 | C35: =0 -> 0 | D35: =0 -> 0 | E35: =0 -> 0 | F35: =0 -> 0 | G35: =0 -> 0 | H35: =0 -> 0 | I35: =0 -> 0 | J35: =0 -> 0 | ... N35: =0 -> 0 | O35: =SUM(B35:N35) -> 1500000
A36: One-time: kirana training + message translation | B36: =Assumptions!$B$65*Assumptions!$B$66 -> 50000 | C36: =0 -> 0 | D36: =0 -> 0 | E36: =0 -> 0 | F36: =0 -> 0 | G36: =0 -> 0 | H36: =0 -> 0 | I36: =0 -> 0 | J36: =0 -> 0 | ... N36: =0 -> 0 | O36: =SUM(B36:N36) -> 50000
A37: One-time: legal (partner agreement, DPDP consent) | B37: =Assumptions!$B$67 -> 200000 | C37: =0 -> 0 | D37: =0 -> 0 | E37: =0 -> 0 | F37: =0 -> 0 | G37: =0 -> 0 | H37: =0 -> 0 | I37: =0 -> 0 | J37: =0 -> 0 | ... N37: =0 -> 0 | O37: =SUM(B37:N37) -> 200000
A38: Total Costs | B38: =SUM(B22:B37) -> 1750000 | C38: =SUM(C22:C37) -> 3298465.2 | D38: =SUM(D22:D37) -> 3052065.2 | E38: =SUM(E22:E37) -> 1822779 | F38: =SUM(F22:F37) -> 1822779 | G38: =SUM(G22:G37) -> 1822779 | H38: =SUM(H22:H37) -> 1822779 | I38: =SUM(I22:I37) -> 12268652 | ... N38: =SUM(N22:N37) -> 45019859 | O38: =SUM(B38:N38) -> 1.9504486e+08
A39: Payback
A40: Month | B40: M0 Setup | C40: M1 Jan 2027 | D40: M2 Feb 2027 | E40: M3 Mar 2027 | F40: M4 Apr 2027 | G40: M5 May 2027 | H40: M6 Jun 2027 | I40: M7 Jul 2027 | J40: M8 Aug 2027 | K40: M9 Sep 2027 | L40: M10 Oct 2027 | M40: M11 Nov 2027 | N40: M12 Dec 2027 | O40: Year-1 Total
...

Sheet Kirana Earnings
A1: Kirana Earnings vs Shelf-Space Cost (one kirana, one month)
A3: Inputs
A4: Input | B4: Value | C4: Unit
A5: Parcels dropped at the kirana per day | B5: =Assumptions!$B$42 -> 30 | C5: parcels/day
A6: Share of parcels the customer collects | B6: =Assumptions!$B$39 -> 0.75701839 | C6: %
A7: Pay per parcel handed over | B7: =Assumptions!$B$17 -> 7 | C7: ₹/parcel
A8: Festive surge per parcel (Oct-Nov) | B8: =Assumptions!$B$23 -> 0 | C8: ₹/parcel
A9: Days in a month | B9: =Assumptions!$B$13/12 -> 30.416667 | C9: days
A10: Hold period before an uncollected parcel is returned | B10: =Assumptions!$B$24 -> 5 | C10: days
A11: Average days a collected parcel waits on the shelf | B11: 2 | C11: days
A12: Parcels one rack holds | B12: 60 | C12: parcels
A13: Floor space one rack takes | B13: 4.5 | C13: sq ft
A14: Monthly shop rent, small town (mid-point) | B14: 14000 | C14: ₹/month
A15: Shop size, small town (mid-point) | B15: 450 | C15: sq ft
A16: Rent per sq ft per month | B16: =B14/B15 -> 31.111111 | C16: ₹/sq ft/month
A18: One kirana, one month, at the model's load
A19: Line | B19: Value | C19: Unit | G19: How it is worked out
A20: Parcels handed over in the month | B20: =$B$5*$B$6*$B$9 -> 690.77928 | C20: parcels | G20: Parcels a day x share collected x days
A21: Earnings from handovers | B21: =B20*$B$7 -> 4835.455 | C21: ₹ | G21: Handovers x pay per parcel
A22: Festive surge (averaged over the year) | B22: =B20*$B$8*2/12 -> 0 | C22: ₹ | G22: 2 months of 12 at the surge rate
A23: Total monthly earnings | B23: =B21+B22 -> 4835.455 | C23: ₹
A24: Parcels on the shelf on an average day | B24: =$B$5*($B$6*$B$11+(1-$B$6)*$B$10) -> 81.868345 | C24: parcels | G24: Collected parcels wait ~2 days; uncollected ones wait the full hold
A25: Racks needed | B25: =ROUNDUP(B24/$B$12,0) -> 2 | C25: racks | G25: Parcels on shelf ÷ parcels per rack, rounded up
A26: Floor space used | B26: =B25*$B$13 -> 9 | C26: sq ft | G26: Racks x floor space per rack
A27: Share of the shop given to Meesho parcels | B27: =B26/$B$15 -> 0.02 | C27: % | G27: Floor space ÷ shop size
A28: Shelf-space cost (rent of that floor space) | B28: =B26*$B$16 -> 280 | C28: ₹ | G28: Floor space x rent per sq ft
A29: Net monthly earning after shelf-space cost | B29: =B23-B28 -> 4555.455 | C29: ₹ | G29: What the kirana keeps
A30: Earnings per ₹1 of shelf-space cost | B30: =B23/B28 -> 17.269482 | C30: ₹
A31: Earnings per sq ft used vs rent per sq ft | B31: =TEXT(B23/B26,"₹#,##0")&" vs "&TEXT($B$16,"₹#,##0") -> ₹537 vs ₹31 | C31: ₹/sq ft | G31: What the space earns from parcels vs what it costs in rent
A32: Refundable deposit (memo, not a cost) | B32: =Assumptions!$B$25 -> 5000 | C32: ₹ once | G32: Taken in instalments from early payouts and returned on exit
A34: If the kirana gets fewer or more parcels a day
A35: Parcels dropped per day | B35: 10 | C35: 20 | D35: 30 | E35: 40 | F35: 50
A36: Monthly earnings | B36: =B35*$B$6*$B$9*($B$7+$B$8*2/12) -> 1611.8183 | C36: =C35*$B$6*$B$9*($B$7+$B$8*2/12) -> 3223.6367 | D36: =D35*$B$6*$B$9*($B$7+$B$8*2/12) -> 4835.455 | E36: =E35*$B$6*$B$9*($B$7+$B$8*2/12) -> 6447.2733 | F36: =F35*$B$6*$B$9*($B$7+$B$8*2/12) -> 8059.0916
A37: Racks needed | B37: =ROUNDUP(B35*($B$6*$B$11+(1-$B$6)*$B$10)/$B$12,0) -> 1 | C37: =ROUNDUP(C35*($B$6*$B$11+(1-$B$6)*$B$10)/$B$12,0) -> 1 | D37: =ROUNDUP(D35*($B$6*$B$11+(1-$B$6)*$B$10)/$B$12,0) -> 2 | E37: =ROUNDUP(E35*($B$6*$B$11+(1-$B$6)*$B$10)/$B$12,0) -> 2 | F37: =ROUNDUP(F35*($B$6*$B$11+(1-$B$6)*$B$10)/$B$12,0) -> 3
A38: Shelf-space cost | B38: =B37*$B$13*$B$16 -> 140 | C38: =C37*$B$13*$B$16 -> 140 | D38: =D37*$B$13*$B$16 -> 280 | E38: =E37*$B$13*$B$16 -> 280 | F38: =F37*$B$13*$B$16 -> 420
A39: Net monthly earning | B39: =B36-B38 -> 1471.8183 | C39: =C36-C38 -> 3083.6367 | D39: =D36-D38 -> 4555.455 | E39: =E36-E38 -> 6167.2733 | F39: =F36-F38 -> 7639.0916
A41: Year 1 by month: average payout per live kirana (from the Year 1 Monthly sheet)
A42: Month | B42: M1 | C42: M3 | D42: M6 | E42: M9 | F42: M12
A43: Kiranas live | B43: ='Year 1 Monthly'!C7 -> 112 | C43: ='Year 1 Monthly'!E7 -> 112 | D43: ='Year 1 Monthly'!H7 -> 112 | E43: ='Year 1 Monthly'!K7 -> 1176 | F43: ='Year 1 Monthly'!N7 -> 2240
A44: Paid to all kiranas in the month | B44: ='Year 1 Monthly'!C24 -> 541570.96 | C44: ='Year 1 Monthly'!E24 -> 541570.96 | D44: ='Year 1 Monthly'!H24 -> 541570.96 | E44: ='Year 1 Monthly'!K24 -> 5686495.1 | F44: ='Year 1 Monthly'!N24 -> 10831419
...
