Workbook

Sheet Assumptions 
A1: Assumptions
A2: Parameter | B2: Value | C2: Unit | D2: Link
A3: 1. Volume and logistics cost
A4: Valmo orders per day | B4: 4200000 | C4: orders/day
A5: COD share of orders | B5: 0.8 | C5: % | D5: Open source ↗
A6: RTO rate on COD orders (today) | B6: 0.2 | C6: % | D6: Open source ↗
A7: Forward cost already spent when an order fails (spent by seller) | B7: 29 | C7: ₹/order
A8: Reverse logistics cost per RTO | B8: 120 | C8: ₹/order
A9: Days per year | B9: 365 | C9: days
A11: 2. Re-basing D2C benchmarks to Meesho's customers
A12: No. of orders below Tier-3 for general E-Commerce | B12: 0.38 | C12: % | D12: Open source ↗
A13: Meesho tier-3-and-below share of orders | B13: 0.65 | C13: % | D13: Open source ↗
A14: Small-town vs city messaging reach ratio | B14: 0.815 | C14: x | D14: Open source ↗
A15: WhatsApp confirm-response rate in D2C benchmarks | B15: 0.6 | C15: % | D15: Open source ↗
A16: Average COD RTO in D2C benchmarks | B16: 0.265 | C16: % | D16: Open source ↗
A17: First-time-buyer COD RTO in D2C benchmarks | B17: 0.35 | C17: % | D17: Open source ↗
A18: Intent-driven share of RTOs in D2C benchmarks | B18: 0.375 | C18: % | D18: Open source ↗
A19: Intent-driven share of RTOs at Valmo | B19: 0.16 | C19: % | D19: Open source ↗
A21: 3. Flow, targeting and behaviour (Meesho-adjusted)
A22: Flow | B22: WhatsApp to all COD orders → SMS (reply YES/NO) to non-responders → IVR only for high-risk orders still silent
A23: Share of COD orders flagged high-risk (IVR-eligible) (RTO Value v/s No. of orders) | B23: 0.2 | C23: % | D23: Open source ↗
A24: WhatsApp confirm-response rate (Meesho) | B24: =$B$15*((1-$B$13)+$B$13*$B$14)/((1-$B$12)+$B$12*$B$14) -> 0.56776379 | C24: %
A25: Risk multiple of flagged customers | B25: ='Assumptions '!$B$17/'Assumptions '!$B$16 -> 1.3207547 | C25: x
A26: RTO rate among flagged orders (Meesho) | B26: =MIN(1,'Assumptions '!$B$6*'Assumptions '!$B$25) -> 0.26415094 | C26: %
A27: RTO rate among non-flagged orders (Meesho) | B27: =('Assumptions '!$B$6-'Assumptions '!$B$23*'Assumptions '!$B$26)/(1-'Assumptions '!$B$23) -> 0.18396226 | C27: %
A28: SMS reply rate (among WhatsApp non-responders) | B28: 0.15 | C28: %
A29: IVR answer rate per call attempt | B29: 0.2 | C29: % | D29: Open source ↗
A30: Max IVR attempts per order | B30: 2 | C30: calls | D30: Open source ↗
A31: Cancel rate among reached would-be RTOs in D2C benchmarks | B31: 0.48 | C31: % | D31: Open source ↗
A32: Cancel rate among reached would-be RTOs (Meesho) | B32: =MIN(1,'Assumptions '!$B$31*'Assumptions '!$B$19/'Assumptions '!$B$18) -> 0.2048 | C32: %
A33: Genuine-order loss rate among flagged orders | B33: 0.03 | C33: % | D33: Open source ↗
A34: Contribution lost per lost genuine order | B34: 11.04 | C34: ₹/order | D34: Open source ↗
A35: 1-attempt RTO rule applies to: 1 = every failed first attempt, 0 = doorstep refusals only | B35: 0 | C35: switch
A36: Share of those orders delivered only on a re-attempt | B36: 0.342 | C36: %
A37: Flagged orders that contact customer support | B37: 0.03 | C37: %
A38: Cost per customer-support contact | B38: 15 | C38: ₹/contact
A39: Days from order to when the RTO would have happened | B39: 13 | C39: days | D39: Open source ↗
A41: 4. Messaging and telephony prices
A42: WhatsApp utility message (Meta rate, India) | B42: 0.115 | C42: ₹/msg | D42: Open source ↗
A43: WhatsApp confirmation templates per COD order (Utility/Service) | B43: 1 | C43: msgs
...

Sheet Final Payback
A1: Total Costs
A2: Month | B2: M0 | C2: M1 | D2: M2 | E2: M3 | F2: M4 | G2: M5 | H2: M6 | I2: M7 | J2: M8 | K2: M9 | L2: M10 | M2: M11 | N2: M12 | O2: Year 1
A3: WhatsApp Costs | B3: ='Final WhatsApp'!B5 -> 0 | C3: ='Final WhatsApp'!C5 -> 1013426 | D3: ='Final WhatsApp'!D5 -> 1013426 | E3: ='Final WhatsApp'!E5 -> 5067130.2 | F3: ='Final WhatsApp'!F5 -> 10134260 | G3: ='Final WhatsApp'!G5 -> 20268521 | H3: ='Final WhatsApp'!H5 -> 20268521 | I3: ='Final WhatsApp'!I5 -> 20268521 | ... N3: ='Final WhatsApp'!N5 -> 20268521 | O3: =SUM(B3:N3) -> 1.7937641e+08
A4: SMS Costs | B4: ='Final SMS'!B7 -> 50000 | C4: ='Final SMS'!C7 -> 432575.59 | D4: ='Final SMS'!D7 -> 432575.59 | E4: ='Final SMS'!E7 -> 2128877.9 | F4: ='Final SMS'!F7 -> 4249255.9 | G4: ='Final SMS'!G7 -> 8490011.7 | H4: ='Final SMS'!H7 -> 8490011.7 | I4: ='Final SMS'!I7 -> 8490011.7 | ... N4: ='Final SMS'!N7 -> 8490011.7 | O4: =SUM(B4:N4) -> 75213379
A5: IVR Costs | B5: ='Final IVR'!B5 -> 0 | C5: ='Final IVR'!C5 -> 56366.155 | D5: ='Final IVR'!D5 -> 56366.155 | E5: ='Final IVR'!E5 -> 281830.78 | F5: ='Final IVR'!F5 -> 563661.55 | G5: ='Final IVR'!G5 -> 1127323.1 | H5: ='Final IVR'!H5 -> 1127323.1 | I5: ='Final IVR'!I5 -> 1127323.1 | ... N5: ='Final IVR'!N5 -> 1127323.1 | O5: =SUM(B5:N5) -> 9976809.5
A6: Shared & Setup Costs | B6: ='Final Shared Costs'!B15 -> 690960 | C6: ='Final Shared Costs'!C15 -> 1041570.6 | D6: ='Final Shared Costs'!D15 -> 1041570.6 | E6: ='Final Shared Costs'!E15 -> 4760053.1 | F6: ='Final Shared Costs'!F15 -> 9408156.2 | G6: ='Final Shared Costs'!G15 -> 18704362 | H6: ='Final Shared Costs'!H15 -> 18704362 | I6: ='Final Shared Costs'!I15 -> 18704362 | ... N6: ='Final Shared Costs'!N15 -> 18924362 | O6: =SUM(B6:N6) -> 166797209
A7: Total Costs | B7: =SUM(B3:B6) -> 740960 | C7: =SUM(C3:C6) -> 2543938.4 | D7: =SUM(D3:D6) -> 2543938.4 | E7: =SUM(E3:E6) -> 12237892 | F7: =SUM(F3:F6) -> 24355334 | G7: =SUM(G3:G6) -> 48590218 | H7: =SUM(H3:H6) -> 48590218 | I7: =SUM(I3:I6) -> 48590218 | ... N7: =SUM(N3:N6) -> 48810218 | O7: =SUM(B7:N7) -> 4.3136381e+08
A9: Net Savings and Payback
A10: Month | B10: M0 | C10: M1 | D10: M2 | E10: M3 | F10: M4 | G10: M5 | H10: M6 | I10: M7 | J10: M8 | K10: M9 | L10: M10 | M10: M11 | N10: M12 | O10: Year 1
A11: Total Cost | B11: =B7 -> 740960 | C11: =C7 -> 2543938.4 | D11: =D7 -> 2543938.4 | E11: =E7 -> 12237892 | F11: =F7 -> 24355334 | G11: =G7 -> 48590218 | H11: =H7 -> 48590218 | I11: =I7 -> 48590218 | ... N11: =N7 -> 48810218 | O11: =SUM(B11:N11) -> 4.3136381e+08
A12: Cost Avoided | B12: ='Final Cost Avoided'!B6 -> 0 | C12: ='Final Cost Avoided'!C6 -> 9600433.2 | D12: ='Final Cost Avoided'!D6 -> 16766307 | E12: ='Final Cost Avoided'!E6 -> 55168040 | F12: ='Final Cost Avoided'!F6 -> 1.318337e+08 | G12: ='Final Cost Avoided'!G6 -> 2.636674e+08 | H12: ='Final Cost Avoided'!H6 -> 3.3532614e+08 | I12: ='Final Cost Avoided'!I6 -> 3.3532614e+08 | ... N12: ='Final Cost Avoided'!N6 -> 3.3532614e+08 | O12: =SUM(B12:N12) -> 2824318842
A13: Net Savings | B13: =B12-B11 -> -740960 | C13: =C12-C11 -> 7056494.9 | D13: =D12-D11 -> 14222368 | E13: =E12-E11 -> 42930148 | F13: =F12-F11 -> 1.0747837e+08 | G13: =G12-G11 -> 2.1507718e+08 | H13: =H12-H11 -> 2.8673592e+08 | I13: =I12-I11 -> 2.8673592e+08 | ... N13: =N12-N11 -> 2.8651592e+08 | O13: =SUM(B13:N13) -> 2392955037
A14: Cumulative Net Savings | B14: =B13 -> -740960 | C14: =B14+C13 -> 6315534.9 | D14: =C14+D13 -> 20537903 | E14: =D14+E13 -> 63468051 | F14: =E14+F13 -> 1.7094642e+08 | G14: =F14+G13 -> 3.860236e+08 | H14: =G14+H13 -> 6.7275952e+08 | I14: =H14+I13 -> 9.5949544e+08 | J14: =I14+J13 -> 1246231359 | ... N14: =M14+N13 -> 2392955037 | O14: =N14 -> 2392955037
A15: Investment Paid Back? | B15: =IF(B14>=0,"Yes","No") -> No | C15: =IF(C14>=0,"Yes","No") -> Yes | D15: =IF(D14>=0,"Yes","No") -> Yes | E15: =IF(E14>=0,"Yes","No") -> Yes | F15: =IF(F14>=0,"Yes","No") -> Yes | G15: =IF(G14>=0,"Yes","No") -> Yes | H15: =IF(H14>=0,"Yes","No") -> Yes | I15: =IF(I14>=0,"Yes","No") -> Yes | ... N15: =IF(N14>=0,"Yes","No") -> Yes
A17: Key Ratios
A18: Month | B18: M0 | C18: M1 | D18: M2 | E18: M3 | F18: M4 | G18: M5 | H18: M6 | I18: M7 | J18: M8 | K18: M9 | L18: M10 | M18: M11 | N18: M12 | O18: Year 1
A19: Share of COD orders live | B19: ='Payback Analysis '!C$13 -> 0 | C19: ='Payback Analysis '!D$13 -> 0.05 | D19: ='Payback Analysis '!E$13 -> 0.05 | E19: ='Payback Analysis '!F$13 -> 0.25 | F19: ='Payback Analysis '!G$13 -> 0.5 | G19: ='Payback Analysis '!H$13 -> 1 | H19: ='Payback Analysis '!I$13 -> 1 | I19: ='Payback Analysis '!J$13 -> 1 | ... N19: ='Payback Analysis '!O$13 -> 1 | O19: =AVERAGE(C19:N19) -> 0.7375
A20: Cost Avoided per ₹1 spent | B20: =IF(B11=0,"",B12/B11) -> 0 | C20: =IF(C11=0,"",C12/C11) -> 3.7738466 | D20: =IF(D11=0,"",D12/D11) -> 6.590689 | E20: =IF(E11=0,"",E12/E11) -> 4.5079692 | F20: =IF(F11=0,"",F12/F11) -> 5.4129293 | G20: =IF(G11=0,"",G12/G11) -> 5.4263474 | H20: =IF(H11=0,"",H12/H11) -> 6.9011038 | I20: =IF(I11=0,"",I12/I11) -> 6.9011038 | ... N20: =IF(N11=0,"",N12/N11) -> 6.8699988 | O20: =O12/O11 -> 6.5474173
A21: RTOs prevented | B21: ='Final Cost Avoided'!B13+'Final Cost Avoided'!B22+'Final Cost Avoided'!B31 -> 0 | C21: ='Final Cost Avoided'!C13+'Final Cost Avoided'!C22+'Final Cost Avoided'!C31 -> 80003.61 | D21: ='Final Cost Avoided'!D13+'Final Cost Avoided'!D22+'Final Cost Avoided'!D31 -> 139719.22 | E21: ='Final Cost Avoided'!E13+'Final Cost Avoided'!E22+'Final Cost Avoided'!E31 -> 459733.67 | F21: ='Final Cost Avoided'!F13+'Final Cost Avoided'!F22+'Final Cost Avoided'!F31 -> 1098614.2 | G21: ='Final Cost Avoided'!G13+'Final Cost Avoided'!G22+'Final Cost Avoided'!G31 -> 2197228.3 | H21: ='Final Cost Avoided'!H13+'Final Cost Avoided'!H22+'Final Cost Avoided'!H31 -> 2794384.5 | I21: ='Final Cost Avoided'!I13+'Final Cost Avoided'!I22+'Final Cost Avoided'!I31 -> 2794384.5 | ... N21: ='Final Cost Avoided'!N13+'Final Cost Avoided'!N22+'Final Cost Avoided'!N31 -> 2794384.5 | O21: =SUM(B21:N21) -> 23535990

Sheet Final Cost Avoided
A1: Total Cost Avoided (logistics cost saved on RTOs prevented)
A2: Channel | B2: M0 | C2: M1 | D2: M2 | E2: M3 | F2: M4 | G2: M5 | H2: M6 | I2: M7 | J2: M8 | K2: M9 | L2: M10 | M2: M11 | N2: M12 | O2: Year 1
A3: WhatsApp | B3: =B15 -> 0 | C3: =C15 -> 8165508 | D3: =D15 -> 14260337 | E3: =E15 -> 46922369 | F3: =F15 -> 1.1212923e+08 | G3: =G15 -> 2.2425845e+08 | H3: =H15 -> 2.8520674e+08 | I3: =I15 -> 2.8520674e+08 | ... N3: =N15 -> 2.8520674e+08 | O3: =SUM(B3:N3) -> 2402183071
A4: SMS | B4: =B24 -> 0 | C4: =C24 -> 932455.07 | D4: =D24 -> 1628450.2 | E4: =E24 -> 5358270.5 | F4: =F24 -> 12804527 | G4: =G24 -> 25609053 | H4: =H24 -> 32569005 | I4: =I24 -> 32569005 | ... N4: =N24 -> 32569005 | O4: =SUM(B4:N4) -> 2.7431579e+08
A5: IVR Call | B5: =B33 -> 0 | C5: =C33 -> 502470.13 | D5: =D33 -> 877519.61 | E5: =E33 -> 2887400.1 | F5: =F33 -> 6899948.7 | G5: =G33 -> 13799897 | H5: =H33 -> 17550392 | I5: =I33 -> 17550392 | ... N5: =N33 -> 17550392 | O5: =SUM(B5:N5) -> 1.4781998e+08
A6: Total Cost Avoided | B6: =SUM(B3:B5) -> 0 | C6: =SUM(C3:C5) -> 9600433.2 | D6: =SUM(D3:D5) -> 16766307 | E6: =SUM(E3:E5) -> 55168040 | F6: =SUM(F3:F5) -> 1.318337e+08 | G6: =SUM(G3:G5) -> 2.636674e+08 | H6: =SUM(H3:H5) -> 3.3532614e+08 | I6: =SUM(I3:I5) -> 3.3532614e+08 | ... N6: =SUM(N3:N5) -> 3.3532614e+08 | O6: =SUM(B6:N6) -> 2824318842
A8: WHATSAPP (all COD orders)
A9: Month | B9: M0 | C9: M1 | D9: M2 | E9: M3 | F9: M4 | G9: M5 | H9: M6 | I9: M7 | J9: M8 | K9: M9 | L9: M10 | M9: M11 | N9: M12 | O9: Year 1
A10: RTOs prevented per day at full scale | B10: ='Assumptions '!$B$96 -> 78138.833 | C10: ='Assumptions '!$B$96 -> 78138.833 | D10: ='Assumptions '!$B$96 -> 78138.833 | E10: ='Assumptions '!$B$96 -> 78138.833 | F10: ='Assumptions '!$B$96 -> 78138.833 | G10: ='Assumptions '!$B$96 -> 78138.833 | H10: ='Assumptions '!$B$96 -> 78138.833 | I10: ='Assumptions '!$B$96 -> 78138.833 | ... N10: ='Assumptions '!$B$96 -> 78138.833
A11: Share of savings realised this month | B11: ='Payback Analysis '!C$14 -> 0 | C11: ='Payback Analysis '!D$14 -> 0.028630137 | D11: ='Payback Analysis '!E$14 -> 0.05 | E11: ='Payback Analysis '!F$14 -> 0.16452055 | F11: ='Payback Analysis '!G$14 -> 0.39315068 | G11: ='Payback Analysis '!H$14 -> 0.78630137 | H11: ='Payback Analysis '!I$14 -> 1 | I11: ='Payback Analysis '!J$14 -> 1 | ... N11: ='Payback Analysis '!O$14 -> 1
A12: Days in month | B12: =('Assumptions '!$B$9/12) -> 30.416667 | C12: =('Assumptions '!$B$9/12) -> 30.416667 | D12: =('Assumptions '!$B$9/12) -> 30.416667 | E12: =('Assumptions '!$B$9/12) -> 30.416667 | F12: =('Assumptions '!$B$9/12) -> 30.416667 | G12: =('Assumptions '!$B$9/12) -> 30.416667 | H12: =('Assumptions '!$B$9/12) -> 30.416667 | I12: =('Assumptions '!$B$9/12) -> 30.416667 | ... N12: =('Assumptions '!$B$9/12) -> 30.416667
A13: No. of RTOs prevented | B13: =B10*B11*B12 -> 0 | C13: =C10*C11*C12 -> 68045.9 | D13: =D10*D11*D12 -> 118836.14 | E13: =E10*E11*E12 -> 391019.74 | F13: =F10*F11*F12 -> 934410.21 | G13: =G10*G11*G12 -> 1868820.4 | H13: =H10*H11*H12 -> 2376722.8 | I13: =I10*I11*I12 -> 2376722.8 | ... N13: =N10*N11*N12 -> 2376722.8 | O13: =SUM(B13:N13) -> 20018192
A14: Saving per RTO prevented (reverse cost) | B14: ='Assumptions '!$B$100 -> 120 | C14: ='Assumptions '!$B$100 -> 120 | D14: ='Assumptions '!$B$100 -> 120 | E14: ='Assumptions '!$B$100 -> 120 | F14: ='Assumptions '!$B$100 -> 120 | G14: ='Assumptions '!$B$100 -> 120 | H14: ='Assumptions '!$B$100 -> 120 | I14: ='Assumptions '!$B$100 -> 120 | ... N14: ='Assumptions '!$B$100 -> 120
A15: Total Cost Avoided | B15: =B13*B14 -> 0 | C15: =C13*C14 -> 8165508 | D15: =D13*D14 -> 14260337 | E15: =E13*E14 -> 46922369 | F15: =F13*F14 -> 1.1212923e+08 | G15: =G13*G14 -> 2.2425845e+08 | H15: =H13*H14 -> 2.8520674e+08 | I15: =I13*I14 -> 2.8520674e+08 | ... N15: =N13*N14 -> 2.8520674e+08 | O15: =SUM(B15:N15) -> 2402183071
A17: SMS (WhatsApp non-responders)
A18: Month | B18: M0 | C18: M1 | D18: M2 | E18: M3 | F18: M4 | G18: M5 | H18: M6 | I18: M7 | J18: M8 | K18: M9 | L18: M10 | M18: M11 | N18: M12 | O18: Year 1
A19: RTOs prevented per day at full scale | B19: ='Assumptions '!$B$97 -> 8923.0151 | C19: ='Assumptions '!$B$97 -> 8923.0151 | D19: ='Assumptions '!$B$97 -> 8923.0151 | E19: ='Assumptions '!$B$97 -> 8923.0151 | F19: ='Assumptions '!$B$97 -> 8923.0151 | G19: ='Assumptions '!$B$97 -> 8923.0151 | H19: ='Assumptions '!$B$97 -> 8923.0151 | I19: ='Assumptions '!$B$97 -> 8923.0151 | ... N19: ='Assumptions '!$B$97 -> 8923.0151
A20: Share of savings realised this month | B20: ='Payback Analysis '!C$14 -> 0 | C20: ='Payback Analysis '!D$14 -> 0.028630137 | D20: ='Payback Analysis '!E$14 -> 0.05 | E20: ='Payback Analysis '!F$14 -> 0.16452055 | F20: ='Payback Analysis '!G$14 -> 0.39315068 | G20: ='Payback Analysis '!H$14 -> 0.78630137 | H20: ='Payback Analysis '!I$14 -> 1 | I20: ='Payback Analysis '!J$14 -> 1 | ... N20: ='Payback Analysis '!O$14 -> 1
A21: Days in month | B21: =('Assumptions '!$B$9/12) -> 30.416667 | C21: =('Assumptions '!$B$9/12) -> 30.416667 | D21: =('Assumptions '!$B$9/12) -> 30.416667 | E21: =('Assumptions '!$B$9/12) -> 30.416667 | F21: =('Assumptions '!$B$9/12) -> 30.416667 | G21: =('Assumptions '!$B$9/12) -> 30.416667 | H21: =('Assumptions '!$B$9/12) -> 30.416667 | I21: =('Assumptions '!$B$9/12) -> 30.416667 | ... N21: =('Assumptions '!$B$9/12) -> 30.416667
A22: No. of RTOs prevented | B22: =B19*B20*B21 -> 0 | C22: =C19*C20*C21 -> 7770.459 | D22: =D19*D20*D21 -> 13570.419 | E22: =E19*E20*E21 -> 44652.255 | F22: =F19*F20*F21 -> 106704.39 | G22: =G19*G20*G21 -> 213408.78 | H22: =H19*H20*H21 -> 271408.37 | I22: =I19*I20*I21 -> 271408.37 | ... N22: =N19*N20*N21 -> 271408.37 | O22: =SUM(B22:N22) -> 2285964.9
A23: Saving per RTO prevented (reverse cost) | B23: ='Assumptions '!$B$100 -> 120 | C23: ='Assumptions '!$B$100 -> 120 | D23: ='Assumptions '!$B$100 -> 120 | E23: ='Assumptions '!$B$100 -> 120 | F23: ='Assumptions '!$B$100 -> 120 | G23: ='Assumptions '!$B$100 -> 120 | H23: ='Assumptions '!$B$100 -> 120 | I23: ='Assumptions '!$B$100 -> 120 | ... N23: ='Assumptions '!$B$100 -> 120
A24: Total Cost Avoided | B24: =B22*B23 -> 0 | C24: =C22*C23 -> 932455.07 | D24: =D22*D23 -> 1628450.2 | E24: =E22*E23 -> 5358270.5 | F24: =F22*F23 -> 12804527 | G24: =G22*G23 -> 25609053 | H24: =H22*H23 -> 32569005 | I24: =I22*I23 -> 32569005 | ... N24: =N22*N23 -> 32569005 | O24: =SUM(B24:N24) -> 2.7431579e+08
A26: IVR CALL (high-risk, still silent)
A27: Month | B27: M0 | C27: M1 | D27: M2 | E27: M3 | F27: M4 | G27: M5 | H27: M6 | I27: M7 | J27: M8 | K27: M9 | L27: M10 | M27: M11 | N27: M12 | O27: Year 1
A28: RTOs prevented per day at full scale | B28: ='Assumptions '!$B$98 -> 4808.3266 | C28: ='Assumptions '!$B$98 -> 4808.3266 | D28: ='Assumptions '!$B$98 -> 4808.3266 | E28: ='Assumptions '!$B$98 -> 4808.3266 | F28: ='Assumptions '!$B$98 -> 4808.3266 | G28: ='Assumptions '!$B$98 -> 4808.3266 | H28: ='Assumptions '!$B$98 -> 4808.3266 | I28: ='Assumptions '!$B$98 -> 4808.3266 | ... N28: ='Assumptions '!$B$98 -> 4808.3266
A29: Share of savings realised this month | B29: ='Payback Analysis '!C$14 -> 0 | C29: ='Payback Analysis '!D$14 -> 0.028630137 | D29: ='Payback Analysis '!E$14 -> 0.05 | E29: ='Payback Analysis '!F$14 -> 0.16452055 | F29: ='Payback Analysis '!G$14 -> 0.39315068 | G29: ='Payback Analysis '!H$14 -> 0.78630137 | H29: ='Payback Analysis '!I$14 -> 1 | I29: ='Payback Analysis '!J$14 -> 1 | ... N29: ='Payback Analysis '!O$14 -> 1
A30: Days in month | B30: =('Assumptions '!$B$9/12) -> 30.416667 | C30: =('Assumptions '!$B$9/12) -> 30.416667 | D30: =('Assumptions '!$B$9/12) -> 30.416667 | E30: =('Assumptions '!$B$9/12) -> 30.416667 | F30: =('Assumptions '!$B$9/12) -> 30.416667 | G30: =('Assumptions '!$B$9/12) -> 30.416667 | H30: =('Assumptions '!$B$9/12) -> 30.416667 | I30: =('Assumptions '!$B$9/12) -> 30.416667 | ... N30: =('Assumptions '!$B$9/12) -> 30.416667
A31: No. of RTOs prevented | B31: =B28*B29*B30 -> 0 | C31: =C28*C29*C30 -> 4187.2511 | D31: =D28*D29*D30 -> 7312.6634 | E31: =E28*E29*E30 -> 24061.668 | F31: =F28*F29*F30 -> 57499.572 | G31: =G28*G29*G30 -> 114999.14 | H31: =H28*H29*H30 -> 146253.27 | I31: =I28*I29*I30 -> 146253.27 | ... N31: =N28*N29*N30 -> 146253.27 | O31: =SUM(B31:N31) -> 1231833.2
A32: Saving per RTO prevented (reverse cost) | B32: ='Assumptions '!$B$100 -> 120 | C32: ='Assumptions '!$B$100 -> 120 | D32: ='Assumptions '!$B$100 -> 120 | E32: ='Assumptions '!$B$100 -> 120 | F32: ='Assumptions '!$B$100 -> 120 | G32: ='Assumptions '!$B$100 -> 120 | H32: ='Assumptions '!$B$100 -> 120 | I32: ='Assumptions '!$B$100 -> 120 | ... N32: ='Assumptions '!$B$100 -> 120
A33: Total Cost Avoided | B33: =B31*B32 -> 0 | C33: =C31*C32 -> 502470.13 | D33: =D31*D32 -> 877519.61 | E33: =E31*E32 -> 2887400.1 | F33: =F31*F32 -> 6899948.7 | G33: =G31*G32 -> 13799897 | H33: =H31*H32 -> 17550392 | I33: =I31*I32 -> 17550392 | ... N33: =N31*N32 -> 17550392 | O33: =SUM(B33:N33) -> 1.4781998e+08

Sheet Final WhatsApp
A1: Total Costs: WhatsApp confirmation
A2: Components | B2: M0 | C2: M1 | D2: M2 | E2: M3 | F2: M4 | G2: M5 | H2: M6 | I2: M7 | J2: M8 | K2: M9 | L2: M10 | M2: M11 | N2: M12 | O2: Year 1
A3: WhatsApp Messages | B3: =B14 -> 0 | C3: =C14 -> 921296.39 | D3: =D14 -> 921296.39 | E3: =E14 -> 4606482 | F3: =F14 -> 9212963.9 | G3: =G14 -> 18425928 | H3: =H14 -> 18425928 | I3: =I14 -> 18425928 | ... N3: =N14 -> 18425928 | O3: =SUM(B3:N3) -> 1.6306946e+08
A4: Service-provider Markup | B4: =B20 -> 0 | C4: =C20 -> 92129.639 | D4: =D20 -> 92129.639 | E4: =E20 -> 460648.2 | F4: =F20 -> 921296.39 | G4: =G20 -> 1842592.8 | H4: =H20 -> 1842592.8 | I4: =I20 -> 1842592.8 | ... N4: =N20 -> 1842592.8 | O4: =SUM(B4:N4) -> 16306946
A5: Total Costs | B5: =SUM(B3:B4) -> 0 | C5: =SUM(C3:C4) -> 1013426 | D5: =SUM(D3:D4) -> 1013426 | E5: =SUM(E3:E4) -> 5067130.2 | F5: =SUM(F3:F4) -> 10134260 | G5: =SUM(G3:G4) -> 20268521 | H5: =SUM(H3:H4) -> 20268521 | I5: =SUM(I3:I4) -> 20268521 | ... N5: =SUM(N3:N4) -> 20268521 | O5: =SUM(B5:N5) -> 1.7937641e+08
A7: MESSAGE COST
A8: Month | B8: M0 | C8: M1 | D8: M2 | E8: M3 | F8: M4 | G8: M5 | H8: M6 | I8: M7 | J8: M8 | K8: M9 | L8: M10 | M8: M11 | N8: M12 | O8: Year 1
A9: COD orders per day (live) | B9: ='Assumptions '!$B$88*'Payback Analysis '!C$13 -> 0 | C9: ='Assumptions '!$B$88*'Payback Analysis '!D$13 -> 168000 | D9: ='Assumptions '!$B$88*'Payback Analysis '!E$13 -> 168000 | E9: ='Assumptions '!$B$88*'Payback Analysis '!F$13 -> 840000 | F9: ='Assumptions '!$B$88*'Payback Analysis '!G$13 -> 1680000 | G9: ='Assumptions '!$B$88*'Payback Analysis '!H$13 -> 3360000 | H9: ='Assumptions '!$B$88*'Payback Analysis '!I$13 -> 3360000 | I9: ='Assumptions '!$B$88*'Payback Analysis '!J$13 -> 3360000 | ... N9: ='Assumptions '!$B$88*'Payback Analysis '!O$13 -> 3360000
A10: Billed messages per order (confirmation + acknowledgement) | B10: ='Assumptions '!$B$43+'Assumptions '!$B$24*'Assumptions '!$B$44 -> 1.5677638 | C10: ='Assumptions '!$B$43+'Assumptions '!$B$24*'Assumptions '!$B$44 -> 1.5677638 | D10: ='Assumptions '!$B$43+'Assumptions '!$B$24*'Assumptions '!$B$44 -> 1.5677638 | E10: ='Assumptions '!$B$43+'Assumptions '!$B$24*'Assumptions '!$B$44 -> 1.5677638 | F10: ='Assumptions '!$B$43+'Assumptions '!$B$24*'Assumptions '!$B$44 -> 1.5677638 | G10: ='Assumptions '!$B$43+'Assumptions '!$B$24*'Assumptions '!$B$44 -> 1.5677638 | H10: ='Assumptions '!$B$43+'Assumptions '!$B$24*'Assumptions '!$B$44 -> 1.5677638 | I10: ='Assumptions '!$B$43+'Assumptions '!$B$24*'Assumptions '!$B$44 -> 1.5677638 | ... N10: ='Assumptions '!$B$43+'Assumptions '!$B$24*'Assumptions '!$B$44 -> 1.5677638
A11: Days in month | B11: =('Assumptions '!$B$9/12) -> 30.416667 | C11: =('Assumptions '!$B$9/12) -> 30.416667 | D11: =('Assumptions '!$B$9/12) -> 30.416667 | E11: =('Assumptions '!$B$9/12) -> 30.416667 | F11: =('Assumptions '!$B$9/12) -> 30.416667 | G11: =('Assumptions '!$B$9/12) -> 30.416667 | H11: =('Assumptions '!$B$9/12) -> 30.416667 | I11: =('Assumptions '!$B$9/12) -> 30.416667 | ... N11: =('Assumptions '!$B$9/12) -> 30.416667
A12: No. of messages | B12: =B9*B10*B11 -> 0 | C12: =C9*C10*C11 -> 8011273 | D12: =D9*D10*D11 -> 8011273 | E12: =E9*E10*E11 -> 40056365 | F12: =F9*F10*F11 -> 80112730 | G12: =G9*G10*G11 -> 1.6022546e+08 | H12: =H9*H10*H11 -> 1.6022546e+08 | I12: =I9*I10*I11 -> 1.6022546e+08 | ... N12: =N9*N10*N11 -> 1.6022546e+08 | O12: =SUM(B12:N12) -> 1417995319
A13: Cost per message (Meta utility rate) | B13: ='Assumptions '!$B$42 -> 0.115 | C13: ='Assumptions '!$B$42 -> 0.115 | D13: ='Assumptions '!$B$42 -> 0.115 | E13: ='Assumptions '!$B$42 -> 0.115 | F13: ='Assumptions '!$B$42 -> 0.115 | G13: ='Assumptions '!$B$42 -> 0.115 | H13: ='Assumptions '!$B$42 -> 0.115 | I13: ='Assumptions '!$B$42 -> 0.115 | ... N13: ='Assumptions '!$B$42 -> 0.115
A14: Total Cost | B14: =B12*B13 -> 0 | C14: =C12*C13 -> 921296.39 | D14: =D12*D13 -> 921296.39 | E14: =E12*E13 -> 4606482 | F14: =F12*F13 -> 9212963.9 | G14: =G12*G13 -> 18425928 | H14: =H12*H13 -> 18425928 | I14: =I12*I13 -> 18425928 | ... N14: =N12*N13 -> 18425928 | O14: =SUM(B14:N14) -> 1.6306946e+08
A16: SERVICE-PROVIDER (BSP) MARKUP
A17: Month | B17: M0 | C17: M1 | D17: M2 | E17: M3 | F17: M4 | G17: M5 | H17: M6 | I17: M7 | J17: M8 | K17: M9 | L17: M10 | M17: M11 | N17: M12 | O17: Year 1
A18: Message cost | B18: =B14 -> 0 | C18: =C14 -> 921296.39 | D18: =D14 -> 921296.39 | E18: =E14 -> 4606482 | F18: =F14 -> 9212963.9 | G18: =G14 -> 18425928 | H18: =H14 -> 18425928 | I18: =I14 -> 18425928 | ... N18: =N14 -> 18425928 | O18: =SUM(B18:N18) -> 1.6306946e+08
A19: Markup | B19: ='Assumptions '!$B$45 -> 0.1 | C19: ='Assumptions '!$B$45 -> 0.1 | D19: ='Assumptions '!$B$45 -> 0.1 | E19: ='Assumptions '!$B$45 -> 0.1 | F19: ='Assumptions '!$B$45 -> 0.1 | G19: ='Assumptions '!$B$45 -> 0.1 | H19: ='Assumptions '!$B$45 -> 0.1 | I19: ='Assumptions '!$B$45 -> 0.1 | ... N19: ='Assumptions '!$B$45 -> 0.1
A20: Total Cost | B20: =B18*B19 -> 0 | C20: =C18*C19 -> 92129.639 | D20: =D18*D19 -> 92129.639 | E20: =E18*E19 -> 460648.2 | F20: =F18*F19 -> 921296.39 | G20: =G18*G19 -> 1842592.8 | H20: =H18*H19 -> 1842592.8 | I20: =I18*I19 -> 1842592.8 | ... N20: =N18*N19 -> 1842592.8 | O20: =SUM(B20:N20) -> 16306946

Sheet Final SMS
A1: Total Costs: SMS to WhatsApp non-responders
A2: Components | B2: M0 | C2: M1 | D2: M2 | E2: M3 | F2: M4 | G2: M5 | H2: M6 | I2: M7 | J2: M8 | K2: M9 | L2: M10 | M2: M11 | N2: M12 | O2: Year 1
A3: SMS Sent | B3: =B15 -> 0 | C3: =C15 -> 397570.86 | D3: =D15 -> 397570.86 | E3: =E15 -> 1987854.3 | F3: =F15 -> 3975708.6 | G3: =G15 -> 7951417.2 | H3: =H15 -> 7951417.2 | I3: =I15 -> 7951417.2 | ... N3: =N15 -> 7951417.2 | O3: =SUM(B3:N3) -> 70370042
A4: SMS Replies Received | B4: =B23 -> 0 | C4: =C23 -> 26504.724 | D4: =D23 -> 26504.724 | E4: =E23 -> 132523.62 | F4: =F23 -> 265047.24 | G4: =G23 -> 530094.48 | H4: =H23 -> 530094.48 | I4: =I23 -> 530094.48 | ... N4: =N23 -> 530094.48 | O4: =SUM(B4:N4) -> 4691336.2
A5: Two-way Number Rental | B5: =B27 -> 0 | C5: =C27 -> 8500 | D5: =D27 -> 8500 | E5: =E27 -> 8500 | F5: =F27 -> 8500 | G5: =G27 -> 8500 | H5: =H27 -> 8500 | I5: =I27 -> 8500 | ... N5: =N27 -> 8500 | O5: =SUM(B5:N5) -> 102000
A6: Two-way Number Setup | B6: =B28 -> 50000 | C6: =C28 -> 0 | D6: =D28 -> 0 | E6: =E28 -> 0 | F6: =F28 -> 0 | G6: =G28 -> 0 | H6: =H28 -> 0 | I6: =I28 -> 0 | ... N6: =N28 -> 0 | O6: =SUM(B6:N6) -> 50000
A7: Total Costs | B7: =SUM(B3:B6) -> 50000 | C7: =SUM(C3:C6) -> 432575.59 | D7: =SUM(D3:D6) -> 432575.59 | E7: =SUM(E3:E6) -> 2128877.9 | F7: =SUM(F3:F6) -> 4249255.9 | G7: =SUM(G3:G6) -> 8490011.7 | H7: =SUM(H3:H6) -> 8490011.7 | I7: =SUM(I3:I6) -> 8490011.7 | ... N7: =SUM(N3:N6) -> 8490011.7 | O7: =SUM(B7:N7) -> 75213379
A9: SMS SENT
A10: Month | B10: M0 | C10: M1 | D10: M2 | E10: M3 | F10: M4 | G10: M5 | H10: M6 | I10: M7 | J10: M8 | K10: M9 | L10: M10 | M10: M11 | N10: M12 | O10: Year 1
A11: SMS sent per day (live) | B11: ='Assumptions '!$B$90*'Payback Analysis '!C$13 -> 0 | C11: ='Assumptions '!$B$90*'Payback Analysis '!D$13 -> 72615.682 | D11: ='Assumptions '!$B$90*'Payback Analysis '!E$13 -> 72615.682 | E11: ='Assumptions '!$B$90*'Payback Analysis '!F$13 -> 363078.41 | F11: ='Assumptions '!$B$90*'Payback Analysis '!G$13 -> 726156.82 | G11: ='Assumptions '!$B$90*'Payback Analysis '!H$13 -> 1452313.6 | H11: ='Assumptions '!$B$90*'Payback Analysis '!I$13 -> 1452313.6 | I11: ='Assumptions '!$B$90*'Payback Analysis '!J$13 -> 1452313.6 | ... N11: ='Assumptions '!$B$90*'Payback Analysis '!O$13 -> 1452313.6
A12: Days in month | B12: =('Assumptions '!$B$9/12) -> 30.416667 | C12: =('Assumptions '!$B$9/12) -> 30.416667 | D12: =('Assumptions '!$B$9/12) -> 30.416667 | E12: =('Assumptions '!$B$9/12) -> 30.416667 | F12: =('Assumptions '!$B$9/12) -> 30.416667 | G12: =('Assumptions '!$B$9/12) -> 30.416667 | H12: =('Assumptions '!$B$9/12) -> 30.416667 | I12: =('Assumptions '!$B$9/12) -> 30.416667 | ... N12: =('Assumptions '!$B$9/12) -> 30.416667
A13: No. of SMS | B13: =B11*B12 -> 0 | C13: =C11*C12 -> 2208727 | D13: =D11*D12 -> 2208727 | E13: =E11*E12 -> 11043635 | F13: =F11*F12 -> 22087270 | G13: =G11*G12 -> 44174540 | H13: =H11*H12 -> 44174540 | I13: =I11*I12 -> 44174540 | ... N13: =N11*N12 -> 44174540 | O13: =SUM(B13:N13) -> 3.9094468e+08
A14: Cost per SMS (DLT transactional) | B14: ='Assumptions '!$B$46 -> 0.18 | C14: ='Assumptions '!$B$46 -> 0.18 | D14: ='Assumptions '!$B$46 -> 0.18 | E14: ='Assumptions '!$B$46 -> 0.18 | F14: ='Assumptions '!$B$46 -> 0.18 | G14: ='Assumptions '!$B$46 -> 0.18 | H14: ='Assumptions '!$B$46 -> 0.18 | I14: ='Assumptions '!$B$46 -> 0.18 | ... N14: ='Assumptions '!$B$46 -> 0.18
A15: Total Cost | B15: =B13*B14 -> 0 | C15: =C13*C14 -> 397570.86 | D15: =D13*D14 -> 397570.86 | E15: =E13*E14 -> 1987854.3 | F15: =F13*F14 -> 3975708.6 | G15: =G13*G14 -> 7951417.2 | H15: =H13*H14 -> 7951417.2 | I15: =I13*I14 -> 7951417.2 | ... N15: =N13*N14 -> 7951417.2 | O15: =SUM(B15:N15) -> 70370042
A17: SMS REPLIES RECEIVED
A18: Month | B18: M0 | C18: M1 | D18: M2 | E18: M3 | F18: M4 | G18: M5 | H18: M6 | I18: M7 | J18: M8 | K18: M9 | L18: M10 | M18: M11 | N18: M12 | O18: Year 1
A19: Replies per day (live) | B19: ='Assumptions '!$B$91*'Payback Analysis '!C$13 -> 0 | C19: ='Assumptions '!$B$91*'Payback Analysis '!D$13 -> 10892.352 | D19: ='Assumptions '!$B$91*'Payback Analysis '!E$13 -> 10892.352 | E19: ='Assumptions '!$B$91*'Payback Analysis '!F$13 -> 54461.762 | F19: ='Assumptions '!$B$91*'Payback Analysis '!G$13 -> 108923.52 | G19: ='Assumptions '!$B$91*'Payback Analysis '!H$13 -> 217847.05 | H19: ='Assumptions '!$B$91*'Payback Analysis '!I$13 -> 217847.05 | I19: ='Assumptions '!$B$91*'Payback Analysis '!J$13 -> 217847.05 | ... N19: ='Assumptions '!$B$91*'Payback Analysis '!O$13 -> 217847.05
A20: Days in month | B20: =('Assumptions '!$B$9/12) -> 30.416667 | C20: =('Assumptions '!$B$9/12) -> 30.416667 | D20: =('Assumptions '!$B$9/12) -> 30.416667 | E20: =('Assumptions '!$B$9/12) -> 30.416667 | F20: =('Assumptions '!$B$9/12) -> 30.416667 | G20: =('Assumptions '!$B$9/12) -> 30.416667 | H20: =('Assumptions '!$B$9/12) -> 30.416667 | I20: =('Assumptions '!$B$9/12) -> 30.416667 | ... N20: =('Assumptions '!$B$9/12) -> 30.416667
A21: No. of replies | B21: =B19*B20 -> 0 | C21: =C19*C20 -> 331309.05 | D21: =D19*D20 -> 331309.05 | E21: =E19*E20 -> 1656545.3 | F21: =F19*F20 -> 3313090.5 | G21: =G19*G20 -> 6626181 | H21: =H19*H20 -> 6626181 | I21: =I19*I20 -> 6626181 | ... N21: =N19*N20 -> 6626181 | O21: =SUM(B21:N21) -> 58641702
A22: Cost per incoming SMS (long code) | B22: ='Assumptions '!$B$47 -> 0.08 | C22: ='Assumptions '!$B$47 -> 0.08 | D22: ='Assumptions '!$B$47 -> 0.08 | E22: ='Assumptions '!$B$47 -> 0.08 | F22: ='Assumptions '!$B$47 -> 0.08 | G22: ='Assumptions '!$B$47 -> 0.08 | H22: ='Assumptions '!$B$47 -> 0.08 | I22: ='Assumptions '!$B$47 -> 0.08 | ... N22: ='Assumptions '!$B$47 -> 0.08
A23: Total Cost | B23: =B21*B22 -> 0 | C23: =C21*C22 -> 26504.724 | D23: =D21*D22 -> 26504.724 | E23: =E21*E22 -> 132523.62 | F23: =F21*F22 -> 265047.24 | G23: =G21*G22 -> 530094.48 | H23: =H21*H22 -> 530094.48 | I23: =I21*I22 -> 530094.48 | ... N23: =N21*N22 -> 530094.48 | O23: =SUM(B23:N23) -> 4691336.2
A25: TWO-WAY SMS NUMBER (LONG CODE)
A26: Month | B26: M0 | C26: M1 | D26: M2 | E26: M3 | F26: M4 | G26: M5 | H26: M6 | I26: M7 | J26: M8 | K26: M9 | L26: M10 | M26: M11 | N26: M12 | O26: Year 1
A27: Monthly rental (from M1) | B27: =IF(0>=1,'Assumptions '!$B$48,0) -> 0 | C27: =IF(1>=1,'Assumptions '!$B$48,0) -> 8500 | D27: =IF(2>=1,'Assumptions '!$B$48,0) -> 8500 | E27: =IF(3>=1,'Assumptions '!$B$48,0) -> 8500 | F27: =IF(4>=1,'Assumptions '!$B$48,0) -> 8500 | G27: =IF(5>=1,'Assumptions '!$B$48,0) -> 8500 | H27: =IF(6>=1,'Assumptions '!$B$48,0) -> 8500 | I27: =IF(7>=1,'Assumptions '!$B$48,0) -> 8500 | J27: =IF(8>=1,'Assumptions '!$B$48,0) -> 8500 | K27: =IF(9>=1,'Assumptions '!$B$48,0) -> 8500 | L27: =IF(10>=1,'Assumptions '!$B$48,0) -> 8500 | M27: =IF(11>=1,'Assumptions '!$B$48,0) -> 8500 | N27: =IF(12>=1,'Assumptions '!$B$48,0) -> 8500 | O27: =SUM(B27:N27) -> 102000
A28: One-time setup (M0) | B28: ='Assumptions '!$B$49 -> 50000 | C28: 0 | D28: 0 | E28: 0 | F28: 0 | G28: 0 | H28: 0 | I28: 0 | J28: 0 | K28: 0 | L28: 0 | M28: 0 | N28: 0 | O28: =SUM(B28:N28) -> 50000

Sheet Final IVR
A1: Total Costs: IVR call (high-risk orders still silent)
A2: Components | B2: M0 | C2: M1 | D2: M2 | E2: M3 | F2: M4 | G2: M5 | H2: M6 | I2: M7 | J2: M8 | K2: M9 | L2: M10 | M2: M11 | N2: M12 | O2: Year 1
A3: Call Charges | B3: =B14 -> 0 | C3: =C14 -> 51366.155 | D3: =D14 -> 51366.155 | E3: =E14 -> 256830.78 | F3: =F14 -> 513661.55 | G3: =G14 -> 1027323.1 | H3: =H14 -> 1027323.1 | I3: =I14 -> 1027323.1 | ... N3: =N14 -> 1027323.1 | O3: =SUM(B3:N3) -> 9091809.5
A4: Phone Line Rental | B4: =B20 -> 0 | C4: =C20 -> 5000 | D4: =D20 -> 5000 | E4: =E20 -> 25000 | F4: =F20 -> 50000 | G4: =G20 -> 100000 | H4: =H20 -> 100000 | I4: =I20 -> 100000 | ... N4: =N20 -> 100000 | O4: =SUM(B4:N4) -> 885000
A5: Total Costs | B5: =SUM(B3:B4) -> 0 | C5: =SUM(C3:C4) -> 56366.155 | D5: =SUM(D3:D4) -> 56366.155 | E5: =SUM(E3:E4) -> 281830.78 | F5: =SUM(F3:F4) -> 563661.55 | G5: =SUM(G3:G4) -> 1127323.1 | H5: =SUM(H3:H4) -> 1127323.1 | I5: =SUM(I3:I4) -> 1127323.1 | ... N5: =SUM(N3:N4) -> 1127323.1 | O5: =SUM(B5:N5) -> 9976809.5
A7: CALL CHARGES
A8: Month | B8: M0 | C8: M1 | D8: M2 | E8: M3 | F8: M4 | G8: M5 | H8: M6 | I8: M7 | J8: M8 | K8: M9 | L8: M10 | M8: M11 | N8: M12 | O8: Year 1
A9: Orders sent to IVR per day (live) | B9: ='Assumptions '!$B$92*'Payback Analysis '!C$13 -> 0 | C9: ='Assumptions '!$B$92*'Payback Analysis '!D$13 -> 12344.666 | D9: ='Assumptions '!$B$92*'Payback Analysis '!E$13 -> 12344.666 | E9: ='Assumptions '!$B$92*'Payback Analysis '!F$13 -> 61723.33 | F9: ='Assumptions '!$B$92*'Payback Analysis '!G$13 -> 123446.66 | G9: ='Assumptions '!$B$92*'Payback Analysis '!H$13 -> 246893.32 | H9: ='Assumptions '!$B$92*'Payback Analysis '!I$13 -> 246893.32 | I9: ='Assumptions '!$B$92*'Payback Analysis '!J$13 -> 246893.32 | ... N9: ='Assumptions '!$B$92*'Payback Analysis '!O$13 -> 246893.32
A10: Reach within 2 attempts | B10: ='Assumptions '!$B$93 -> 0.36 | C10: ='Assumptions '!$B$93 -> 0.36 | D10: ='Assumptions '!$B$93 -> 0.36 | E10: ='Assumptions '!$B$93 -> 0.36 | F10: ='Assumptions '!$B$93 -> 0.36 | G10: ='Assumptions '!$B$93 -> 0.36 | H10: ='Assumptions '!$B$93 -> 0.36 | I10: ='Assumptions '!$B$93 -> 0.36 | ... N10: ='Assumptions '!$B$93 -> 0.36
A11: Days in month | B11: =('Assumptions '!$B$9/12) -> 30.416667 | C11: =('Assumptions '!$B$9/12) -> 30.416667 | D11: =('Assumptions '!$B$9/12) -> 30.416667 | E11: =('Assumptions '!$B$9/12) -> 30.416667 | F11: =('Assumptions '!$B$9/12) -> 30.416667 | G11: =('Assumptions '!$B$9/12) -> 30.416667 | H11: =('Assumptions '!$B$9/12) -> 30.416667 | I11: =('Assumptions '!$B$9/12) -> 30.416667 | ... N11: =('Assumptions '!$B$9/12) -> 30.416667
A12: No. of answered (billed) calls | B12: =B9*B10*B11 -> 0 | C12: =C9*C10*C11 -> 135174.09 | D12: =D9*D10*D11 -> 135174.09 | E12: =E9*E10*E11 -> 675870.46 | F12: =F9*F10*F11 -> 1351740.9 | G12: =G9*G10*G11 -> 2703481.9 | H12: =H9*H10*H11 -> 2703481.9 | I12: =I9*I10*I11 -> 2703481.9 | ... N12: =N9*N10*N11 -> 2703481.9 | O12: =SUM(B12:N12) -> 23925814
A13: Cost per answered call (60 s, Plivo) | B13: ='Assumptions '!$B$102 -> 0.38 | C13: ='Assumptions '!$B$102 -> 0.38 | D13: ='Assumptions '!$B$102 -> 0.38 | E13: ='Assumptions '!$B$102 -> 0.38 | F13: ='Assumptions '!$B$102 -> 0.38 | G13: ='Assumptions '!$B$102 -> 0.38 | H13: ='Assumptions '!$B$102 -> 0.38 | I13: ='Assumptions '!$B$102 -> 0.38 | ... N13: ='Assumptions '!$B$102 -> 0.38
A14: Total Cost | B14: =B12*B13 -> 0 | C14: =C12*C13 -> 51366.155 | D14: =D12*D13 -> 51366.155 | E14: =E12*E13 -> 256830.78 | F14: =F12*F13 -> 513661.55 | G14: =G12*G13 -> 1027323.1 | H14: =H12*H13 -> 1027323.1 | I14: =I12*I13 -> 1027323.1 | ... N14: =N12*N13 -> 1027323.1 | O14: =SUM(B14:N14) -> 9091809.5
A16: PHONE LINES
A17: Month | B17: M0 | C17: M1 | D17: M2 | E17: M3 | F17: M4 | G17: M5 | H17: M6 | I17: M7 | J17: M8 | K17: M9 | L17: M10 | M17: M11 | N17: M12 | O17: Year 1
A18: No. of lines (scaled with rollout) | B18: ='Assumptions '!$B$53*'Payback Analysis '!C$13 -> 0 | C18: ='Assumptions '!$B$53*'Payback Analysis '!D$13 -> 25 | D18: ='Assumptions '!$B$53*'Payback Analysis '!E$13 -> 25 | E18: ='Assumptions '!$B$53*'Payback Analysis '!F$13 -> 125 | F18: ='Assumptions '!$B$53*'Payback Analysis '!G$13 -> 250 | G18: ='Assumptions '!$B$53*'Payback Analysis '!H$13 -> 500 | H18: ='Assumptions '!$B$53*'Payback Analysis '!I$13 -> 500 | I18: ='Assumptions '!$B$53*'Payback Analysis '!J$13 -> 500 | ... N18: ='Assumptions '!$B$53*'Payback Analysis '!O$13 -> 500
A19: Rental per line per month | B19: ='Assumptions '!$B$54 -> 200 | C19: ='Assumptions '!$B$54 -> 200 | D19: ='Assumptions '!$B$54 -> 200 | E19: ='Assumptions '!$B$54 -> 200 | F19: ='Assumptions '!$B$54 -> 200 | G19: ='Assumptions '!$B$54 -> 200 | H19: ='Assumptions '!$B$54 -> 200 | I19: ='Assumptions '!$B$54 -> 200 | ... N19: ='Assumptions '!$B$54 -> 200
A20: Total Cost | B20: =B18*B19 -> 0 | C20: =C18*C19 -> 5000 | D20: =D18*D19 -> 5000 | E20: =E18*E19 -> 25000 | F20: =F18*F19 -> 50000 | G20: =G18*G19 -> 100000 | H20: =H18*H19 -> 100000 | I20: =I18*I19 -> 100000 | ... N20: =N18*N19 -> 100000 | O20: =SUM(B20:N20) -> 885000

Sheet Final Shared Costs
A1: Total Costs: shared platform, customer impact and setup
A2: Components | B2: M0 | C2: M1 | D2: M2 | E2: M3 | F2: M4 | G2: M5 | H2: M6 | I2: M7 | J2: M8 | K2: M9 | L2: M10 | M2: M11 | N2: M12 | O2: Year 1
A3: Cloud Servers | B3: =B36 -> 0 | C3: =C36 -> 46800 | D3: =D36 -> 46800 | E3: =E36 -> 46800 | F3: =F36 -> 46800 | G3: =G36 -> 46800 | H3: =H36 -> 46800 | I3: =I36 -> 46800 | ... N3: =N36 -> 46800 | O3: =SUM(B3:N3) -> 561600
A4: Risk-score Database | B4: =B37 -> 0 | C4: =C37 -> 30800 | D4: =D37 -> 30800 | E4: =E37 -> 30800 | F4: =F37 -> 30800 | G4: =G37 -> 30800 | H4: =H37 -> 30800 | I4: =I37 -> 30800 | ... N4: =N37 -> 30800 | O4: =SUM(B4:N4) -> 369600
A5: Data Storage | B5: =B38 -> 0 | C5: =C38 -> 328.59146 | D5: =D38 -> 328.59146 | E5: =E38 -> 1642.9573 | F5: =F38 -> 3285.9146 | G5: =G38 -> 6571.8292 | H5: =H38 -> 6571.8292 | I5: =I38 -> 6571.8292 | ... N5: =N38 -> 6571.8292 | O5: =SUM(B5:N5) -> 58160.688
A6: Logging & Dashboards | B6: =B39 -> 0 | C6: =C39 -> 23400 | D6: =D39 -> 23400 | E6: =E39 -> 23400 | F6: =F39 -> 23400 | G6: =G39 -> 23400 | H6: =H39 -> 23400 | I6: =I39 -> 23400 | ... N6: =N39 -> 23400 | O6: =SUM(B6:N6) -> 280800
A7: Customer-support Contacts | B7: =B24 -> 0 | C7: =C24 -> 459900 | D7: =D24 -> 459900 | E7: =E24 -> 2299500 | F7: =F24 -> 4599000 | G7: =G24 -> 9198000 | H7: =H24 -> 9198000 | I7: =I24 -> 9198000 | ... N7: =N24 -> 9198000 | O7: =SUM(B7:N7) -> 81402300
A8: Genuine Orders Lost | B8: =B32 -> 0 | C8: =C32 -> 249074.9 | D8: =D32 -> 249074.9 | E8: =E32 -> 1245374.5 | F8: =F32 -> 2490749 | G8: =G32 -> 4981498 | H8: =H32 -> 4981498 | I8: =I32 -> 4981498 | ... N8: =N32 -> 4981498 | O8: =SUM(B8:N8) -> 44086257
A9: DLT Registration | B9: =B43 -> 23600 | C9: =C43 -> 0 | D9: =D43 -> 0 | E9: =E43 -> 0 | F9: =F43 -> 0 | G9: =G43 -> 0 | H9: =H43 -> 0 | I9: =I43 -> 0 | ... N9: =N43 -> 0 | O9: =SUM(B9:N9) -> 23600
A10: Script Translation | B10: =B44 -> 50000 | C10: =C44 -> 0 | D10: =D44 -> 0 | E10: =E44 -> 0 | F10: =F44 -> 0 | G10: =G44 -> 0 | H10: =H44 -> 0 | I10: =I44 -> 0 | ... N10: =N44 -> 0 | O10: =SUM(B10:N10) -> 50000
A11: Legal Review | B11: =B45 -> 500000 | C11: =C45 -> 0 | D11: =D45 -> 0 | E11: =E45 -> 0 | F11: =F45 -> 0 | G11: =G45 -> 0 | H11: =H45 -> 0 | I11: =I45 -> 0 | ... N11: =N45 -> 0 | O11: =SUM(B11:N11) -> 500000
A12: Integration & Testing | B12: =B46 -> 50000 | C12: =C46 -> 0 | D12: =D46 -> 0 | E12: =E46 -> 0 | F12: =F46 -> 0 | G12: =G46 -> 0 | H12: =H46 -> 0 | I12: =I46 -> 0 | ... N12: =N46 -> 0 | O12: =SUM(B12:N12) -> 50000
A13: Compliance Audit | B13: =B47 -> 0 | C13: =C47 -> 0 | D13: =D47 -> 0 | E13: =E47 -> 0 | F13: =F47 -> 0 | G13: =G47 -> 0 | H13: =H47 -> 0 | I13: =I47 -> 0 | ... N13: =N47 -> 200000 | O13: =SUM(B13:N13) -> 200000
A14: Contingency (10% of all costs) | B14: ='Assumptions '!$B$79*(SUM(B3:B13)+'Final WhatsApp'!B5+'Final SMS'!B7+'Final IVR'!B5) -> 67360 | C14: ='Assumptions '!$B$79*(SUM(C3:C13)+'Final WhatsApp'!C5+'Final SMS'!C7+'Final IVR'!C5) -> 231267.13 | D14: ='Assumptions '!$B$79*(SUM(D3:D13)+'Final WhatsApp'!D5+'Final SMS'!D7+'Final IVR'!D5) -> 231267.13 | E14: ='Assumptions '!$B$79*(SUM(E3:E13)+'Final WhatsApp'!E5+'Final SMS'!E7+'Final IVR'!E5) -> 1112535.6 | F14: ='Assumptions '!$B$79*(SUM(F3:F13)+'Final WhatsApp'!F5+'Final SMS'!F7+'Final IVR'!F5) -> 2214121.3 | G14: ='Assumptions '!$B$79*(SUM(G3:G13)+'Final WhatsApp'!G5+'Final SMS'!G7+'Final IVR'!G5) -> 4417292.5 | H14: ='Assumptions '!$B$79*(SUM(H3:H13)+'Final WhatsApp'!H5+'Final SMS'!H7+'Final IVR'!H5) -> 4417292.5 | I14: ='Assumptions '!$B$79*(SUM(I3:I13)+'Final WhatsApp'!I5+'Final SMS'!I7+'Final IVR'!I5) -> 4417292.5 | ... N14: ='Assumptions '!$B$79*(SUM(N3:N13)+'Final WhatsApp'!N5+'Final SMS'!N7+'Final IVR'!N5) -> 4437292.5 | O14: =SUM(B14:N14) -> 39214891
A15: Total Costs | B15: =SUM(B3:B14) -> 690960 | C15: =SUM(C3:C14) -> 1041570.6 | D15: =SUM(D3:D14) -> 1041570.6 | E15: =SUM(E3:E14) -> 4760053.1 | F15: =SUM(F3:F14) -> 9408156.2 | G15: =SUM(G3:G14) -> 18704362 | H15: =SUM(H3:H14) -> 18704362 | I15: =SUM(I3:I14) -> 18704362 | ... N15: =SUM(N3:N14) -> 18924362 | O15: =SUM(B15:N15) -> 166797209
A17: CUSTOMER-SUPPORT CONTACTS
A18: Month | B18: M0 | C18: M1 | D18: M2 | E18: M3 | F18: M4 | G18: M5 | H18: M6 | I18: M7 | J18: M8 | K18: M9 | L18: M10 | M18: M11 | N18: M12 | O18: Year 1
A19: High-risk COD orders per day (live) | B19: ='Assumptions '!$B$89*'Payback Analysis '!C$13 -> 0 | C19: ='Assumptions '!$B$89*'Payback Analysis '!D$13 -> 33600 | D19: ='Assumptions '!$B$89*'Payback Analysis '!E$13 -> 33600 | E19: ='Assumptions '!$B$89*'Payback Analysis '!F$13 -> 168000 | F19: ='Assumptions '!$B$89*'Payback Analysis '!G$13 -> 336000 | G19: ='Assumptions '!$B$89*'Payback Analysis '!H$13 -> 672000 | H19: ='Assumptions '!$B$89*'Payback Analysis '!I$13 -> 672000 | I19: ='Assumptions '!$B$89*'Payback Analysis '!J$13 -> 672000 | ... N19: ='Assumptions '!$B$89*'Payback Analysis '!O$13 -> 672000
A20: Share who contact support | B20: ='Assumptions '!$B$37 -> 0.03 | C20: ='Assumptions '!$B$37 -> 0.03 | D20: ='Assumptions '!$B$37 -> 0.03 | E20: ='Assumptions '!$B$37 -> 0.03 | F20: ='Assumptions '!$B$37 -> 0.03 | G20: ='Assumptions '!$B$37 -> 0.03 | H20: ='Assumptions '!$B$37 -> 0.03 | I20: ='Assumptions '!$B$37 -> 0.03 | ... N20: ='Assumptions '!$B$37 -> 0.03
A21: Days in month | B21: =('Assumptions '!$B$9/12) -> 30.416667 | C21: =('Assumptions '!$B$9/12) -> 30.416667 | D21: =('Assumptions '!$B$9/12) -> 30.416667 | E21: =('Assumptions '!$B$9/12) -> 30.416667 | F21: =('Assumptions '!$B$9/12) -> 30.416667 | G21: =('Assumptions '!$B$9/12) -> 30.416667 | H21: =('Assumptions '!$B$9/12) -> 30.416667 | I21: =('Assumptions '!$B$9/12) -> 30.416667 | ... N21: =('Assumptions '!$B$9/12) -> 30.416667
A22: No. of contacts | B22: =B19*B20*B21 -> 0 | C22: =C19*C20*C21 -> 30660 | D22: =D19*D20*D21 -> 30660 | E22: =E19*E20*E21 -> 153300 | F22: =F19*F20*F21 -> 306600 | G22: =G19*G20*G21 -> 613200 | H22: =H19*H20*H21 -> 613200 | I22: =I19*I20*I21 -> 613200 | ... N22: =N19*N20*N21 -> 613200 | O22: =SUM(B22:N22) -> 5426820
A23: Cost per contact | B23: ='Assumptions '!$B$38 -> 15 | C23: ='Assumptions '!$B$38 -> 15 | D23: ='Assumptions '!$B$38 -> 15 | E23: ='Assumptions '!$B$38 -> 15 | F23: ='Assumptions '!$B$38 -> 15 | G23: ='Assumptions '!$B$38 -> 15 | H23: ='Assumptions '!$B$38 -> 15 | I23: ='Assumptions '!$B$38 -> 15 | ... N23: ='Assumptions '!$B$38 -> 15
A24: Total Cost | B24: =B22*B23 -> 0 | C24: =C22*C23 -> 459900 | D24: =D22*D23 -> 459900 | E24: =E22*E23 -> 2299500 | F24: =F22*F23 -> 4599000 | G24: =G22*G23 -> 9198000 | H24: =H22*H23 -> 9198000 | I24: =I22*I23 -> 9198000 | ... N24: =N22*N23 -> 9198000 | O24: =SUM(B24:N24) -> 81402300
A26: GENUINE ORDERS LOST
A27: Month | B27: M0 | C27: M1 | D27: M2 | E27: M3 | F27: M4 | G27: M5 | H27: M6 | I27: M7 | J27: M8 | K27: M9 | L27: M10 | M27: M11 | N27: M12 | O27: Year 1
A28: Genuine orders lost per day (live) | B28: ='Assumptions '!$B$103*'Payback Analysis '!C$13 -> 0 | C28: ='Assumptions '!$B$103*'Payback Analysis '!D$13 -> 741.73585 | D28: ='Assumptions '!$B$103*'Payback Analysis '!E$13 -> 741.73585 | E28: ='Assumptions '!$B$103*'Payback Analysis '!F$13 -> 3708.6792 | F28: ='Assumptions '!$B$103*'Payback Analysis '!G$13 -> 7417.3585 | G28: ='Assumptions '!$B$103*'Payback Analysis '!H$13 -> 14834.717 | H28: ='Assumptions '!$B$103*'Payback Analysis '!I$13 -> 14834.717 | I28: ='Assumptions '!$B$103*'Payback Analysis '!J$13 -> 14834.717 | ... N28: ='Assumptions '!$B$103*'Payback Analysis '!O$13 -> 14834.717
A29: Days in month | B29: =('Assumptions '!$B$9/12) -> 30.416667 | C29: =('Assumptions '!$B$9/12) -> 30.416667 | D29: =('Assumptions '!$B$9/12) -> 30.416667 | E29: =('Assumptions '!$B$9/12) -> 30.416667 | F29: =('Assumptions '!$B$9/12) -> 30.416667 | G29: =('Assumptions '!$B$9/12) -> 30.416667 | H29: =('Assumptions '!$B$9/12) -> 30.416667 | I29: =('Assumptions '!$B$9/12) -> 30.416667 | ... N29: =('Assumptions '!$B$9/12) -> 30.416667
A30: No. of orders lost | B30: =B28*B29 -> 0 | C30: =C28*C29 -> 22561.132 | D30: =D28*D29 -> 22561.132 | E30: =E28*E29 -> 112805.66 | F30: =F28*F29 -> 225611.32 | G30: =G28*G29 -> 451222.64 | H30: =H28*H29 -> 451222.64 | I30: =I28*I29 -> 451222.64 | ... N30: =N28*N29 -> 451222.64 | O30: =SUM(B30:N30) -> 3993320.4
A31: Contribution lost per order | B31: ='Assumptions '!$B$34 -> 11.04 | C31: ='Assumptions '!$B$34 -> 11.04 | D31: ='Assumptions '!$B$34 -> 11.04 | E31: ='Assumptions '!$B$34 -> 11.04 | F31: ='Assumptions '!$B$34 -> 11.04 | G31: ='Assumptions '!$B$34 -> 11.04 | H31: ='Assumptions '!$B$34 -> 11.04 | I31: ='Assumptions '!$B$34 -> 11.04 | ... N31: ='Assumptions '!$B$34 -> 11.04
A32: Total Cost | B32: =B30*B31 -> 0 | C32: =C30*C31 -> 249074.9 | D32: =D30*D31 -> 249074.9 | E32: =E30*E31 -> 1245374.5 | F32: =F30*F31 -> 2490749 | G32: =G30*G31 -> 4981498 | H32: =H30*H31 -> 4981498 | I32: =I30*I31 -> 4981498 | ... N32: =N30*N31 -> 4981498 | O32: =SUM(B32:N32) -> 44086257
A34: PLATFORM (from M1)
A35: Month | B35: M0 | C35: M1 | D35: M2 | E35: M3 | F35: M4 | G35: M5 | H35: M6 | I35: M7 | J35: M8 | K35: M9 | L35: M10 | M35: M11 | N35: M12 | O35: Year 1
A36: Cloud servers (no. x monthly price) | B36: =IF(0>=1,'Assumptions '!$B$61*'Assumptions '!$B$60,0) -> 0 | C36: =IF(1>=1,'Assumptions '!$B$61*'Assumptions '!$B$60,0) -> 46800 | D36: =IF(2>=1,'Assumptions '!$B$61*'Assumptions '!$B$60,0) -> 46800 | E36: =IF(3>=1,'Assumptions '!$B$61*'Assumptions '!$B$60,0) -> 46800 | F36: =IF(4>=1,'Assumptions '!$B$61*'Assumptions '!$B$60,0) -> 46800 | G36: =IF(5>=1,'Assumptions '!$B$61*'Assumptions '!$B$60,0) -> 46800 | H36: =IF(6>=1,'Assumptions '!$B$61*'Assumptions '!$B$60,0) -> 46800 | I36: =IF(7>=1,'Assumptions '!$B$61*'Assumptions '!$B$60,0) -> 46800 | J36: =IF(8>=1,'Assumptions '!$B$61*'Assumptions '!$B$60,0) -> 46800 | K36: =IF(9>=1,'Assumptions '!$B$61*'Assumptions '!$B$60,0) -> 46800 | L36: =IF(10>=1,'Assumptions '!$B$61*'Assumptions '!$B$60,0) -> 46800 | M36: =IF(11>=1,'Assumptions '!$B$61*'Assumptions '!$B$60,0) -> 46800 | N36: =IF(12>=1,'Assumptions '!$B$61*'Assumptions '!$B$60,0) -> 46800 | O36: =SUM(B36:N36) -> 561600
A37: Risk-score database (nodes x monthly price) | B37: =IF(0>=1,'Assumptions '!$B$63*'Assumptions '!$B$62,0) -> 0 | C37: =IF(1>=1,'Assumptions '!$B$63*'Assumptions '!$B$62,0) -> 30800 | D37: =IF(2>=1,'Assumptions '!$B$63*'Assumptions '!$B$62,0) -> 30800 | E37: =IF(3>=1,'Assumptions '!$B$63*'Assumptions '!$B$62,0) -> 30800 | F37: =IF(4>=1,'Assumptions '!$B$63*'Assumptions '!$B$62,0) -> 30800 | G37: =IF(5>=1,'Assumptions '!$B$63*'Assumptions '!$B$62,0) -> 30800 | H37: =IF(6>=1,'Assumptions '!$B$63*'Assumptions '!$B$62,0) -> 30800 | I37: =IF(7>=1,'Assumptions '!$B$63*'Assumptions '!$B$62,0) -> 30800 | J37: =IF(8>=1,'Assumptions '!$B$63*'Assumptions '!$B$62,0) -> 30800 | K37: =IF(9>=1,'Assumptions '!$B$63*'Assumptions '!$B$62,0) -> 30800 | L37: =IF(10>=1,'Assumptions '!$B$63*'Assumptions '!$B$62,0) -> 30800 | M37: =IF(11>=1,'Assumptions '!$B$63*'Assumptions '!$B$62,0) -> 30800 | N37: =IF(12>=1,'Assumptions '!$B$63*'Assumptions '!$B$62,0) -> 30800 | O37: =SUM(B37:N37) -> 369600
A38: Data storage (GB x price, scaled with rollout) | B38: ='Assumptions '!$B$106*'Assumptions '!$B$67*'Payback Analysis '!C$13 -> 0 | C38: ='Assumptions '!$B$106*'Assumptions '!$B$67*'Payback Analysis '!D$13 -> 328.59146 | D38: ='Assumptions '!$B$106*'Assumptions '!$B$67*'Payback Analysis '!E$13 -> 328.59146 | E38: ='Assumptions '!$B$106*'Assumptions '!$B$67*'Payback Analysis '!F$13 -> 1642.9573 | F38: ='Assumptions '!$B$106*'Assumptions '!$B$67*'Payback Analysis '!G$13 -> 3285.9146 | G38: ='Assumptions '!$B$106*'Assumptions '!$B$67*'Payback Analysis '!H$13 -> 6571.8292 | H38: ='Assumptions '!$B$106*'Assumptions '!$B$67*'Payback Analysis '!I$13 -> 6571.8292 | I38: ='Assumptions '!$B$106*'Assumptions '!$B$67*'Payback Analysis '!J$13 -> 6571.8292 | ... N38: ='Assumptions '!$B$106*'Assumptions '!$B$67*'Payback Analysis '!O$13 -> 6571.8292 | O38: =SUM(B38:N38) -> 58160.688
A39: Logging & dashboards (servers x price) | B39: =IF(0>=1,'Assumptions '!$B$68*'Assumptions '!$B$60,0) -> 0 | C39: =IF(1>=1,'Assumptions '!$B$68*'Assumptions '!$B$60,0) -> 23400 | D39: =IF(2>=1,'Assumptions '!$B$68*'Assumptions '!$B$60,0) -> 23400 | E39: =IF(3>=1,'Assumptions '!$B$68*'Assumptions '!$B$60,0) -> 23400 | F39: =IF(4>=1,'Assumptions '!$B$68*'Assumptions '!$B$60,0) -> 23400 | G39: =IF(5>=1,'Assumptions '!$B$68*'Assumptions '!$B$60,0) -> 23400 | H39: =IF(6>=1,'Assumptions '!$B$68*'Assumptions '!$B$60,0) -> 23400 | I39: =IF(7>=1,'Assumptions '!$B$68*'Assumptions '!$B$60,0) -> 23400 | J39: =IF(8>=1,'Assumptions '!$B$68*'Assumptions '!$B$60,0) -> 23400 | K39: =IF(9>=1,'Assumptions '!$B$68*'Assumptions '!$B$60,0) -> 23400 | L39: =IF(10>=1,'Assumptions '!$B$68*'Assumptions '!$B$60,0) -> 23400 | M39: =IF(11>=1,'Assumptions '!$B$68*'Assumptions '!$B$60,0) -> 23400 | N39: =IF(12>=1,'Assumptions '!$B$68*'Assumptions '!$B$60,0) -> 23400 | O39: =SUM(B39:N39) -> 280800
A41: ONE-TIME SETUP (M0) AND COMPLIANCE
A42: Month | B42: M0 | C42: M1 | D42: M2 | E42: M3 | F42: M4 | G42: M5 | H42: M6 | I42: M7 | J42: M8 | K42: M9 | L42: M10 | M42: M11 | N42: M12 | O42: Year 1
A43: DLT registration (4 operators) | B43: ='Assumptions '!$B$55*'Assumptions '!$B$56 -> 23600 | C43: 0 | D43: 0 | E43: 0 | F43: 0 | G43: 0 | H43: 0 | I43: 0 | J43: 0 | K43: 0 | L43: 0 | M43: 0 | N43: 0 | O43: =SUM(B43:N43) -> 23600
A44: Script translation (all languages) | B44: ='Assumptions '!$B$74*'Assumptions '!$B$75 -> 50000 | C44: 0 | D44: 0 | E44: 0 | F44: 0 | G44: 0 | H44: 0 | I44: 0 | J44: 0 | K44: 0 | L44: 0 | M44: 0 | N44: 0 | O44: =SUM(B44:N44) -> 50000
...

Sheet Payback Analysis 
A1: Cost-Savings Investment & Payback (Year 1): WhatsApp → SMS → IVR COD confirmation for Valmo
A2: The programme earns no revenue: it is an investment that avoids logistics cost on RTOs. Payback = the month cumulative cost avoided covers everything spent (setup + running). All figures in ₹, conservative case, Meesho-adjusted inputs from the Assumptions sheet (gold = guesstimate). GST excluded (input tax credit).
B4: Year 1 at a glance | C4: Upfront investment (M0) | E4: Payback month | G4: Peak cash outlay before payback | I4: Year-1 cost avoided | K4: Year-1 total spend | M4: Year-1 net savings
C5: =P51 -> 673600 | E5: =IFERROR("M"&(MATCH("Yes",C59:O59,0)-1),"After M12") -> M1 | G5: =-MIN(0,MIN(C58:O58)) -> 740960 | I5: =P22 -> 2824318842 | K5: =P56 -> 4.3136381e+08 | M5: =P57 -> 2392955037
C7: Cost avoided per ₹1 spent | E7: Return on investment (net ÷ spend) | G7: RTOs prevented in Year 1 | I7: COD RTO rate at full scale | K7: Monthly net savings at full scale (M12) | M7: Cancel rate needed to cover Year-1 spend
C8: =P22/P56 -> 6.5474173 | E8: =P57/P56 -> 5.5474173 | G8: =P18 -> 23535990 | I8: =TEXT('Assumptions '!$B$6,"0%")&" → "&TEXT('Assumptions '!$B$107,"0.0%") -> 20% → 17.3% | K8: =O57 -> 2.8651592e+08 | M8: =TEXT('Assumptions '!$B$32*P56/P22,"0.0%")&" (assumed "&TEXT('Assumptions '!$B$32,"0%")&")" -> 3.1% (assumed 20%)
A11: Rollout | B11: Rollout: build finished at M0, pilot from M1 (share of Valmo COD orders going through the flow)
B12: Month | C12: M0 (setup) | D12: M1 | E12: M2 | F12: M3 | G12: M4 | H12: M5 | I12: M6 | J12: M7 | K12: M8 | L12: M9 | M12: M10 | N12: M11 | O12: M12 | P12: Year 1 total
B13: Share of COD orders live (rollout plan) | C13: =0 -> 0 | D13: =IF(1<='Assumptions '!$B$82,'Assumptions '!$B$83,IF(1='Assumptions '!$B$82+1,'Assumptions '!$B$84,IF(1='Assumptions '!$B$82+2,'Assumptions '!$B$85,1))) -> 0.05 | E13: =IF(2<='Assumptions '!$B$82,'Assumptions '!$B$83,IF(2='Assumptions '!$B$82+1,'Assumptions '!$B$84,IF(2='Assumptions '!$B$82+2,'Assumptions '!$B$85,1))) -> 0.05 | F13: =IF(3<='Assumptions '!$B$82,'Assumptions '!$B$83,IF(3='Assumptions '!$B$82+1,'Assumptions '!$B$84,IF(3='Assumptions '!$B$82+2,'Assumptions '!$B$85,1))) -> 0.25 | G13: =IF(4<='Assumptions '!$B$82,'Assumptions '!$B$83,IF(4='Assumptions '!$B$82+1,'Assumptions '!$B$84,IF(4='Assumptions '!$B$82+2,'Assumptions '!$B$85,1))) -> 0.5 | H13: =IF(5<='Assumptions '!$B$82,'Assumptions '!$B$83,IF(5='Assumptions '!$B$82+1,'Assumptions '!$B$84,IF(5='Assumptions '!$B$82+2,'Assumptions '!$B$85,1))) -> 1 | I13: =IF(6<='Assumptions '!$B$82,'Assumptions '!$B$83,IF(6='Assumptions '!$B$82+1,'Assumptions '!$B$84,IF(6='Assumptions '!$B$82+2,'Assumptions '!$B$85,1))) -> 1 | J13: =IF(7<='Assumptions '!$B$82,'Assumptions '!$B$83,IF(7='Assumptions '!$B$82+1,'Assumptions '!$B$84,IF(7='Assumptions '!$B$82+2,'Assumptions '!$B$85,1))) -> 1 | K13: =IF(8<='Assumptions '!$B$82,'Assumptions '!$B$83,IF(8='Assumptions '!$B$82+1,'Assumptions '!$B$84,IF(8='Assumptions '!$B$82+2,'Assumptions '!$B$85,1))) -> 1 | L13: =IF(9<='Assumptions '!$B$82,'Assumptions '!$B$83,IF(9='Assumptions '!$B$82+1,'Assumptions '!$B$84,IF(9='Assumptions '!$B$82+2,'Assumptions '!$B$85,1))) -> 1 | M13: =IF(10<='Assumptions '!$B$82,'Assumptions '!$B$83,IF(10='Assumptions '!$B$82+1,'Assumptions '!$B$84,IF(10='Assumptions '!$B$82+2,'Assumptions '!$B$85,1))) -> 1 | N13: =IF(11<='Assumptions '!$B$82,'Assumptions '!$B$83,IF(11='Assumptions '!$B$82+1,'Assumptions '!$B$84,IF(11='Assumptions '!$B$82+2,'Assumptions '!$B$85,1))) -> 1 | O13: =IF(12<='Assumptions '!$B$82,'Assumptions '!$B$83,IF(12='Assumptions '!$B$82+1,'Assumptions '!$B$84,IF(12='Assumptions '!$B$82+2,'Assumptions '!$B$85,1))) -> 1 | P13: =AVERAGE(D13:O13) -> 0.7375
B14: Share of savings realised (13-day RTO lag) | C14: =C13*(1-MIN('Assumptions '!$B$39,('Assumptions '!$B$9/12))/('Assumptions '!$B$9/12))+0*MIN('Assumptions '!$B$39,('Assumptions '!$B$9/12))/('Assumptions '!$B$9/12) -> 0 | D14: =D13*(1-MIN('Assumptions '!$B$39,('Assumptions '!$B$9/12))/('Assumptions '!$B$9/12))+C13*MIN('Assumptions '!$B$39,('Assumptions '!$B$9/12))/('Assumptions '!$B$9/12) -> 0.028630137 | E14: =E13*(1-MIN('Assumptions '!$B$39,('Assumptions '!$B$9/12))/('Assumptions '!$B$9/12))+D13*MIN('Assumptions '!$B$39,('Assumptions '!$B$9/12))/('Assumptions '!$B$9/12) -> 0.05 | F14: =F13*(1-MIN('Assumptions '!$B$39,('Assumptions '!$B$9/12))/('Assumptions '!$B$9/12))+E13*MIN('Assumptions '!$B$39,('Assumptions '!$B$9/12))/('Assumptions '!$B$9/12) -> 0.16452055 | G14: =G13*(1-MIN('Assumptions '!$B$39,('Assumptions '!$B$9/12))/('Assumptions '!$B$9/12))+F13*MIN('Assumptions '!$B$39,('Assumptions '!$B$9/12))/('Assumptions '!$B$9/12) -> 0.39315068 | H14: =H13*(1-MIN('Assumptions '!$B$39,('Assumptions '!$B$9/12))/('Assumptions '!$B$9/12))+G13*MIN('Assumptions '!$B$39,('Assumptions '!$B$9/12))/('Assumptions '!$B$9/12) -> 0.78630137 | I14: =I13*(1-MIN('Assumptions '!$B$39,('Assumptions '!$B$9/12))/('Assumptions '!$B$9/12))+H13*MIN('Assumptions '!$B$39,('Assumptions '!$B$9/12))/('Assumptions '!$B$9/12) -> 1 | J14: =J13*(1-MIN('Assumptions '!$B$39,('Assumptions '!$B$9/12))/('Assumptions '!$B$9/12))+I13*MIN('Assumptions '!$B$39,('Assumptions '!$B$9/12))/('Assumptions '!$B$9/12) -> 1 | K14: =K13*(1-MIN('Assumptions '!$B$39,('Assumptions '!$B$9/12))/('Assumptions '!$B$9/12))+J13*MIN('Assumptions '!$B$39,('Assumptions '!$B$9/12))/('Assumptions '!$B$9/12) -> 1 | ... O14: =O13*(1-MIN('Assumptions '!$B$39,('Assumptions '!$B$9/12))/('Assumptions '!$B$9/12))+N13*MIN('Assumptions '!$B$39,('Assumptions '!$B$9/12))/('Assumptions '!$B$9/12) -> 1 | P14: =AVERAGE(D14:O14) -> 0.70188356
A16: Cost Avoided | B16: Logistics cost avoided: ₹120 per RTO prevented
B17: Channel | C17: M0 (setup) | D17: M1 | E17: M2 | F17: M3 | G17: M4 | H17: M5 | I17: M6 | J17: M7 | K17: M8 | L17: M9 | M17: M10 | N17: M11 | O17: M12 | P17: Year 1 total
B18: RTOs prevented (orders) | C18: ='Assumptions '!$B$99*('Assumptions '!$B$9/12)*C$14 -> 0 | D18: ='Assumptions '!$B$99*('Assumptions '!$B$9/12)*D$14 -> 80003.61 | E18: ='Assumptions '!$B$99*('Assumptions '!$B$9/12)*E$14 -> 139719.22 | F18: ='Assumptions '!$B$99*('Assumptions '!$B$9/12)*F$14 -> 459733.67 | G18: ='Assumptions '!$B$99*('Assumptions '!$B$9/12)*G$14 -> 1098614.2 | H18: ='Assumptions '!$B$99*('Assumptions '!$B$9/12)*H$14 -> 2197228.3 | I18: ='Assumptions '!$B$99*('Assumptions '!$B$9/12)*I$14 -> 2794384.5 | J18: ='Assumptions '!$B$99*('Assumptions '!$B$9/12)*J$14 -> 2794384.5 | ... O18: ='Assumptions '!$B$99*('Assumptions '!$B$9/12)*O$14 -> 2794384.5 | P18: =SUM(C18:O18) -> 23535990
B19: Via WhatsApp (all COD orders) | C19: ='Assumptions '!$B$96*'Assumptions '!$B$100*('Assumptions '!$B$9/12)*C$14 -> 0 | D19: ='Assumptions '!$B$96*'Assumptions '!$B$100*('Assumptions '!$B$9/12)*D$14 -> 8165508 | E19: ='Assumptions '!$B$96*'Assumptions '!$B$100*('Assumptions '!$B$9/12)*E$14 -> 14260337 | F19: ='Assumptions '!$B$96*'Assumptions '!$B$100*('Assumptions '!$B$9/12)*F$14 -> 46922369 | G19: ='Assumptions '!$B$96*'Assumptions '!$B$100*('Assumptions '!$B$9/12)*G$14 -> 1.1212923e+08 | H19: ='Assumptions '!$B$96*'Assumptions '!$B$100*('Assumptions '!$B$9/12)*H$14 -> 2.2425845e+08 | I19: ='Assumptions '!$B$96*'Assumptions '!$B$100*('Assumptions '!$B$9/12)*I$14 -> 2.8520674e+08 | J19: ='Assumptions '!$B$96*'Assumptions '!$B$100*('Assumptions '!$B$9/12)*J$14 -> 2.8520674e+08 | ... O19: ='Assumptions '!$B$96*'Assumptions '!$B$100*('Assumptions '!$B$9/12)*O$14 -> 2.8520674e+08 | P19: =SUM(C19:O19) -> 2402183071
B20: Via SMS (WhatsApp non-responders) | C20: ='Assumptions '!$B$97*'Assumptions '!$B$100*('Assumptions '!$B$9/12)*C$14 -> 0 | D20: ='Assumptions '!$B$97*'Assumptions '!$B$100*('Assumptions '!$B$9/12)*D$14 -> 932455.07 | E20: ='Assumptions '!$B$97*'Assumptions '!$B$100*('Assumptions '!$B$9/12)*E$14 -> 1628450.2 | F20: ='Assumptions '!$B$97*'Assumptions '!$B$100*('Assumptions '!$B$9/12)*F$14 -> 5358270.5 | G20: ='Assumptions '!$B$97*'Assumptions '!$B$100*('Assumptions '!$B$9/12)*G$14 -> 12804527 | H20: ='Assumptions '!$B$97*'Assumptions '!$B$100*('Assumptions '!$B$9/12)*H$14 -> 25609053 | I20: ='Assumptions '!$B$97*'Assumptions '!$B$100*('Assumptions '!$B$9/12)*I$14 -> 32569005 | J20: ='Assumptions '!$B$97*'Assumptions '!$B$100*('Assumptions '!$B$9/12)*J$14 -> 32569005 | ... O20: ='Assumptions '!$B$97*'Assumptions '!$B$100*('Assumptions '!$B$9/12)*O$14 -> 32569005 | P20: =SUM(C20:O20) -> 2.7431579e+08
B21: Via IVR call (high-risk, still silent) | C21: ='Assumptions '!$B$98*'Assumptions '!$B$100*('Assumptions '!$B$9/12)*C$14 -> 0 | D21: ='Assumptions '!$B$98*'Assumptions '!$B$100*('Assumptions '!$B$9/12)*D$14 -> 502470.13 | E21: ='Assumptions '!$B$98*'Assumptions '!$B$100*('Assumptions '!$B$9/12)*E$14 -> 877519.61 | F21: ='Assumptions '!$B$98*'Assumptions '!$B$100*('Assumptions '!$B$9/12)*F$14 -> 2887400.1 | G21: ='Assumptions '!$B$98*'Assumptions '!$B$100*('Assumptions '!$B$9/12)*G$14 -> 6899948.7 | H21: ='Assumptions '!$B$98*'Assumptions '!$B$100*('Assumptions '!$B$9/12)*H$14 -> 13799897 | I21: ='Assumptions '!$B$98*'Assumptions '!$B$100*('Assumptions '!$B$9/12)*I$14 -> 17550392 | J21: ='Assumptions '!$B$98*'Assumptions '!$B$100*('Assumptions '!$B$9/12)*J$14 -> 17550392 | ... O21: ='Assumptions '!$B$98*'Assumptions '!$B$100*('Assumptions '!$B$9/12)*O$14 -> 17550392 | P21: =SUM(C21:O21) -> 1.4781998e+08
B22: Total Cost Avoided | C22: =SUM(C19:C21) -> 0 | D22: =SUM(D19:D21) -> 9600433.2 | E22: =SUM(E19:E21) -> 16766307 | F22: =SUM(F19:F21) -> 55168040 | G22: =SUM(G19:G21) -> 1.318337e+08 | H22: =SUM(H19:H21) -> 2.636674e+08 | I22: =SUM(I19:I21) -> 3.3532614e+08 | J22: =SUM(J19:J21) -> 3.3532614e+08 | ... O22: =SUM(O19:O21) -> 3.3532614e+08 | P22: =SUM(C22:O22) -> 2824318842
A24: Running Costs | B24: Monthly running costs (from M1)
B25: Component | C25: M0 (setup) | D25: M1 | E25: M2 | F25: M3 | G25: M4 | H25: M5 | I25: M6 | J25: M7 | K25: M8 | L25: M9 | M25: M10 | N25: M11 | O25: M12 | P25: Year 1 total
